Workbook

Sheet PAR tracking 2023
A1: Location (drop-down) | B1: Location ID | C1: # | D1: PAR # | E1: PAR type | F1: BRIEF DESCRIPTION OF PAR if VOID: Location, type, details (initials, date) | G1: PAR initialized date | H1: QA team member initials | I1: Date closed | J1: Area (Ops, Lab, Misc., PT) (drop-down) | K1: Projected Improvement | L1: Action taken | M1: Notes
A2: Tampa, FL | B2: =VLOOKUP(Table24[[#This Row],[Location (drop-down)]],'List source'!D$2:E$59,2,FALSE) -> 126 | C2: 001 | D2: ="P" & C2 & "-" & B2 & "-" & "23" -> P001-126-23 | E2: PT | F2: PT: JF2207; D1322 - Smoke Point, Man | G2: 44937 | H2: JN | I2: 45099 | J2: PT | K2: To minimize future PT outliers and improve lab accuracy. | L2: Ensure techs are properly trained
A3: Tampa, FL | B3: =VLOOKUP(Table24[[#This Row],[Location (drop-down)]],'List source'!D$2:E$59,2,FALSE) -> 126 | C3: 002 | D3: ="P" & C3 & "-" & B3 & "-" & "23" -> P002-126-23 | E3: PT | F3: PT: JF2207; D6045 - Color, Auto, as D156 Saybolt | G3: 44937 | H3: JN | I3: 45099 | J3: PT | K3: To minimize future PT outliers and improve lab accuracy. | L3: Ensure techs are properly trained
A4: Los Angeles (Signal Hill), CA | B4: 130 | C4: 003 | D4: ="P" & C4 & "-" & B4 & "-" & "23" -> P003-130-23 | E4: PT | F4: PT: JF2207; D56 - Flash Point, TAG, Corrected | G4: 44937 | H4: JN | I4: 45295 | J4: PT
A5: Los Angeles (Signal Hill), CA | B5: 130 | C5: 004 | D5: ="P" & C5 & "-" & B5 & "-" & "23" -> P004-130-23 | E5: PT | F5: PT: JF2207; D1840 - Napthalenes, by UVS, Proc A | G5: 44937 | H5: JN | I5: 45295 | J5: PT
A6: Bellingham (Ferndale), WA | B6: =VLOOKUP(Table24[[#This Row],[Location (drop-down)]],'List source'!D$2:E$59,2,FALSE) -> 132 | C6: 005 | D6: ="P" & C6 & "-" & B6 & "-" & "23" -> P005-132-23 | E6: PT | F6: PT: JF2207; D86 - Distillation, Auto, IBP | G6: 44937 | H6: JN | I6: 45295 | J6: PT
A7: Bellingham (Ferndale), WA | B7: =VLOOKUP(Table24[[#This Row],[Location (drop-down)]],'List source'!D$2:E$59,2,FALSE) -> 132 | C7: 006 | D7: ="P" & C7 & "-" & B7 & "-" & "23" -> P006-132-23 | E7: PT | F7: PT: JF2207; D1319 - HC Type, Olefins, Oxy-Free | G7: 44937 | H7: JN | I7: 45307 | J7: PT | K7: To minimize future PT outliers and improve lab accuracy. | L7: N/A
A8: Bellingham (Ferndale), WA | B8: =VLOOKUP(Table24[[#This Row],[Location (drop-down)]],'List source'!D$2:E$59,2,FALSE) -> 132 | C8: 007 | D8: ="P" & C8 & "-" & B8 & "-" & "23" -> P007-132-23 | E8: PT | F8: PT: R-1328; D2699 - Octane Number, Research | G8: 44937 | H8: JN | I8: 45372 | J8: PT | K8: Technicians to be throughly trained to improve future Z-scores. | L8: Training
A9: Brownsville, TX | B9: =VLOOKUP(Table24[[#This Row],[Location (drop-down)]],'List source'!D$2:E$59,2,FALSE) -> 158 | C9: 008 | D9: ="P" & C9 & "-" & B9 & "-" & "23" -> P008-158-23 | E9: PT | F9: PT: MG2208; D1319 - HC Type, Aromatics, Corrected & Oxy-Free | G9: 44937 | H9: JN | I9: 45217 | J9: PT
A10: Brownsville, TX | B10: =VLOOKUP(Table24[[#This Row],[Location (drop-down)]],'List source'!D$2:E$59,2,FALSE) -> 158 | C10: 009 | D10: ="P" & C10 & "-" & B10 & "-" & "23" -> P009-158-23 | E10: PT | F10: PT: MG2208; D5453 - Sulfur, by UVF | G10: 44937 | H10: JN | I10: 45022 | J10: PT
A11: Halifax (Dartmouth), NS | B11: =VLOOKUP(Table24[[#This Row],[Location (drop-down)]],'List source'!D$2:E$59,2,FALSE) -> 198 | C11: 010 | D11: ="P" & C11 & "-" & B11 & "-" & "23" -> P010-198-23 | E11: PT | F11: PT: JF2207; D3242 - Acidity | G11: 44937 | H11: JN | I11: 45581 | J11: PT
A12: Halifax (Dartmouth), NS | B12: =VLOOKUP(Table24[[#This Row],[Location (drop-down)]],'List source'!D$2:E$59,2,FALSE) -> 198 | C12: 011 | D12: ="P" & C12 & "-" & B12 & "-" & "23" -> P011-198-23 | E12: PT | F12: PT: JF2207; D3338 - Net Heat of Combustion | G12: 44937 | H12: JN | I12: 45581 | J12: PT
A13: Bahamas (Freeport), GBI | B13: =VLOOKUP(Table24[[#This Row],[Location (drop-down)]],'List source'!D$2:E$59,2,FALSE) -> 215 | C13: 012 | D13: ="P" & C13 & "-" & B13 & "-" & "23" -> P012-215-23 | E13: PT | F13: PT: JF2207; D2622 - Sulfur by WDXRF | G13: 44937 | H13: JN | I13: VOID | J13: PT | M13: oided per local MOC 132 due to lab fire on 11/2/24.
A14: Cape Canaveral, FL | B14: =VLOOKUP(Table24[[#This Row],[Location (drop-down)]],'List source'!D$2:E$59,2,FALSE) -> 127 | C14: 013 | D14: ="P" & C14 & "-" & B14 & "-" & "23" -> P013-127-23 | E14: PT | F14: PT: RFG2210; D5769 - Aromatics, Total, by GC/MS (EPA) | G14: 44937 | H14: JN | I14: 44942 | J14: PT | K14: To minmize PT outliers and improve lab competency | L14: N/A, original results within ASTM test method reproducibility
A15: Corpus Christi, TX | B15: =VLOOKUP(Table24[[#This Row],[Location (drop-down)]],'List source'!D$2:E$59,2,FALSE) -> 155 | C15: 014 | D15: ="P" & C15 & "-" & B15 & "-" & "23" -> P014-155-23 | E15: PT | F15: PT: TM10C-22; D2700 - Motor Octane Number | G15: 44938 | H15: JN | I15: 44978 | J15: PT | K15: To monitor method performance
A16: Houston (HTC), TX | B16: =VLOOKUP(Table24[[#This Row],[Location (drop-down)]],'List source'!D$2:E$59,2,FALSE) -> 120 | C16: 015 | D16: ="P" & C16 & "-" & B16 & "-" & "23" -> P015-120-23 | E16: PT | F16: PT: RFG2210; D8071 - HC Type, Naphthenes, GC-VUV | G16: 44956 | H16: JN | I16: 45083 | J16: PT | K16: Monitor testing performance and improve accuracy | L16: Cross reference GC methods before reporting results
A17: Lake Charles (Sulfur), LA | B17: =VLOOKUP(Table24[[#This Row],[Location (drop-down)]],'List source'!D$2:E$59,2,FALSE) -> 165 | C17: 016 | D17: ="P" & C17 & "-" & B17 & "-" & "23" -> P016-165-23 | E17: PT | F17: PT: RFG2211; D6839 - HC Type/Oxy, Aromatics, Benzene, & Saturates, by M-D GC | G17: 44956 | H17: JN | I17: 44957 | J17: PT | K17: To minmize PT outliers and improve lab competency | L17: N/A, original results within ASTM test method reproducibility
A18: Lake Charles (Sulfur), LA | B18: =VLOOKUP(Table24[[#This Row],[Location (drop-down)]],'List source'!D$2:E$59,2,FALSE) -> 165 | C18: 017 | D18: ="P" & C18 & "-" & B18 & "-" & "23" -> P017-165-23 | E18: PT | F18: PT: RFG2211; D3606 - Toluene, by GC, Proc B & EPA | G18: 44956 | H18: JN | I18: 44964 | J18: PT | K18: To minmize PT outliers and improve lab competency | L18: retraining
A19: Montreal, QC | B19: =VLOOKUP(Table24[[#This Row],[Location (drop-down)]],'List source'!D$2:E$59,2,FALSE) -> 197 | C19: 018 | D19: ="P" & C19 & "-" & B19 & "-" & "23" -> P018-197-23 | E19: PT | F19: PT: RFG2211; D5453 - Sulfur, by UVF | G19: 44957 | H19: JN | I19: 45539 | J19: PT
A20: Mickleton (Philly), NJ | B20: =VLOOKUP(Table24[[#This Row],[Location (drop-down)]],'List source'!D$2:E$59,2,FALSE) -> 180 | C20: 019 | D20: ="P" & C20 & "-" & B20 & "-" & "23" -> P019-180-23 | E20: PT | F20: PT: NP2210; D1159 - Bromine Number, titration | G20: 44957 | H20: JN | I20: 44973 | J20: PT | K20: To monitor method performance | L20: Retraining (email to all techs)
A21: Boston (Everett), MA | B21: =VLOOKUP(Table24[[#This Row],[Location (drop-down)]],'List source'!D$2:E$59,2,FALSE) -> 141 | C21: 020 | D21: ="P" & C21 & "-" & B21 & "-" & "23" -> P020-141-23 | E21: PT | F21: PT: AT-351; D2699 - Research Octane Number | G21: 44960 | H21: JN | I21: 44967 | J21: PT | K21: To ensure proper instrument function and decrease NC results | L21: Calibration / verification schedule established
A22: Lake Charles (Sulfur), LA | B22: =VLOOKUP(Table24[[#This Row],[Location (drop-down)]],'List source'!D$2:E$59,2,FALSE) -> 165 | C22: 021 | D22: ="P" & C22 & "-" & B22 & "-" & "23" -> P021-165-23 | E22: PT | F22: PT: DF22210; D86 - Distillation, Auto, IBP | G22: 44960 | H22: JN | I22: 44998 | J22: PT | K22: To monitor method performance | L22: Within method R
A23: St Croix, USVI | B23: =VLOOKUP(Table24[[#This Row],[Location (drop-down)]],'List source'!D$2:E$59,2,FALSE) -> 210 | C23: 022 | D23: ="P" & C23 & "-" & B23 & "-" & "23" -> P022-210-23 | E23: PT | F23: PT: RFG2211; D1319 - HC Type, Aromatics, Corrected (EPA) | G23: 44965 | H23: JN | I23: 45152 | J23: PT | K23: To minmize PT outliers and improve lab competency | L23: TMA and retraining
A24: Lake Charles (Sulfur), LA | B24: =VLOOKUP(Table24[[#This Row],[Location (drop-down)]],'List source'!D$2:E$59,2,FALSE) -> 165 | C24: 023 | D24: ="P" & C24 & "-" & B24 & "-" & "23" -> P023-165-23 | E24: PT | F24: PT: RFG2212; D1319 19(EPA) & -20a - HC Type, Olefins, Corrected & Oxy-Free | G24: 44965 | H24: JN | I24: 44998 | J24: PT | K24: To monitor method performance | L24: Within method R
A25: Boston (Everett), MA | B25: =VLOOKUP(Table24[[#This Row],[Location (drop-down)]],'List source'!D$2:E$59,2,FALSE) -> 141 | C25: 024 | D25: ="P" & C25 & "-" & B25 & "-" & "23" -> P024-141-23 | E25: Internal assessment (9001 & 17025) | F25: IA: Irving Flow Times SOP should be locally controlled | G25: 44986 | H25: ECC | I25: 45021 | J25: Lab | K25: To control all non-AmSpec SOPs | L25: Controlled SOP
A26: Boston (Everett), MA | B26: =VLOOKUP(Table24[[#This Row],[Location (drop-down)]],'List source'!D$2:E$59,2,FALSE) -> 141 | C26: 025 | D26: ="P" & C26 & "-" & B26 & "-" & "23" -> P025-141-23 | E26: Internal assessment (9001 & 17025) | F26: IA: Surrogate bottle RVP-03 has lost some liquid and will be redone | G26: 44986 | H26: ECC | I26: 45009 | J26: Lab | K26: Aid lab in observing correct volumes and temps | L26: Redo reference bottle
A27: Boston (Everett), MA | B27: =VLOOKUP(Table24[[#This Row],[Location (drop-down)]],'List source'!D$2:E$59,2,FALSE) -> 141 | C27: 026 | D27: ="P" & C27 & "-" & B27 & "-" & "23" -> P026-141-23 | E27: Internal assessment (9001 & 17025) | F27: IA: FL 15.3s do not record hours that oil was changed, no record of filter change | G27: 44986 | H27: ECC | I27: 45021 | J27: Lab | K27: To ensure record of maintenance is recorded | L27: Completed FL 15.3 for last oil/filter change
A28: Memphis, TN | B28: =VLOOKUP(Table24[[#This Row],[Location (drop-down)]],'List source'!D$2:E$59,2,FALSE) -> 191 | C28: 027 | D28: ="P" & C28 & "-" & B28 & "-" & "23" -> P027-191-23 | E28: PT | F28: PT: RFG2212; D86 - HC Type, Saturates, Corrected (EPA) | G28: 45016 | H28: JN | I28: 45035 | J28: PT | K28: To minimize future PT outliers and improve lab accuracy. | L28: Syringes have been uniquely identified. Controlled reference documented posted in D1319 area
A29: Collins (Purvis), MS | B29: =VLOOKUP(Table24[[#This Row],[Location (drop-down)]],'List source'!D$2:E$59,2,FALSE) -> 115 | C29: 028 | D29: ="P" & C29 & "-" & B29 & "-" & "23" -> P028-115-23 | E29: PT | F29: PT: CE501; D5769 - Total Aromatics | G29: 45016 | H29: JN | I29: 45204 | J29: PT
A30: Memphis, TN | B30: =VLOOKUP(Table24[[#This Row],[Location (drop-down)]],'List source'!D$2:E$59,2,FALSE) -> 191 | C30: 029 | D30: ="P" & C30 & "-" & B30 & "-" & "23" -> P029-191-23 | E30: PT | F30: PT: CE501; D2699 - Research Octane Number | G30: 45016 | H30: JN | I30: 45096 | J30: PT
A31: Memphis, TN | B31: =VLOOKUP(Table24[[#This Row],[Location (drop-down)]],'List source'!D$2:E$59,2,FALSE) -> 191 | C31: 030 | D31: ="P" & C31 & "-" & B31 & "-" & "23" -> P030-191-23 | E31: PT | F31: PT: CE501; D5769 - Total Aromatics | G31: 45016 | H31: JN | I31: 45051 | J31: PT | K31: To minimize future PT outliers and improve lab accuracy. | L31: Controlled SOP
A32: Montreal, QC | B32: =VLOOKUP(Table24[[#This Row],[Location (drop-down)]],'List source'!D$2:E$59,2,FALSE) -> 197 | C32: 031 | D32: ="P" & C32 & "-" & B32 & "-" & "23" -> P031-197-23 | E32: PT | F32: PT: DF22210; D4052 - API Gravity, Digital, 60 °F | G32: 45016 | H32: JN | I32: 45539 | J32: PT
A33: St Croix, USVI | B33: =VLOOKUP(Table24[[#This Row],[Location (drop-down)]],'List source'!D$2:E$59,2,FALSE) -> 210 | C33: 032 | D33: ="P" & C33 & "-" & B33 & "-" & "23" -> P032-210-23 | E33: PT | F33: PT: DF22210; D189 - Carbon Residue, Conradson | G33: 45016 | H33: JN | I33: 45160 | J33: PT | K33: To minimize future PT outliers and improve lab accuracy. | L33: transcription error
A34: Bellingham (Ferndale), WA | B34: =VLOOKUP(Table24[[#This Row],[Location (drop-down)]],'List source'!D$2:E$59,2,FALSE) -> 132 | C34: 033 | D34: ="P" & C34 & "-" & B34 & "-" & "23" -> P033-132-23 | E34: PT | F34: PT: RFG2212; D5188 - V/L Ratio Temp, Evac Chamber | G34: 45016 | H34: JN | I34: 45546 | J34: PT
A35: Ft Lauderdale (Davie), FL | B35: =VLOOKUP(Table24[[#This Row],[Location (drop-down)]],'List source'!D$2:E$59,2,FALSE) -> 125 | C35: 034 | D35: ="P" & C35 & "-" & B35 & "-" & "23" -> P034-125-23 | E35: Internal assessment (9001 & 17025) | F35: IA - QC | G35: 45026 | H35: RB | I35: 45128 | J35: Lab | K35: To ensure record of maintenance is recorded | L35: Completed RVP notes in QC Plus
A36: VOIDED ASSMT/CAR/PAR NO | B36: =VLOOKUP(Table24[[#This Row],[Location (drop-down)]],'List source'!D$2:E$59,2,FALSE) -> VOID | C36: 035 | D36: ="P" & C36 & "-" & B36 & "-" & "23" -> P035-VOID-23 | E36: VOID | F36: VOID: Ft. Lauderdale, IA - Equipment Maintenance (RB) | G36: VOID | H36: VOID | I36: VOID | J36: VOID | K36: VOID | L36: VOID
A37: Ft Lauderdale (Davie), FL | B37: =VLOOKUP(Table24[[#This Row],[Location (drop-down)]],'List source'!D$2:E$59,2,FALSE) -> 125 | C37: 036 | D37: ="P" & C37 & "-" & B37 & "-" & "23" -> P036-125-23 | E37: Internal assessment (9001 & 17025) | F37: IA - TMA D445 | G37: 45026 | H37: RB | I37: 45070 | J37: Lab | K37: To ensure proper instrument function and decrease NC results | L37: Thermometer placement
A38: Ft Lauderdale (Davie), FL | B38: =VLOOKUP(Table24[[#This Row],[Location (drop-down)]],'List source'!D$2:E$59,2,FALSE) -> 125 | C38: 037 | D38: ="P" & C38 & "-" & B38 & "-" & "23" -> P037-125-23 | E38: Internal assessment (9001 & 17025) | F38: IA - TMA D5769 | G38: 45026 | H38: RB | I38: 45070 | J38: Lab | K38: Improve results | L38: Method review
A39: Ft Lauderdale (Davie), FL | B39: =VLOOKUP(Table24[[#This Row],[Location (drop-down)]],'List source'!D$2:E$59,2,FALSE) -> 125 | C39: 038 | D39: ="P" & C39 & "-" & B39 & "-" & "23" -> P038-125-23 | E39: Internal assessment (9001 & 17025) | F39: IA - PT | G39: 45026 | H39: RB | I39: 45070 | J39: Lab | K39: Improve PT program | L39: Enroll in additional programs
A40: Ft Lauderdale (Davie), FL | B40: =VLOOKUP(Table24[[#This Row],[Location (drop-down)]],'List source'!D$2:E$59,2,FALSE) -> 125 | C40: 039 | D40: ="P" & C40 & "-" & B40 & "-" & "23" -> P039-125-23 | E40: Internal assessment (9001 & 17025) | F40: IA - Purchasing | G40: 45026 | H40: RB | I40: 45070 | J40: Operations | K40: PO Compliance | L40: Quality statement
...

Sheet CAR tracking 2023
A1: Location (drop-down) | B1: Location ID | C1: # | D1: CAR # | E1: Area | F1: CAR Type | G1: BRIEF DESCRIPTION OF NC if VOID: "VOID, Location, type, details (initials, date)" | H1: CAR initialized date | I1: QA team member initials | J1: Date Corrective Action completed | K1: Effectiveness Review & date deemed effective | L1: Area (Lab, Ops, PT, Misc.) (drop-down) | M1: Types of Deficiency (drop-down) | N1: Types of Root Cause (drop-down) | O1: Notes
A2: Tampa, FL | B2: =VLOOKUP(Table2[[#This Row],[Location (drop-down)]],'List source'!D$2:E$59,2,FALSE) -> 126 | C2: 001 | D2: ="C" & C2 & "-" & B2 & "-" & "23" -> C001-126-23 | E2: =VLOOKUP(Table2[[#This Row],[Location (drop-down)]],Table1[#All],3,FALSE) -> SE & Caribbean | F2: PT | G2: PT: JF2207; D2386 - Freeze Point, Z-Score = -8.00 | H2: 44937 | I2: JN | J2: Closed | K2: 45100 | L2: PT | M2: PT | N2: Training/ competency
A3: Tampa, FL | B3: =VLOOKUP(Table2[[#This Row],[Location (drop-down)]],'List source'!D$2:E$59,2,FALSE) -> 126 | C3: 002 | D3: ="C" & C3 & "-" & B3 & "-" & "23" -> C002-126-23 | E3: =VLOOKUP(Table2[[#This Row],[Location (drop-down)]],Table1[#All],3,FALSE) -> SE & Caribbean | F3: PT | G3: PT: JF2207; D445 - Viscosity, Kinematic, -20 °C, Z-Score = -14.91 | H3: 44937 | I3: JN | J3: Closed | K3: 45100 | L3: PT | M3: PT | N3: Training/ competency
A4: Bellingham (Ferndale), WA | B4: =VLOOKUP(Table2[[#This Row],[Location (drop-down)]],'List source'!D$2:E$59,2,FALSE) -> 132 | C4: 003 | D4: ="C" & C4 & "-" & B4 & "-" & "23" -> C003-132-23 | E4: =VLOOKUP(Table2[[#This Row],[Location (drop-down)]],Table1[#All],3,FALSE) -> USWC | F4: PT | G4: PT: CO2207; D4294 - Sulfur, by EDXRF, Z-Score = 3.18 | H4: 44937 | I4: JN | J4: Closed | K4: 45777 | L4: PT | M4: PT
A5: Bellingham (Ferndale), WA | B5: =VLOOKUP(Table2[[#This Row],[Location (drop-down)]],'List source'!D$2:E$59,2,FALSE) -> 132 | C5: 004 | D5: ="C" & C5 & "-" & B5 & "-" & "23" -> C004-132-23 | E5: =VLOOKUP(Table2[[#This Row],[Location (drop-down)]],Table1[#All],3,FALSE) -> USWC | F5: PT | G5: PT: D-1187; D445 - Viscosity at 40°C, Z-Score = -6.54 | H5: 44937 | I5: JN | J5: Closed | K5: 45686 | L5: PT | M5: PT
A6: New Haven, CT | B6: =VLOOKUP(Table2[[#This Row],[Location (drop-down)]],'List source'!D$2:E$59,2,FALSE) -> 145 | C6: 005 | D6: ="C" & C6 & "-" & B6 & "-" & "23" -> C005-145-23 | E6: =VLOOKUP(Table2[[#This Row],[Location (drop-down)]],Table1[#All],3,FALSE) -> USNE, USMW & Canada | F6: PT | G6: PT: ULSD2210; D5453 - Sulfur by UVF, Z-Score = 3.02 | H6: 44937 | I6: JN | J6: 45001 | K6: 45004 | L6: PT | M6: PT | N6: Normal statistics variance - no CA
A7: Brownsville, TX | B7: =VLOOKUP(Table2[[#This Row],[Location (drop-down)]],'List source'!D$2:E$59,2,FALSE) -> 158 | C7: 006 | D7: ="C" & C7 & "-" & B7 & "-" & "23" -> C006-158-23 | E7: =VLOOKUP(Table2[[#This Row],[Location (drop-down)]],Table1[#All],3,FALSE) -> USGC | F7: PT | G7: PT: MG2208; D3227 - Mercaptan Sulfur, Potentiometric, Z-Score = 4.70 | H7: 44937 | I7: JN | J7: Closed | K7: 45127 | L7: PT | M7: PT
A8: Halifax (Dartmouth), NS | B8: =VLOOKUP(Table2[[#This Row],[Location (drop-down)]],'List source'!D$2:E$59,2,FALSE) -> 198 | C8: 007 | D8: ="C" & C8 & "-" & B8 & "-" & "23" -> C007-198-23 | E8: =VLOOKUP(Table2[[#This Row],[Location (drop-down)]],Table1[#All],3,FALSE) -> USNE, USMW & Canada | F8: PT | G8: PT: JF2207; D86 - Distillation, Auto, IBP, Z-Score = -5.07 | H8: 44937 | I8: JN | J8: Closed | K8: 45001 | L8: PT | M8: PT | N8: Training/ competency
A9: Halifax (Dartmouth), NS | B9: =VLOOKUP(Table2[[#This Row],[Location (drop-down)]],'List source'!D$2:E$59,2,FALSE) -> 198 | C9: 008 | D9: ="C" & C9 & "-" & B9 & "-" & "23" -> C008-198-23 | E9: =VLOOKUP(Table2[[#This Row],[Location (drop-down)]],Table1[#All],3,FALSE) -> USNE, USMW & Canada | F9: PT | G9: PT: JF2207; D1319 - HC Type, Aromatics, Olefins, & Saturates, Oxy-Free, Z-Scores = -4.80, 15.14, & -4.40 | H9: 44937 | I9: JN | J9: Closed | K9: 44998 | L9: PT | M9: PT | N9: Equipment/ calibration
A10: Halifax (Dartmouth), NS | B10: =VLOOKUP(Table2[[#This Row],[Location (drop-down)]],'List source'!D$2:E$59,2,FALSE) -> 198 | C10: 009 | D10: ="C" & C10 & "-" & B10 & "-" & "23" -> C009-198-23 | E10: =VLOOKUP(Table2[[#This Row],[Location (drop-down)]],Table1[#All],3,FALSE) -> USNE, USMW & Canada | F10: PT | G10: PT: JF2207; D1840 - Napthalenes, by UVS, Proc A, Z-Score = 9.60 | H10: 44937 | I10: JN | J10: Closed | K10: 45006 | L10: PT | M10: PT | N10: Equipment/ calibration
A11: Bahamas (Freeport), GBI | B11: =VLOOKUP(Table2[[#This Row],[Location (drop-down)]],'List source'!D$2:E$59,2,FALSE) -> 215 | C11: 010 | D11: ="C" & C11 & "-" & B11 & "-" & "23" -> C010-215-23 | E11: =VLOOKUP(Table2[[#This Row],[Location (drop-down)]],Table1[#All],3,FALSE) -> SE & Caribbean | F11: PT | G11: PT: JF2207; D7039 - Sulfur by MWDXRF, Z-Score = -4.40 | H11: 44937 | I11: JN | J11: Closed | K11: 45275 | L11: PT | M11: PT
A12: St Croix, USVI | B12: =VLOOKUP(Table2[[#This Row],[Location (drop-down)]],'List source'!D$2:E$59,2,FALSE) -> 210 | C12: 011 | D12: ="C" & C12 & "-" & B12 & "-" & "23" -> C011-210-23 | E12: =VLOOKUP(Table2[[#This Row],[Location (drop-down)]],Table1[#All],3,FALSE) -> SE & Caribbean | F12: PT | G12: PT: JF2207; D4052 - API Gravity, Digital, 60°F, Z-Score = 6.30 | H12: 44937 | I12: JN | J12: Closed | K12: 45238 | L12: PT | M12: PT
A13: St Croix, USVI | B13: =VLOOKUP(Table2[[#This Row],[Location (drop-down)]],'List source'!D$2:E$59,2,FALSE) -> 210 | C13: 012 | D13: ="C" & C13 & "-" & B13 & "-" & "23" -> C012-210-23 | E13: =VLOOKUP(Table2[[#This Row],[Location (drop-down)]],Table1[#All],3,FALSE) -> SE & Caribbean | F13: PT | G13: PT: JF2207; D1298 - Density, by Hydrometer, 15 °C, Z-Score = -4.95 | H13: 44937 | I13: JN | J13: 45167 | K13: 45170 | L13: PT | M13: PT | N13: Negligence (typo, no review)
A14: St Croix, USVI | B14: =VLOOKUP(Table2[[#This Row],[Location (drop-down)]],'List source'!D$2:E$59,2,FALSE) -> 210 | C14: 013 | D14: ="C" & C14 & "-" & B14 & "-" & "23" -> C013-210-23 | E14: =VLOOKUP(Table2[[#This Row],[Location (drop-down)]],Table1[#All],3,FALSE) -> SE & Caribbean | F14: PT | G14: PT: JF2207; D86 - Distillation, Auto 60%, 70%, 80%, & 90%, Z-scores = -2.74, -3.02, -2.63, & -2.38 | H14: 44937 | I14: JN | J14: Closed | K14: 45100 | L14: PT | M14: PT
A15: St Croix, USVI | B15: =VLOOKUP(Table2[[#This Row],[Location (drop-down)]],'List source'!D$2:E$59,2,FALSE) -> 210 | C15: 014 | D15: ="C" & C15 & "-" & B15 & "-" & "23" -> C014-210-23 | E15: =VLOOKUP(Table2[[#This Row],[Location (drop-down)]],Table1[#All],3,FALSE) -> SE & Caribbean | F15: PT | G15: PT: JF2207; D2386 - Freeze Point, Z-Score = -4.00 | H15: 44937 | I15: JN | J15: Closed | K15: 45239 | L15: PT | M15: PT | N15: Training/ competency
A16: St Croix, USVI | B16: =VLOOKUP(Table2[[#This Row],[Location (drop-down)]],'List source'!D$2:E$59,2,FALSE) -> 210 | C16: 015 | D16: ="C" & C16 & "-" & B16 & "-" & "23" -> C015-210-23 | E16: =VLOOKUP(Table2[[#This Row],[Location (drop-down)]],Table1[#All],3,FALSE) -> SE & Caribbean | F16: PT | G16: PT: JF2207; D3227 - Mercaptan Sulfur, Potentiometric, Z-Score = 3.44 | H16: 44937 | I16: JN | J16: Closed | K16: 45287 | L16: PT | M16: PT | N16: Training/ competency
A17: St Croix, USVI | B17: =VLOOKUP(Table2[[#This Row],[Location (drop-down)]],'List source'!D$2:E$59,2,FALSE) -> 210 | C17: 016 | D17: ="C" & C17 & "-" & B17 & "-" & "23" -> C016-210-23 | E17: =VLOOKUP(Table2[[#This Row],[Location (drop-down)]],Table1[#All],3,FALSE) -> SE & Caribbean | F17: PT | G17: PT: JF2207; D2622 - Sulfur by WDXRF, Z-Score = -7.87 | H17: 44937 | I17: JN | J17: Closed | K17: 45156 | L17: PT | M17: PT | N17: Training/ competency
A18: St Croix, USVI | B18: =VLOOKUP(Table2[[#This Row],[Location (drop-down)]],'List source'!D$2:E$59,2,FALSE) -> 210 | C18: 017 | D18: ="C" & C18 & "-" & B18 & "-" & "23" -> C017-210-23 | E18: =VLOOKUP(Table2[[#This Row],[Location (drop-down)]],Table1[#All],3,FALSE) -> SE & Caribbean | F18: PT | G18: PT: JF2207; D4294 - Sulfur by EDXRF, Z-Score = 6.20 | H18: 44937 | I18: JN | J18: Closed | K18: 45184 | L18: PT | M18: PT | N18: Equipment/ calibration
A19: St Croix, USVI | B19: =VLOOKUP(Table2[[#This Row],[Location (drop-down)]],'List source'!D$2:E$59,2,FALSE) -> 210 | C19: 018 | D19: ="C" & C19 & "-" & B19 & "-" & "23" -> C018-210-23 | E19: =VLOOKUP(Table2[[#This Row],[Location (drop-down)]],Table1[#All],3,FALSE) -> SE & Caribbean | F19: PT | G19: PT: JF2207; D445 - Viscosity, Kinematic, -20 °C, Z-Score = 6.74 | H19: 44937 | I19: JN | J19: Closed | K19: 45154 | L19: PT | M19: PT | N19: Training/ competency
A20: St Croix, USVI | B20: =VLOOKUP(Table2[[#This Row],[Location (drop-down)]],'List source'!D$2:E$59,2,FALSE) -> 210 | C20: 019 | D20: ="C" & C20 & "-" & B20 & "-" & "23" -> C019-210-23 | E20: =VLOOKUP(Table2[[#This Row],[Location (drop-down)]],Table1[#All],3,FALSE) -> SE & Caribbean | F20: PT | G20: PT: JF2207; D7042 - Viscosity, Stabinger, Kin, -20 °C, Z-Score = 3.32 | H20: 44937 | I20: JN | J20: Closed | K20: 45184 | L20: PT | M20: PT | N20: Training/ competency
A21: Corpus Christi, TX | B21: =VLOOKUP(Table2[[#This Row],[Location (drop-down)]],'List source'!D$2:E$59,2,FALSE) -> 155 | C21: 020 | D21: ="C" & C21 & "-" & B21 & "-" & "23" -> C020-155-23 | E21: =VLOOKUP(Table2[[#This Row],[Location (drop-down)]],Table1[#All],3,FALSE) -> USGC | F21: PT | G21: PT: RFG2210; D1319 - HC Type, Aromatics, Corrected & Oxy Free, 20a & 19, Z-Scores = 4.41, 3.03, & 4.84 | H21: 44937 | I21: JN | J21: Closed | K21: 44993 | L21: PT | M21: PT | N21: Training/ competency
A22: Mickleton (Philly), NJ | B22: =VLOOKUP(Table2[[#This Row],[Location (drop-down)]],'List source'!D$2:E$59,2,FALSE) -> 180 | C22: 021 | D22: ="C" & C22 & "-" & B22 & "-" & "23" -> C021-180-23 | E22: =VLOOKUP(Table2[[#This Row],[Location (drop-down)]],Table1[#All],3,FALSE) -> SE & Caribbean | F22: PT | G22: PT: RFG2210; D5191 - Vapor Pressure, TVP, 1L (EPA), Z-Score = 3.02 | H22: 44937 | I22: JN | J22: Closed | K22: 44957 | L22: PT | M22: PT | N22: Normal statistics variance - no CA
A23: Bellingham (Ferndale), WA | B23: =VLOOKUP(Table2[[#This Row],[Location (drop-down)]],'List source'!D$2:E$59,2,FALSE) -> 132 | C23: 022 | D23: ="C" & C23 & "-" & B23 & "-" & "23" -> C022-132-23 | E23: =VLOOKUP(Table2[[#This Row],[Location (drop-down)]],Table1[#All],3,FALSE) -> USWC | F23: PT | G23: PT: RFG2210; D5580 - Total Aromatics, Benzene & Toluene, by GC, Z-Scores = 7.94, 14.14, & 20.50 | H23: 44938 | I23: JN | J23: Closed | K23: 45302 | L23: PT | M23: PT | N23: Negligence (typo, no review)
A24: Memphis, TN | B24: =VLOOKUP(Table2[[#This Row],[Location (drop-down)]],'List source'!D$2:E$59,2,FALSE) -> 191 | C24: 023 | D24: ="C" & C24 & "-" & B24 & "-" & "23" -> C023-191-23 | E24: =VLOOKUP(Table2[[#This Row],[Location (drop-down)]],Table1[#All],3,FALSE) -> SE & Caribbean | F24: PT | G24: PT: RFG2210; D1319 - HC Type, Saturates, Corrected (EPA), Z-Score = 5.75 | H24: 44938 | I24: JN | J24: Closed | K24: 45097 | L24: PT | M24: PT
A25: Halifax (Dartmouth), NS | B25: =VLOOKUP(Table2[[#This Row],[Location (drop-down)]],'List source'!D$2:E$59,2,FALSE) -> 198 | C25: 024 | D25: ="C" & C25 & "-" & B25 & "-" & "23" -> C024-198-23 | E25: =VLOOKUP(Table2[[#This Row],[Location (drop-down)]],Table1[#All],3,FALSE) -> USNE, USMW & Canada | F25: PT | G25: PT: D329; D86 - Distillation, Loss, Z-Score = 4.43 | H25: 44938 | I25: JN | J25: Closed | K25: 45006 | L25: PT | M25: PT | N25: Training/ competency
A26: Los Angeles (Signal Hill), CA | B26: =VLOOKUP(Table2[[#This Row],[Location (drop-down)]],'List source'!D$2:E$59,2,FALSE) -> 130 | C26: 025 | D26: ="C" & C26 & "-" & B26 & "-" & "23" -> C025-130-23 | E26: =VLOOKUP(Table2[[#This Row],[Location (drop-down)]],Table1[#All],3,FALSE) -> USWC | F26: PT | G26: PT: RFG2211; D86 - Distillation, Auto, % Loss (EPA), Z-Score = -5.30 | H26: 44938 | I26: JN | J26: Closed | K26: 45214 | L26: PT | M26: PT | N26: Training/ competency
A27: Corpus Christi, TX | B27: =VLOOKUP(Table2[[#This Row],[Location (drop-down)]],'List source'!D$2:E$59,2,FALSE) -> 155 | C27: 026 | D27: ="C" & C27 & "-" & B27 & "-" & "23" -> C026-155-23 | E27: =VLOOKUP(Table2[[#This Row],[Location (drop-down)]],Table1[#All],3,FALSE) -> USGC | F27: PT | G27: PT: RFG2211; D86 - Distillation, Auto, 70%, °F (EPA), Z-Score = -8.55 | H27: 44938 | I27: JN | J27: Closed | K27: 44993 | L27: PT | M27: PT | N27: Training/ competency
A28: Houston (HTC), TX | B28: =VLOOKUP(Table2[[#This Row],[Location (drop-down)]],'List source'!D$2:E$59,2,FALSE) -> 120 | C28: 027 | D28: ="C" & C28 & "-" & B28 & "-" & "23" -> C027-120-23 | E28: =VLOOKUP(Table2[[#This Row],[Location (drop-down)]],Table1[#All],3,FALSE) -> USGC | F28: Complaint | G28: Vitol - Silicon result off spec | H28: 44942 | I28: RB | J28: Closed | K28: 44960 | L28: Lab | M28: Technical (Calibration/ Verification/ Maintenance/ PT/ method deviation) | N28: Equipment/ calibration | O28: Internal standard
A29: Corpus Christi, TX | B29: =VLOOKUP(Table2[[#This Row],[Location (drop-down)]],'List source'!D$2:E$59,2,FALSE) -> 155 | C29: 028 | D29: ="C" & C29 & "-" & B29 & "-" & "23" -> C028-155-23 | E29: =VLOOKUP(Table2[[#This Row],[Location (drop-down)]],Table1[#All],3,FALSE) -> USGC | F29: Internal assessment (9001 & 17025) | G29: IA - QC – Job file 155-22-03771 | H29: 44946 | I29: RB | J29: Closed | K29: 45061 | L29: Lab | M29: Traceability and records (SR-1, raw data) | N29: Ineffective/ Lack system/ procedure
A30: Corpus Christi, TX | B30: =VLOOKUP(Table2[[#This Row],[Location (drop-down)]],'List source'!D$2:E$59,2,FALSE) -> 155 | C30: 029 | D30: ="C" & C30 & "-" & B30 & "-" & "23" -> C029-155-23 | E30: =VLOOKUP(Table2[[#This Row],[Location (drop-down)]],Table1[#All],3,FALSE) -> USGC | F30: Internal assessment (9001 & 17025) | G30: IA - File review: Operations | H30: 44946 | I30: RB | J30: Closed | K30: 44960 | L30: Operations | M30: Traceability and records (SR-1, raw data) | N30: Training/ competency
A31: Corpus Christi, TX | B31: =VLOOKUP(Table2[[#This Row],[Location (drop-down)]],'List source'!D$2:E$59,2,FALSE) -> 155 | C31: 030 | D31: ="C" & C31 & "-" & B31 & "-" & "23" -> C030-155-23 | E31: =VLOOKUP(Table2[[#This Row],[Location (drop-down)]],Table1[#All],3,FALSE) -> USGC | F31: Internal assessment (9001 & 17025) | G31: IA - 2022 Test Method Assessments (TMA) are not completed per schedule | H31: 44946 | I31: RB | J31: Closed | K31: 44973 | L31: Lab | M31: Traceability and records (SR-1, raw data) | N31: Ineffective/ Lack system/ procedure
A32: Corpus Christi, TX | B32: =VLOOKUP(Table2[[#This Row],[Location (drop-down)]],'List source'!D$2:E$59,2,FALSE) -> 155 | C32: 031 | D32: ="C" & C32 & "-" & B32 & "-" & "23" -> C031-155-23 | E32: =VLOOKUP(Table2[[#This Row],[Location (drop-down)]],Table1[#All],3,FALSE) -> USGC | F32: Internal assessment (9001 & 17025) | G32: IA - Training Record | H32: 44946 | I32: RB | J32: Closed | K32: 44971 | L32: Lab | M32: Training (include quality, safety, ethics) | N32: Training/ competency
A33: Corpus Christi, TX | B33: =VLOOKUP(Table2[[#This Row],[Location (drop-down)]],'List source'!D$2:E$59,2,FALSE) -> 155 | C33: 032 | D33: ="C" & C33 & "-" & B33 & "-" & "23" -> C032-155-23 | E33: =VLOOKUP(Table2[[#This Row],[Location (drop-down)]],Table1[#All],3,FALSE) -> USGC | F33: Internal assessment (9001 & 17025) | G33: IA - Clause 6.2.3 Staff Competency | H33: 44946 | I33: RB | J33: Closed | K33: 44984 | L33: Lab | M33: Training (include quality, safety, ethics) | N33: Training/ competency
A34: Corpus Christi, TX | B34: =VLOOKUP(Table2[[#This Row],[Location (drop-down)]],'List source'!D$2:E$59,2,FALSE) -> 155 | C34: 033 | D34: ="C" & C34 & "-" & B34 & "-" & "23" -> C033-155-23 | E34: =VLOOKUP(Table2[[#This Row],[Location (drop-down)]],Table1[#All],3,FALSE) -> USGC | F34: Internal assessment (9001 & 17025) | G34: IA - Clause 7.2.1.2 and Clause 8.3 Equipment manual use for PCS HFRR lubricity operating, maintenance, calibration, verification is not controlled. | H34: 44946 | I34: RB | J34: Closed | K34: 44974 | L34: Lab | M34: Traceability and records (SR-1, raw data) | N34: Ineffective/ Lack system/ procedure
A35: Corpus Christi, TX | B35: =VLOOKUP(Table2[[#This Row],[Location (drop-down)]],'List source'!D$2:E$59,2,FALSE) -> 155 | C35: 034 | D35: ="C" & C35 & "-" & B35 & "-" & "23" -> C034-155-23 | E35: =VLOOKUP(Table2[[#This Row],[Location (drop-down)]],Table1[#All],3,FALSE) -> USGC | F35: Internal assessment (9001 & 17025) | G35: IA - Clause 7.5.1 Technical records | H35: 44946 | I35: RB | J35: Closed | K35: 44988 | L35: Lab | M35: Traceability and records (SR-1, raw data) | N35: Ineffective/ Lack system/ procedure
A36: Corpus Christi, TX | B36: =VLOOKUP(Table2[[#This Row],[Location (drop-down)]],'List source'!D$2:E$59,2,FALSE) -> 155 | C36: 035 | D36: ="C" & C36 & "-" & B36 & "-" & "23" -> C035-155-23 | E36: =VLOOKUP(Table2[[#This Row],[Location (drop-down)]],Table1[#All],3,FALSE) -> USGC | F36: Internal assessment (9001 & 17025) | G36: IA - Clause 7.8.1.2 Test Report General Requirements | H36: 44946 | I36: RB | J36: Closed | K36: 45020 | L36: Lab | M36: Traceability and records (SR-1, raw data) | N36: Training/ competency
A37: Corpus Christi, TX | B37: =VLOOKUP(Table2[[#This Row],[Location (drop-down)]],'List source'!D$2:E$59,2,FALSE) -> 155 | C37: 036 | D37: ="C" & C37 & "-" & B37 & "-" & "23" -> C036-155-23 | E37: =VLOOKUP(Table2[[#This Row],[Location (drop-down)]],Table1[#All],3,FALSE) -> USGC | F37: Internal assessment (9001 & 17025) | G37: IA - Clause 7.8.3.1 (e) Specific Information required by method | H37: 44946 | I37: RB | J37: Closed | K37: 44964 | L37: Lab | M37: Traceability and records (SR-1, raw data) | N37: Training/ competency
A38: Corpus Christi, TX | B38: =VLOOKUP(Table2[[#This Row],[Location (drop-down)]],'List source'!D$2:E$59,2,FALSE) -> 155 | C38: 037 | D38: ="C" & C38 & "-" & B38 & "-" & "23" -> C037-155-23 | E38: =VLOOKUP(Table2[[#This Row],[Location (drop-down)]],Table1[#All],3,FALSE) -> USGC | F38: Internal assessment (9001 & 17025) | G38: IA - Clause 7.8.2.1 (p) Test outsources are not identified in the following test reports. | H38: 44946 | I38: RB | J38: Closed | K38: 44988 | L38: Lab | M38: Traceability and records (SR-1, raw data) | N38: Ineffective/ Lack system/ procedure
A39: Mobile, AL | B39: =VLOOKUP(Table2[[#This Row],[Location (drop-down)]],'List source'!D$2:E$59,2,FALSE) -> 146 | C39: 038 | D39: ="C" & C39 & "-" & B39 & "-" & "23" -> C038-146-23 | E39: =VLOOKUP(Table2[[#This Row],[Location (drop-down)]],Table1[#All],3,FALSE) -> SE & Caribbean | F39: Customer audit | G39: CHESM - Inspectors cell phone rang while sampling the BATTLE AMY | H39: 44943 | I39: RB | J39: Closed | K39: 44960 | L39: Operations | M39: Safety | N39: Training/ competency | O39: CHESM Field Audit
A40: Boston (Everett), MA | B40: =VLOOKUP(Table2[[#This Row],[Location (drop-down)]],'List source'!D$2:E$59,2,FALSE) -> 141 | C40: 039 | D40: ="C" & C40 & "-" & B40 & "-" & "23" -> C039-141-23 | E40: =VLOOKUP(Table2[[#This Row],[Location (drop-down)]],Table1[#All],3,FALSE) -> USNE, USMW & Canada | F40: Other (QC, customer alert, improper procedure) | G40: QC - D6379 Improper Sample Handling | H40: 44950 | I40: ECC | J40: 44985 | K40: 44987 | L40: Lab | M40: Technical (Calibration/ Verification/ Maintenance/ PT/ method deviation) | N40: Training/ competency
...

Sheet Assessment tracking 2023
A1: Location (drop-down) | B1: Location ID | C1: # | D1: Assessment # | E1: Start Date | F1: End Date | G1: Report Issued | H1: Type of Assessment (drop-down) | I1: Scope of Assessment (drop-down) | J1: QA In Charge (Get a copy of assessment report or summary) | K1: Assessor(s) / Auditor(s) name(s) | L1: Assessor's company | M1: Agency Type (Regulatory / certification / accreditation agency) (drop-down) | N1: Brief description of assessment scope
A2: Cape Canaveral, FL | B2: =VLOOKUP(Table245[[#This Row],[Location (drop-down)]],'List source'!D$2:E$59,2,FALSE) -> 127 | C2: 001 | D2: ="A" & C2 & "-" & B2 & "-" & "23" -> A001-127-23 | E2: 44935 | F2: 44938 | G2: 44957 | H2: Internal | I2: Inspection & Laboratory | J2: AH | K2: AH | L2: AmSpec | N2: Annual internal quality systems assessment (ISO 9001)
A3: Corpus Christi, TX | B3: =VLOOKUP(Table245[[#This Row],[Location (drop-down)]],'List source'!D$2:E$59,2,FALSE) -> 155 | C3: 002 | D3: ="A" & C3 & "-" & B3 & "-" & "23" -> A002-155-23 | E3: 44935 | F3: 44938 | G3: 44946 | H3: Internal | I3: Inspection & Laboratory | J3: RB | K3: RB, MT | L3: AmSpec | N3: Annual internal quality systems assessment (ISO 9001)
A4: Corpus Christi, TX | B4: =VLOOKUP(Table245[[#This Row],[Location (drop-down)]],'List source'!D$2:E$59,2,FALSE) -> 155 | C4: 003 | D4: ="A" & C4 & "-" & B4 & "-" & "23" -> A003-155-23 | E4: 44935 | F4: 44938 | G4: 44946 | H4: Internal | I4: Laboratory | J4: RB | K4: RB, MT | L4: AmSpec | N4: Annual internal quality systems assessment (ISO 17025)
A5: San Francisco (Concord), CA | B5: =VLOOKUP(Table245[[#This Row],[Location (drop-down)]],'List source'!D$2:E$59,2,FALSE) -> 131 | C5: 004 | D5: ="A" & C5 & "-" & B5 & "-" & "23" -> A004-131-23 | E5: 44949 | F5: 44952 | G5: 44956 | H5: Internal | I5: Inspection & Laboratory | K5: KA, MT | L5: AmSpec | N5: Annual internal quality systems assessment (ISO 9001)
A6: San Francisco (Concord), CA | B6: =VLOOKUP(Table245[[#This Row],[Location (drop-down)]],'List source'!D$2:E$59,2,FALSE) -> 131 | C6: 005 | D6: ="A" & C6 & "-" & B6 & "-" & "23" -> A005-131-23 | E6: 44949 | F6: 44952 | G6: 44956 | H6: Internal | I6: Laboratory | K6: KA, MT | L6: AmSpec | N6: Annual internal quality systems assessment (ISO 17025)
A7: Avenel (NYH), NJ | B7: =VLOOKUP(Table245[[#This Row],[Location (drop-down)]],'List source'!D$2:E$59,2,FALSE) -> 110 | C7: 006 | D7: ="A" & C7 & "-" & B7 & "-" & "23" -> A006-110-23 | E7: 44937 | F7: 44937 | G7: 44938 | H7: Certifications | I7: Laboratory | J7: KA | K7: Linda Zatkalik | L7: NBAC | N7: BQ-9000 24 month surveillance audit (Year 2)
A8: Mobile, AL | B8: =VLOOKUP(Table245[[#This Row],[Location (drop-down)]],'List source'!D$2:E$59,2,FALSE) -> 146 | C8: 007 | D8: ="A" & C8 & "-" & B8 & "-" & "23" -> A007-146-23 | E8: 44937 | F8: 44937 | G8: 44943 | H8: Customer | I8: Inspection | J8: RB | K8: Brandon Gray | L8: CHESM
A9: Marcus Hook, PA | B9: =VLOOKUP(Table245[[#This Row],[Location (drop-down)]],'List source'!D$2:E$59,2,FALSE) -> 179 | C9: 008 | D9: ="A" & C9 & "-" & B9 & "-" & "23" -> A008-179-23 | E9: 44943 | F9: 44944 | G9: 44956 | H9: Internal | I9: Inspection & Laboratory | J9: KA | K9: KA | L9: AmSpec | N9: Annual internal quality systems assessment (ISO 9001)
A10: Pittsburgh, PA | B10: =VLOOKUP(Table245[[#This Row],[Location (drop-down)]],'List source'!D$2:E$59,2,FALSE) -> 178 | C10: 009 | D10: ="A" & C10 & "-" & B10 & "-" & "23" -> A009-178-23 | E10: 44951 | F10: 44952 | G10: 44956 | H10: Internal | I10: Inspection & Laboratory | J10: RB | K10: RB | L10: AmSpec | N10: Annual internal quality systems assessment (ISO 9001)
A11: Los Angeles (Signal Hill), CA | B11: =VLOOKUP(Table245[[#This Row],[Location (drop-down)]],'List source'!D$2:E$59,2,FALSE) -> 130 | C11: 010 | D11: ="A" & C11 & "-" & B11 & "-" & "23" -> A010-130-23 | E11: 44943 | F11: 44943 | G11: 44956 | H11: Customer | I11: Inspection & Laboratory | J11: RB | K11: Samuel Dapaah | L11: Chevron | N11: Assess Hazards Assessment Safeguards
A12: Texas City, TX | B12: =VLOOKUP(Table245[[#This Row],[Location (drop-down)]],'List source'!D$2:E$59,2,FALSE) -> 150 | C12: 011 | D12: ="A" & C12 & "-" & B12 & "-" & "23" -> A011-150-23 | E12: 44963 | F12: 44966 | G12: 44978 | H12: Internal | I12: Inspection & Laboratory | J12: RB | K12: RB/KA/MT | L12: AmSpec | N12: Annual internal quality systems assessment (ISO 9001)
A13: Texas City, TX | B13: =VLOOKUP(Table245[[#This Row],[Location (drop-down)]],'List source'!D$2:E$59,2,FALSE) -> 150 | C13: 012 | D13: ="A" & C13 & "-" & B13 & "-" & "23" -> A012-150-23 | E13: 44963 | F13: 44966 | G13: 44978 | H13: Internal | I13: Laboratory | J13: RB | K13: RB/KA/MT | L13: AmSpec | N13: Annual internal quality systems assessment (ISO 17025)
A14: Seabrook (Chemicals), TX | B14: =VLOOKUP(Table245[[#This Row],[Location (drop-down)]],'List source'!D$2:E$59,2,FALSE) -> 121 | C14: 013 | D14: ="A" & C14 & "-" & B14 & "-" & "23" -> A013-121-23 | E14: 44965 | F14: 44965 | G14: 44971 | H14: Internal | I14: Inspection | J14: RB | K14: RB | L14: AmSpec | N14: Annual internal quality systems assessment (ISO 9001)
A15: Baton Rouge (Gonzales), LA | B15: =VLOOKUP(Table245[[#This Row],[Location (drop-down)]],'List source'!D$2:E$59,2,FALSE) -> 190 | C15: 014 | D15: ="A" & C15 & "-" & B15 & "-" & "23" -> A014-190-23 | E15: 44963 | F15: 44966 | G15: 44987 | H15: Internal | I15: Inspection & Laboratory | J15: AH | K15: AH | L15: AmSpec | N15: Annual internal quality systems assessment (ISO 9001)
A16: Baton Rouge (Gonzales), LA | B16: =VLOOKUP(Table245[[#This Row],[Location (drop-down)]],'List source'!D$2:E$59,2,FALSE) -> 190 | C16: 015 | D16: ="A" & C16 & "-" & B16 & "-" & "23" -> A015-190-23 | E16: 44963 | F16: 44966 | G16: 44987 | H16: Internal | I16: Laboratory | J16: AH | K16: AH | L16: AmSpec | N16: Annual internal quality systems assessment (ISO 17025)
A17: New Orleans (Destrehan), LA | B17: =VLOOKUP(Table245[[#This Row],[Location (drop-down)]],'List source'!D$2:E$59,2,FALSE) -> 170 | C17: 016 | D17: ="A" & C17 & "-" & B17 & "-" & "23" -> A016-170-23 | E17: 44966 | F17: 44966 | G17: 44966 | H17: Certifications | I17: Laboratory | J17: AH | K17: Chris Garth | L17: NBAC | M17: Certifications | N17: BQ-9000 24 month surveillance audit (Year 2)
A18: Tampa, FL | B18: =VLOOKUP(Table245[[#This Row],[Location (drop-down)]],'List source'!D$2:E$59,2,FALSE) -> 126 | C18: 017 | D18: ="A" & C18 & "-" & B18 & "-" & "23" -> A017-126-23 | E18: 44931 | F18: 44931 | G18: 44935 | H18: Internal | I18: Inspection & Laboratory | J18: RB | K18: Louis Buisson | L18: AmSpec | N18: AmSpec HSSE
A19: Memphis, TN | B19: =VLOOKUP(Table245[[#This Row],[Location (drop-down)]],'List source'!D$2:E$59,2,FALSE) -> 191 | C19: 018 | D19: ="A" & C19 & "-" & B19 & "-" & "23" -> A018-191-23 | E19: 44949 | F19: 44950 | G19: 44952 | H19: Certifications | I19: Laboratory | J19: MT | K19: M. Cahill | L19: A2LA | M19: Accredited agency | N19: A2LA renewal assessment (ISO 17025)
A20: Tampa, FL | B20: =VLOOKUP(Table245[[#This Row],[Location (drop-down)]],'List source'!D$2:E$59,2,FALSE) -> 126 | C20: 019 | D20: ="A" & C20 & "-" & B20 & "-" & "23" -> A019-126-23 | E20: 44977 | F20: 44980 | G20: 44986 | H20: Internal | I20: Inspection & Laboratory | J20: RB | K20: RB | L20: AmSpec | N20: Annual internal quality systems assessment (ISO 9001)
A21: Brownsville, TX | B21: =VLOOKUP(Table245[[#This Row],[Location (drop-down)]],'List source'!D$2:E$59,2,FALSE) -> 158 | C21: 020 | D21: ="A" & C21 & "-" & B21 & "-" & "23" -> A020-158-23 | E21: 44977 | F21: 44980 | G21: 44988 | H21: Internal | I21: Inspection & Laboratory | J21: MT | K21: MT/AH | L21: AmSpec | N21: Annual internal quality systems assessment (ISO 9001)
A22: Brownsville, TX | B22: =VLOOKUP(Table245[[#This Row],[Location (drop-down)]],'List source'!D$2:E$59,2,FALSE) -> 158 | C22: 021 | D22: ="A" & C22 & "-" & B22 & "-" & "23" -> A021-158-23 | E22: 44977 | F22: 44980 | G22: 45008 | H22: Internal | I22: Laboratory | J22: MT | K22: MT/AH | L22: AmSpec | N22: Annual internal quality systems assessment (ISO 17025)
A23: Boston (Everett), MA | B23: =VLOOKUP(Table245[[#This Row],[Location (drop-down)]],'List source'!D$2:E$59,2,FALSE) -> 141 | C23: 022 | D23: ="A" & C23 & "-" & B23 & "-" & "23" -> A022-141-23 | E23: 44978 | F23: 44980 | G23: 44986 | H23: Internal | I23: Inspection & Laboratory | J23: KA | K23: KA | L23: AmSpec | N23: Annual internal quality systems assessment (ISO 9001)
A24: Mobile, AL | B24: =VLOOKUP(Table245[[#This Row],[Location (drop-down)]],'List source'!D$2:E$59,2,FALSE) -> 146 | C24: 023 | D24: ="A" & C24 & "-" & B24 & "-" & "23" -> A023-146-23 | E24: 44977 | F24: 44979 | G24: 44981 | H24: Certifications | I24: Laboratory | J24: RB | K24: M. Cahill | L24: A2LA | M24: Certifications | N24: A2LA initial scope assessment (ISO 17025)
A25: Houston (HTC), TX | B25: =VLOOKUP(Table245[[#This Row],[Location (drop-down)]],'List source'!D$2:E$59,2,FALSE) -> 120 | C25: 024 | D25: ="A" & C25 & "-" & B25 & "-" & "23" -> A024-120-23 | E25: 44977 | F25: 44981 | G25: 44981 | H25: Certifications | I25: Laboratory | J25: MT | K25: A. Lathrop & S. Lerman | L25: A2LA | M25: Certifications | N25: A2LA renewal assessment (ISO 17025)
A26: Puerto Rico | B26: =VLOOKUP(Table245[[#This Row],[Location (drop-down)]],'List source'!D$2:E$59,2,FALSE) -> 192 | C26: 025 | D26: ="A" & C26 & "-" & B26 & "-" & "23" -> A025-192-23 | E26: 44985 | F26: 44985 | G26: 45021 | H26: Internal | I26: Inspection & Laboratory | J26: CS | K26: CS | L26: AmSpec | N26: Annual internal quality systems assessment (ISO 9001)
A27: Puerto Rico | B27: =VLOOKUP(Table245[[#This Row],[Location (drop-down)]],'List source'!D$2:E$59,2,FALSE) -> 192 | C27: 026 | D27: ="A" & C27 & "-" & B27 & "-" & "23" -> A026-192-23 | E27: 44966 | F27: 44967 | G27: 44978 | H27: Customer | I27: Inspection & Laboratory | J27: EC | K27: K. Byrd & S. Anthony | L27: Shell Oil | N27: Inspection, sampling, and laboratory areas assessed
A28: St Croix, USVI | B28: =VLOOKUP(Table245[[#This Row],[Location (drop-down)]],'List source'!D$2:E$59,2,FALSE) -> 210 | C28: 027 | D28: ="A" & C28 & "-" & B28 & "-" & "23" -> A027-210-23 | E28: 44970 | F28: 44971 | G28: 44986 | H28: Regulatory | I28: Inspection & Laboratory | J28: RB | K28: Arlene Badillo | L28: USCBP | M28: Certifications | N28: Operations / Inspection / Lab
A29: Houston (HTC), TX | B29: =VLOOKUP(Table245[[#This Row],[Location (drop-down)]],'List source'!D$2:E$59,2,FALSE) -> 120 | C29: 028 | D29: ="A" & C29 & "-" & B29 & "-" & "23" -> A028-120-23 | E29: 44959 | F29: 44960 | G29: uploaded | H29: Customer | I29: Laboratory | J29: HB | K29: Kiran Vibhandik | L29: ExxonMobil | N29: QP&G Lab
A30: Houston (HTC), TX | B30: =VLOOKUP(Table245[[#This Row],[Location (drop-down)]],'List source'!D$2:E$59,2,FALSE) -> 120 | C30: 029 | D30: ="A" & C30 & "-" & B30 & "-" & "23" -> A029-120-23 | E30: 44978 | F30: 44978 | G30: uploaded | H30: Customer | I30: Laboratory | J30: HB | K30: Maria Fernandez | L30: Citgo
A31: Houston (HTC), TX | B31: =VLOOKUP(Table245[[#This Row],[Location (drop-down)]],'List source'!D$2:E$59,2,FALSE) -> 120 | C31: 030 | D31: ="A" & C31 & "-" & B31 & "-" & "23" -> A030-120-23 | E31: 44965 | F31: 44965 | G31: uploaded | H31: Customer | I31: Laboratory | J31: HB | K31: Charalambos Papaioannou | L31: BP Air
A32: Houston (HTC), TX | B32: =VLOOKUP(Table245[[#This Row],[Location (drop-down)]],'List source'!D$2:E$59,2,FALSE) -> 120 | C32: 031 | D32: ="A" & C32 & "-" & B32 & "-" & "23" -> A031-120-23 | E32: 44986 | F32: 44986 | G32: uploaded | H32: Customer | I32: Laboratory | J32: HB | K32: Krashod Byrd, Scott Anthony, and Umit Ayna | L32: Shell Distillate
A33: New Orleans (Destrehan), LA | B33: =VLOOKUP(Table245[[#This Row],[Location (drop-down)]],'List source'!D$2:E$59,2,FALSE) -> 170 | C33: 032 | D33: ="A" & C33 & "-" & B33 & "-" & "23" -> A032-170-23 | E33: 44991 | F33: 44994 | G33: 45009 | H33: Internal | I33: Inspection & Laboratory | J33: AH | K33: MT/AH/RB | L33: AmSpec | N33: Annual internal quality systems assessment (ISO 9001)
A34: New Orleans (Destrehan), LA | B34: =VLOOKUP(Table245[[#This Row],[Location (drop-down)]],'List source'!D$2:E$59,2,FALSE) -> 170 | C34: 033 | D34: ="A" & C34 & "-" & B34 & "-" & "23" -> A033-170-23 | E34: 44991 | F34: 44994 | G34: 45009 | H34: Internal | I34: Laboratory | J34: AH | K34: MT/AH/RB | L34: AmSpec | N34: Annual internal quality systems assessment (ISO 17025)
A35: New Orleans (Destrehan), LA | B35: =VLOOKUP(Table245[[#This Row],[Location (drop-down)]],'List source'!D$2:E$59,2,FALSE) -> 170 | C35: 034 | D35: ="A" & C35 & "-" & B35 & "-" & "23" -> A034-170-23 | E35: 44991 | F35: 44994 | G35: 45009 | H35: Internal | I35: Laboratory | J35: AH | K35: MT/AH/RB | L35: AmSpec | N35: Annual internal quality systems assessment (BQ-9000)
A36: HOFTI / Channelview, TX | B36: =VLOOKUP(Table245[[#This Row],[Location (drop-down)]],'List source'!D$2:E$59,2,FALSE) -> 128 | C36: 035 | D36: ="A" & C36 & "-" & B36 & "-" & "23" -> A035-128-23 | E36: 45005 | F36: 45006 | G36: 45019 | H36: Internal | I36: Inspection & Laboratory | J36: AH | K36: AH | L36: AmSpec | N36: Annual internal quality systems assessment (ISO 9001)
A37: Freeport, TX | B37: =VLOOKUP(Table245[[#This Row],[Location (drop-down)]],'List source'!D$2:E$59,2,FALSE) -> 157 | C37: 036 | D37: ="A" & C37 & "-" & B37 & "-" & "23" -> A036-157-23 | E37: 45007 | F37: 45008 | G37: 45026 | H37: Internal | I37: Inspection & Laboratory | J37: AH | K37: AH/MT | L37: AmSpec | N37: Annual internal quality systems assessment (ISO 9001)
A38: Halifax (Dartmouth), NS | B38: =VLOOKUP(Table245[[#This Row],[Location (drop-down)]],'List source'!D$2:E$59,2,FALSE) -> 198 | C38: 037 | D38: ="A" & C38 & "-" & B38 & "-" & "23" -> A037-198-23 | E38: 45000 | F38: 45000 | G38: 45000 | H38: Customer | I38: Laboratory | J38: MT | K38: Matt Levis | L38: Irving | N38: D5452
A39: St Croix, USVI | B39: =VLOOKUP(Table245[[#This Row],[Location (drop-down)]],'List source'!D$2:E$59,2,FALSE) -> 210 | C39: 038 | D39: ="A" & C39 & "-" & B39 & "-" & "23" -> A038-210-23 | E39: 44999 | F39: 45000 | G39: 45021 | H39: Internal | I39: Inspection & Laboratory | J39: CS | K39: CS | L39: AmSpec | N39: Annual internal quality systems assessment (ISO 9001)
A40: Ft Lauderdale (Davie), FL | B40: =VLOOKUP(Table245[[#This Row],[Location (drop-down)]],'List source'!D$2:E$59,2,FALSE) -> 125 | C40: 039 | D40: ="A" & C40 & "-" & B40 & "-" & "23" -> A039-125-23 | E40: 45012 | F40: 45014 | G40: 45019 | H40: Internal | I40: Inspection & Laboratory | J40: RB | K40: RB | L40: AmSpec | N40: Annual internal quality systems assessment (ISO 9001)
...

Sheet PTO tracking
A1: Location (drop-down) | B1: Location ID | C1: # | D1: PTO # | E1: BRIEF DESCRIPTION OF NC if VOID: "VOID, Location, details (initials, date)" | F1: PT Program | G1: Parameter (s) | H1: Z-score (s) | I1: PTO initialized date | J1: QA team member initials | K1: Date Corrective Action completed | L1: Types of Root Cause (drop-down) | M1: Notes
A2: Memphis, TN | B2: =VLOOKUP(Table27[[#This Row],[Location (drop-down)]],'List source'!D$2:E$59,2,FALSE) -> 191 | C2: 001 | D2: ="PTO" & C2 & "-" & B2 & "-" & "23" -> PTO001-191-23 | E2: PT: CE506; D4052 - API, Z-Score = -4.24 | F2: GLRE | G2: D4052 - API | H2: -4.24 | I2: 45197 | J2: LJ | K2: 45358
A3: Memphis, TN | B3: =VLOOKUP(Table27[[#This Row],[Location (drop-down)]],'List source'!D$2:E$59,2,FALSE) -> 191 | C3: 002 | D3: ="PTO" & C3 & "-" & B3 & "-" & "23" -> PTO002-191-23 | E3: PT: CE507; D86 - Distillation - 20% - EP, Recovery, Residue, & Loss, Z-Scores = Multiple Outliers | F3: GLRE | G3: D86 - Distillation, 20% - EP, & Recovery | H3: Multiple Outliers | I3: 45142 | J3: JN | K3: 45197 | L3: Negligence (typo, no review) | M3: Transcription Error
A4: Texas City, TX | B4: =VLOOKUP(Table27[[#This Row],[Location (drop-down)]],'List source'!D$2:E$59,2,FALSE) -> 150 | C4: 003 | D4: ="PTO" & C4 & "-" & B4 & "-" & "23" -> PTO003-150-23 | E4: PT: TM06C-23; D2699 - Research Octane Number, Z-Score = -4.36 | F4: TRG | G4: D2699 - Research Octane Number | H4: -4.36 | I4: 45142 | J4: JN | K4: 45197 | L4: Negligence (typo, no review) | M4: Transcription Error
A5: Brownsville, TX | B5: =VLOOKUP(Table27[[#This Row],[Location (drop-down)]],'List source'!D$2:E$59,2,FALSE) -> 158 | C5: 004 | D5: ="PTO" & C5 & "-" & B5 & "-" & "23" -> PTO004-158-23 | E5: PT: TM06C-23; D2699 - Research Octane Number, Z-Score = -3.29 | F5: TRG | G5: D2699 - Research Octane Number | H5: -3.29 | I5: 45142 | J5: JN | K5: 45198 | L5: Negligence (typo, no review) | M5: Transcription Error
A6: Texas City, TX | B6: =VLOOKUP(Table27[[#This Row],[Location (drop-down)]],'List source'!D$2:E$59,2,FALSE) -> 150 | C6: 005 | D6: ="PTO" & C6 & "-" & B6 & "-" & "23" -> PTO005-150-23 | E6: PT: TM06-23; RVP, Z-Score = -10.27 | F6: TRG | G6: RVP | H6: -10.27 | I6: 45142 | J6: HB | K6: 45768
A7: Texas City, TX | B7: =VLOOKUP(Table27[[#This Row],[Location (drop-down)]],'List source'!D$2:E$59,2,FALSE) -> 150 | C7: 006 | D7: ="PTO" & C7 & "-" & B7 & "-" & "23" -> PTO006-150-23 | E7: PT: TM06-23; Sulfur | F7: TRG | G7: Sulfur | H7: -2.2 | I7: 45142 | J7: JN | K7: 45198 | L7: Normal statistics variance - no CA | M7: Meets Precision Performance and R criteria
A8: Brownsville, TX | B8: =VLOOKUP(Table27[[#This Row],[Location (drop-down)]],'List source'!D$2:E$59,2,FALSE) -> 158 | C8: 007 | D8: ="PTO" & C8 & "-" & B8 & "-" & "23" -> PTO007-158-23 | E8: PT: TM06-23; RVP | F8: TRG | G8: RVP | H8: -2.2 | I8: 45198 | J8: JN | K8: 45198 | L8: Normal statistics variance - no CA | M8: Meets Precision Performance and R criteria
A9: Los Angeles (Signal Hill), CA | B9: =VLOOKUP(Table27[[#This Row],[Location (drop-down)]],'List source'!D$2:E$59,2,FALSE) -> 130 | C9: 008 | D9: ="PTO" & C9 & "-" & B9 & "-" & "23" -> PTO008-130-23 | E9: PT: D-1195; D613 - Cetane Number | F9: NEG-D | G9: D613 - Cetane Number | H9: 2.84 | I9: 45198 | J9: JN | K9: 45198 | L9: Normal statistics variance - no CA | M9: Meets Precision Performance and R criteria
A10: Los Angeles (Signal Hill), CA | B10: 130 | C10: 009 | D10: ="PTO" & C10 & "-" & B10 & "-" & "23" -> PTO009-130-23 | E10: PT: D-1195; D4052 - Gravity, API at 60 °F, Z-Score = -16.83 | F10: NEG-D | G10: API Gravity | H10: -16.83 | I10: 45198 | J10: KA | K10: 45281 | L10: Training/ competency
A11: Los Angeles (Signal Hill), CA | B11: =VLOOKUP(Table27[[#This Row],[Location (drop-down)]],'List source'!D$2:E$59,2,FALSE) -> 130 | C11: 010 | D11: ="PTO" & C11 & "-" & B11 & "-" & "23" -> PTO010-130-23 | E11: PT: D-1195; D86 - Distillation - Recovery % | F11: NEG-D | G11: D86 - Distillation | H11: -2.18 | I11: 45198 | J11: JN | K11: 45198 | L11: Normal statistics variance - no CA | M11: Meets Precision Performance and R criteria
A12: Bellingham (Ferndale), WA | B12: =VLOOKUP(Table27[[#This Row],[Location (drop-down)]],'List source'!D$2:E$59,2,FALSE) -> 132 | C12: 011 | D12: ="PTO" & C12 & "-" & B12 & "-" & "23" -> PTO011-132-23 | E12: PT: D-1195; Multiple Parameters and Outliers | F12: NEG-D | G12: Multiple Parameters | H12: Mulitple Outliers | I12: 45198 | J12: JN | K12: 45198 | L12: Negligence (typo, no review) | M12: Wrong sample reported
A13: Ft Lauderdale (Davie), FL | B13: =VLOOKUP(Table27[[#This Row],[Location (drop-down)]],'List source'!D$2:E$59,2,FALSE) -> 125 | C13: 012 | D13: ="PTO" & C13 & "-" & B13 & "-" & "23" -> PTO012-125-23 | E13: PT: OC2304; RVP | F13: OC | G13: RVP | H13: 2.08 | I13: 45198 | J13: JN | K13: 45198 | L13: Normal statistics variance - no CA | M13: Meets Precision Performance and R criteria
A14: Puerto Rico | B14: =VLOOKUP(Table27[[#This Row],[Location (drop-down)]],'List source'!D$2:E$59,2,FALSE) -> 192 | C14: 013 | D14: ="PTO" & C14 & "-" & B14 & "-" & "23" -> PTO013-192-23 | E14: PT: OC2304; API Gravity | F14: OC | G14: API Gravity | H14: 2.5 | I14: 45198 | J14: JN | K14: 45198 | L14: Normal statistics variance - no CA | M14: Meets Precision Performance and R criteria
A15: Puerto Rico | B15: =VLOOKUP(Table27[[#This Row],[Location (drop-down)]],'List source'!D$2:E$59,2,FALSE) -> 192 | C15: 014 | D15: ="PTO" & C15 & "-" & B15 & "-" & "23" -> PTO014-192-23 | E15: PT: OC2304; D2699 - Research Octane Number | F15: OC | G15: D2699 - Research Octane Number | H15: -2.54 | I15: 45198 | J15: JN | K15: 45198 | L15: Normal statistics variance - no CA | M15: Meets Precision Performance and R criteria
A16: Halifax (Dartmouth), NS | B16: =VLOOKUP(Table27[[#This Row],[Location (drop-down)]],'List source'!D$2:E$59,2,FALSE) -> 198 | C16: 015 | D16: ="PTO" & C16 & "-" & B16 & "-" & "23" -> PTO015-198-23 | E16: PT: OC2304; D86 - Distillation, IBP & 10% | F16: OC | G16: D86 - Distillation | H16: 2.01 & 2.60 | I16: 45198 | J16: JN | K16: 45198 | L16: Normal statistics variance - no CA | M16: Meets Precision Performance and R criteria
A17: Halifax (Dartmouth), NS | B17: =VLOOKUP(Table27[[#This Row],[Location (drop-down)]],'List source'!D$2:E$59,2,FALSE) -> 198 | C17: 016 | D17: ="PTO" & C17 & "-" & B17 & "-" & "23" -> PTO016-198-23 | E17: PT: OC2304; D2700 - Motor Octane Number | F17: OC | G17: D2700 - Motor Octane Number | H17: 2.12 | I17: 45198 | J17: KA | K17: 45287 | L17: Normal statistics variance - no CA
A18: Chicago, IL | B18: =VLOOKUP(Table27[[#This Row],[Location (drop-down)]],'List source'!D$2:E$59,2,FALSE) -> 136 | C18: 017 | D18: ="PTO" & C18 & "-" & B18 & "-" & "23" -> PTO017-136-23 | E18: PT: LPG2303; D2163 - Hydrocarbons, n-butane | F18: LPG | G18: D2163 - Hydrocarbons | H18: 2.42 | I18: 45199 | J18: JN | K18: 45199 | L18: Normal statistics variance - no CA | M18: Meets Precision Performance and R criteria
A19: Avenel (NYH), NJ | B19: =VLOOKUP(Table27[[#This Row],[Location (drop-down)]],'List source'!D$2:E$59,2,FALSE) -> 110 | C19: 018 | D19: ="PTO" & C19 & "-" & B19 & "-" & "23" -> PTO018-110-23 | E19: PT: BIOD2304; D2500 - Cloud Point, biodiesel | F19: BIOD | G19: D2500 - Cloud Point | H19: 2.5 | I19: 45201 | J19: JN | K19: 45214 | L19: Negligence (typo, no review) | M19: Transcription Error
A20: Avenel (NYH), NJ | B20: =VLOOKUP(Table27[[#This Row],[Location (drop-down)]],'List source'!D$2:E$59,2,FALSE) -> 110 | C20: 019 | D20: ="PTO" & C20 & "-" & B20 & "-" & "23" -> PTO019-110-23 | E20: PT: BIOD2304; D6371 - Cold Filter Plugging Point, CFPP | F20: BIOD | G20: D6371 - Cold Filter Plugging Point | H20: -2.1 | I20: 45201 | J20: Eco | K20: 45610 | L20: Training/ competency
A21: Avenel (NYH), NJ | B21: =VLOOKUP(Table27[[#This Row],[Location (drop-down)]],'List source'!D$2:E$59,2,FALSE) -> 110 | C21: 020 | D21: ="PTO" & C21 & "-" & B21 & "-" & "23" -> PTO020-110-23 | E21: PT: BIOD2304; D93 - Flash Point, PMCC, Proc C, corrected, Z-Score = -4.38 | F21: BIOD | G21: D93 - Flash Point | H21: -4.38 | I21: 45201 | J21: JN | K21: 45214 | L21: Negligence (typo, no review) | M21: Transcription Error
A22: Avenel (NYH), NJ | B22: =VLOOKUP(Table27[[#This Row],[Location (drop-down)]],'List source'!D$2:E$59,2,FALSE) -> 110 | C22: 021 | D22: ="PTO" & C22 & "-" & B22 & "-" & "23" -> PTO021-110-23 | E22: PT: BIOD2304; D6079 - Lubricity, HFRR, Major Axis | F22: BIOD | G22: D6079 - Lubricity | H22: 2.4 | I22: 45199 | J22: JN | K22: 45199 | L22: Normal statistics variance - no CA | M22: Meets Precision Performance and R criteria
A23: Houston (HTC), TX | B23: =VLOOKUP(Table27[[#This Row],[Location (drop-down)]],'List source'!D$2:E$59,2,FALSE) -> 120 | C23: 022 | D23: ="PTO" & C23 & "-" & B23 & "-" & "23" -> PTO022-120-23 | E23: PT: BIOD2304; D6584 - Triglyceride, by GC | F23: BIOD | G23: D6584 - Triglyceride, by GC | H23: 2.47 | I23: 45199 | J23: JN | K23: 45199 | L23: Normal statistics variance - no CA | M23: Meets Precision Performance and R criteria
A24: Los Angeles (Signal Hill), CA | B24: =VLOOKUP(Table27[[#This Row],[Location (drop-down)]],'List source'!D$2:E$59,2,FALSE) -> 130 | C24: 023 | D24: ="PTO" & C24 & "-" & B24 & "-" & "23" -> PTO023-130-23 | E24: PT: BIOD2304; EN 14538 - Elements, Na + K, by ICP/OES, Z-Score = 7.26 | F24: BIOD | G24: EN 14538 - Elements | H24: 7.26 | I24: 45201 | J24: HM | K24: 45400 | L24: Training/ competency
A25: San Francisco (Concord), CA | B25: =VLOOKUP(Table27[[#This Row],[Location (drop-down)]],'List source'!D$2:E$59,2,FALSE) -> 131 | C25: 024 | D25: ="PTO" & C25 & "-" & B25 & "-" & "23" -> PTO024-131-23 | E25: PT: CO2303; D4807 - Sediment, Membrane Filtration | F25: CO | G25: D4807 - Sediment, Membrane Filtration | H25: 2.03 | I25: 45201 | J25: RB | K25: 45215 | L25: Training/ competency | M25: Filter paper not washed completely by solvent
A26: Bellingham (Ferndale), WA | B26: =VLOOKUP(Table27[[#This Row],[Location (drop-down)]],'List source'!D$2:E$59,2,FALSE) -> 132 | C26: 025 | D26: ="PTO" & C26 & "-" & B26 & "-" & "23" -> PTO025-132-23 | E26: PT: CO2303; D5002 - Density, digital, 15 °C | F26: CO | G26: D5002 - Density, digital, 15 °C | H26: -2.1 | I26: 45201 | J26: JN | K26: 45201 | L26: Normal statistics variance - no CA | M26: Meets Precision Performance and R criteria
A27: Bellingham (Ferndale), WA | B27: =VLOOKUP(Table27[[#This Row],[Location (drop-down)]],'List source'!D$2:E$59,2,FALSE) -> 132 | C27: 026 | D27: ="PTO" & C27 & "-" & B27 & "-" & "23" -> PTO026-132-23 | E27: PT: CO2303; D473 - Sediment | F27: CO | G27: D473 - Sediment | H27: 2.56 | I27: 45201 | J27: JN | K27: 45212 | L27: Negligence (typo, no review) | M27: Transcription Error
A28: Bellingham (Ferndale), WA | B28: =VLOOKUP(Table27[[#This Row],[Location (drop-down)]],'List source'!D$2:E$59,2,FALSE) -> 132 | C28: 027 | D28: ="PTO" & C28 & "-" & B28 & "-" & "23" -> PTO027-132-23 | E28: PT: CO2303; D445 - Viscosity, Kinematic, 40 °C, Z-Score = -30.93 | F28: CO | G28: D445 - Viscosity | H28: -30.93 | I28: 45201 | J28: HM | K28: 45799
A29: Kenai, AK | B29: =VLOOKUP(Table27[[#This Row],[Location (drop-down)]],'List source'!D$2:E$59,2,FALSE) -> 133 | C29: 028 | D29: ="PTO" & C29 & "-" & B29 & "-" & "23" -> PTO028-133-23 | E29: PT: CO2303; D4928 - Water, Coulometric KF, Z-Score = -5.41 | F29: CO | G29: D4928 - Water, Coulometric KF | H29: -5.41 | I29: 45201 | J29: HM | K29: 46014
