Workbook

Sheet Assessment '24
A1: Location (drop-down) | B1: Location ID | C1: # | D1: Assessment # | E1: Start Date | F1: End Date | G1: Report Issued | H1: Type of Assessment (drop-down) | I1: Scope of Assessment (drop-down) | J1: QA In Charge (Get a copy of assessment report or summary) | K1: Assessor(s) / Auditor(s) name(s) | L1: Assessor's company | M1: Agency Type (Regulatory / certification / accreditation agency) (drop-down) | N1: Brief description of assessment scope
A2: Pittsburgh, PA | B2: =VLOOKUP(Table245[[#This Row],[Location (drop-down)]],'List source'!D$2:E$60,2,FALSE) -> 178 | C2: 001 | D2: ="A" & C2 & "-" & B2 & "-" & "24" -> A001-178-24 | E2: 45300 | F2: 45302 | G2: 45308 | H2: Internal | I2: Inspection & Laboratory | J2: RB | K2: RB | L2: AmSpec | N2: Annual internal quality systems assessment (ISO 9001)
A3: San Francisco (Concord), CA | B3: =VLOOKUP(Table245[[#This Row],[Location (drop-down)]],'List source'!D$2:E$60,2,FALSE) -> 131 | C3: 002 | D3: ="A" & C3 & "-" & B3 & "-" & "24" -> A002-131-24 | E3: 45300 | F3: 45302 | G3: 45317 | H3: Internal | I3: Inspection & Laboratory | J3: AH | K3: MT/ AH / KA | L3: AmSpec | N3: Annual internal quality systems assessment (ISO 9001)
A4: San Francisco (Concord), CA | B4: =VLOOKUP(Table245[[#This Row],[Location (drop-down)]],'List source'!D$2:E$60,2,FALSE) -> 131 | C4: 003 | D4: ="A" & C4 & "-" & B4 & "-" & "24" -> A003-131-24 | E4: 45300 | F4: 45302 | G4: 45317 | H4: Internal | I4: Laboratory | J4: AH | K4: MT / AH / KA | L4: AmSpec | N4: Annual internal quality systems assessment (ISO 17025)
A5: Boston (Everett), MA | B5: =VLOOKUP(Table245[[#This Row],[Location (drop-down)]],'List source'!D$2:E$60,2,FALSE) -> 141 | C5: 004 | D5: ="A" & C5 & "-" & B5 & "-" & "24" -> A004-141-24 | E5: 44930 | F5: 44930 | G5: 45392 | H5: Regulatory | I5: Laboratory | J5: AH | K5: Carol Carmen | L5: Mass Dept of Environmental Protection | M5: Regulatory | N5: Random Oversite (unannounced) visit
A6: Brownsville, TX | B6: =VLOOKUP(Table245[[#This Row],[Location (drop-down)]],'List source'!D$2:E$60,2,FALSE) -> 158 | C6: 005 | D6: ="A" & C6 & "-" & B6 & "-" & "24" -> A005-158-24 | E6: 45313 | F6: 45315 | G6: 45317 | H6: Internal | I6: Inspection & Laboratory | J6: RB | K6: MT / HB / RB | L6: AmSpec | N6: Annual internal quality systems assessment (ISO 9001)
A7: Brownsville, TX | B7: =VLOOKUP(Table245[[#This Row],[Location (drop-down)]],'List source'!D$2:E$60,2,FALSE) -> 158 | C7: 006 | D7: ="A" & C7 & "-" & B7 & "-" & "24" -> A006-158-24 | E7: 45313 | F7: 45315 | G7: 45511 | H7: Internal | I7: Laboratory | J7: RB | K7: MT / HB / RB | L7: AmSpec | N7: Annual internal quality systems assessment (ISO 17025)
A8: Cape Canaveral, FL | B8: =VLOOKUP(Table245[[#This Row],[Location (drop-down)]],'List source'!D$2:E$60,2,FALSE) -> 127 | C8: 007 | D8: ="A" & C8 & "-" & B8 & "-" & "24" -> A007-127-24 | E8: 45313 | F8: 45316 | G8: 45511 | H8: Internal | I8: Inspection & Laboratory | J8: KA | K8: KA | L8: AmSpec | N8: Annual internal quality systems assessment (ISO 9001)
A9: Cincinnati (Erlanger), OH | B9: =VLOOKUP(Table245[[#This Row],[Location (drop-down)]],'List source'!D$2:E$60,2,FALSE) -> 138 | C9: 008 | D9: ="A" & C9 & "-" & B9 & "-" & "24" -> A008-138-24 | E9: 45320 | F9: 45323 | G9: 45359 | H9: Internal | I9: Inspection & Laboratory | J9: AH | K9: AH | L9: AmSpec | N9: Annual internal quality systems assessment (ISO 9001)
A10: Puerto Rico | B10: =VLOOKUP(Table245[[#This Row],[Location (drop-down)]],'List source'!D$2:E$60,2,FALSE) -> 192 | C10: 009 | D10: ="A" & C10 & "-" & B10 & "-" & "24" -> A009-192-24 | E10: 45327 | F10: 45330 | G10: 45335 | H10: Internal | I10: Inspection & Laboratory | J10: KA | K10: KA / RB | L10: AmSpec | N10: Annual internal quality systems assessment (ISO 9001)
A11: Mont Belvieu, TX | B11: =VLOOKUP(Table245[[#This Row],[Location (drop-down)]],'List source'!D$2:E$60,2,FALSE) -> 120a | C11: 010 | D11: ="A" & C11 & "-" & B11 & "-" & "24" -> A010-120a-24 | E11: 45322 | F11: 45322 | G11: 45342 | H11: Internal | I11: Laboratory | J11: MT | K11: MT / HB | L11: AmSpec | N11: Annual internal quality systems assessment (ISO 9001)
A12: San Francisco (Concord), CA | B12: =VLOOKUP(Table245[[#This Row],[Location (drop-down)]],'List source'!D$2:E$60,2,FALSE) -> 131 | C12: 011 | D12: ="A" & C12 & "-" & B12 & "-" & "24" -> A011-131-24 | E12: 45321 | F12: 45321 | H12: Customer | I12: Inspection | J12: HM | L12: Chevron | N12: Chevron - Inspection
A13: New Orleans (Destrehan), LA | B13: =VLOOKUP(Table245[[#This Row],[Location (drop-down)]],'List source'!D$2:E$60,2,FALSE) -> 170 | C13: 012 | D13: ="A" & C13 & "-" & B13 & "-" & "24" -> A012-170-24 | E13: 45323 | F13: 45324 | G13: 45324 | H13: Certifications | I13: Laboratory | J13: DA | K13: Scott Fenwick | L13: Clean Fuel (BQ) | M13: Accredited agency | N13: BQ 9000 Renewal
A14: Corpus Christi, TX | B14: =VLOOKUP(Table245[[#This Row],[Location (drop-down)]],'List source'!D$2:E$60,2,FALSE) -> 155 | C14: 013 | D14: ="A" & C14 & "-" & B14 & "-" & "24" -> A013-155-24 | E14: 45334 | F14: 45336 | G14: 45358 | H14: Internal | I14: Inspection & Laboratory | J14: AH | K14: AH / MT | L14: AmSpec | N14: Annual internal quality systems assessment (ISO 9001)
A15: Corpus Christi, TX | B15: =VLOOKUP(Table245[[#This Row],[Location (drop-down)]],'List source'!D$2:E$60,2,FALSE) -> 155 | C15: 014 | D15: ="A" & C15 & "-" & B15 & "-" & "24" -> A014-155-24 | E15: 45334 | F15: 45336 | G15: 45358 | H15: Internal | I15: Laboratory | J15: AH | K15: AH / MT | L15: AmSpec | N15: Annual internal quality systems assessment (ISO 17025)
A16: Mobile, AL | B16: =VLOOKUP(Table245[[#This Row],[Location (drop-down)]],'List source'!D$2:E$60,2,FALSE) -> 146 | C16: 015 | D16: ="A" & C16 & "-" & B16 & "-" & "24" -> A015-146-24 | E16: 45329 | F16: 45329 | G16: 45331 | H16: Certifications | I16: Laboratory | J16: MT | K16: Michael Cahill | L16: A2LA | M16: Accredited agency | N16: A2LA surveillance assessment
A17: Baton Rouge (Gonzales), LA | B17: =VLOOKUP(Table245[[#This Row],[Location (drop-down)]],'List source'!D$2:E$60,2,FALSE) -> 190 | C17: 016 | D17: ="A" & C17 & "-" & B17 & "-" & "24" -> A016-190-24 | E17: 45341 | F17: 45344 | G17: 45350 | H17: Internal | I17: Inspection & Laboratory | J17: RB | K17: KA / RB | L17: AmSpec | N17: Annual internal quality systems assessment (ISO 9001)
A18: Baton Rouge (Gonzales), LA | B18: =VLOOKUP(Table245[[#This Row],[Location (drop-down)]],'List source'!D$2:E$60,2,FALSE) -> 190 | C18: 017 | D18: ="A" & C18 & "-" & B18 & "-" & "24" -> A017-190-24 | E18: 45373 | F18: 45373 | G18: 45379 | H18: Internal | I18: Laboratory | J18: KA | K18: KA / RB | L18: AmSpec | N18: Annual internal quality systems assessment (ISO 17025)
A19: San Francisco (Concord), CA | B19: 131 | C19: 018 | D19: ="A" & C19 & "-" & B19 & "-" & "24" -> A018-131-24 | E19: 45338 | F19: 45338 | H19: Regulatory | I19: Inspection & Laboratory | J19: HM | K19: RAQUEL A HERNANDEZANDRES | L19: USCBP | M19: Regulatory | N19: USCBP Triennial
A20: San Francisco (Concord), CA | B20: 131 | C20: 019 | D20: ="A" & C20 & "-" & B20 & "-" & "24" -> A019-131-24 | E20: 45344 | F20: 45344 | G20: 45422 | H20: Customer | I20: Inspection & Laboratory | J20: HM | K20: Barry Duffin | L20: Phillips 66 | N20: P66
A21: Texas City, TX | B21: =VLOOKUP(Table245[[#This Row],[Location (drop-down)]],'List source'!D$2:E$60,2,FALSE) -> 150 | C21: 020 | D21: ="A" & C21 & "-" & B21 & "-" & "24" -> A020-150-24 | E21: 45348 | F21: 45351 | G21: 45369 | H21: Internal | I21: Inspection & Laboratory | J21: AH | K21: AH / HB | L21: AmSpec | N21: Annual internal quality systems assessment (ISO 9001)
A22: Texas City, TX | B22: =VLOOKUP(Table245[[#This Row],[Location (drop-down)]],'List source'!D$2:E$60,2,FALSE) -> 150 | C22: 021 | D22: ="A" & C22 & "-" & B22 & "-" & "24" -> A021-150-24 | E22: 45348 | F22: 45351 | G22: 45369 | H22: Internal | I22: Laboratory | J22: AH | K22: AH / HB | L22: AmSpec | N22: Annual internal quality systems assessment (ISO 17025)
A23: Freeport, TX | B23: =VLOOKUP(Table245[[#This Row],[Location (drop-down)]],'List source'!D$2:E$60,2,FALSE) -> 157 | C23: 022 | D23: ="A" & C23 & "-" & B23 & "-" & "24" -> A022-157-24 | E23: 45355 | F23: 45356 | G23: 45363 | H23: Internal | I23: Inspection & Laboratory | J23: KA | K23: KA / MT | L23: AmSpec | N23: Annual internal quality systems assessment (ISO 9001)
A24: HOFTI / Channelview, TX | B24: =VLOOKUP(Table245[[#This Row],[Location (drop-down)]],'List source'!D$2:E$60,2,FALSE) -> 128 | C24: 023 | D24: ="A" & C24 & "-" & B24 & "-" & "24" -> A023-128-24 | E24: 45357 | F24: 45358 | G24: 45363 | H24: Internal | I24: Inspection & Laboratory | J24: KA | K24: KA / MT | L24: AmSpec | N24: Annual internal quality systems assessment (ISO 9001)
A25: Albany, NY | B25: =VLOOKUP(Table245[[#This Row],[Location (drop-down)]],'List source'!D$2:E$60,2,FALSE) -> 111 | C25: 024 | D25: ="A" & C25 & "-" & B25 & "-" & "24" -> A024-111-24 | E25: 45357 | F25: 45358 | G25: 45364 | H25: Internal | I25: Inspection | J25: RB | K25: RB | L25: AmSpec
A26: New Orleans (Destrehan), LA | B26: =VLOOKUP(Table245[[#This Row],[Location (drop-down)]],'List source'!D$2:E$60,2,FALSE) -> 170 | C26: 025 | D26: ="A" & C26 & "-" & B26 & "-" & "24" -> A025-170-24 | E26: 45351 | F26: 45351 | G26: 45380 | H26: Customer | I26: Inspection & Laboratory | J26: DA | K26: N. Triche / J. Chauvin | L26: Marathon | N26: Marathon
A27: San Francisco (Concord), CA | B27: =VLOOKUP(Table245[[#This Row],[Location (drop-down)]],'List source'!D$2:E$60,2,FALSE) -> 131 | C27: 026 | D27: ="A" & C27 & "-" & B27 & "-" & "24" -> A026-131-24 | E27: 45337 | F27: 45337 | H27: Regulatory | I27: Laboratory | J27: HM | K27: Joe Mackin | L27: California Department of Public Health | M27: Regulatory | N27: Routine Radiation Safety and Protection Program Inspection
A28: San Francisco (Concord), CA | B28: =VLOOKUP(Table245[[#This Row],[Location (drop-down)]],'List source'!D$2:E$60,2,FALSE) -> 131 | C28: 027 | D28: ="A" & C28 & "-" & B28 & "-" & "24" -> A027-131-24 | E28: 45349 | F28: 45351 | G28: 45385 | H28: Certifications | I28: Laboratory | J28: HM | K28: Steven Lerman | L28: A2LA | M28: Accredited agency | N28: A2LA renewal assessment (ISO 17025)
A29: Houston (HTC), TX | B29: =VLOOKUP(Table245[[#This Row],[Location (drop-down)]],'List source'!D$2:E$60,2,FALSE) -> 120 | C29: 028 | D29: ="A" & C29 & "-" & B29 & "-" & "24" -> A028-120-24 | E29: 45356 | F29: 45357 | G29: 45358 | H29: Certifications | I29: Laboratory | J29: CS | K29: Robert Japiske | L29: Clean Fuels Alliance | M29: Certifications | N29: BQ9000 Renewal Accreditation
A30: VOIDED ASSMT/CAR/PAR NO | B30: VOID | C30: 029 | D30: ="A" & C30 & "-" & B30 & "-" & "24" -> A029-VOID-24 | E30: 45357 | F30: 45357 | G30: VOID | H30: VOID | I30: Laboratory | J30: HM | K30: VOID | L30: VOID | N30: Chevron: Visit to assess Opportunities and Capabilities by Moore, Brad / Yang, Shengzu / Khuu, Hung
A31: Boston (Everett), MA | B31: =VLOOKUP(Table245[[#This Row],[Location (drop-down)]],'List source'!D$2:E$60,2,FALSE) -> 141 | C31: 030 | D31: ="A" & C31 & "-" & B31 & "-" & "24" -> A030-141-24 | E31: 45362 | F31: 45364 | G31: 45371 | H31: Internal | I31: Inspection & Laboratory | J31: AH | K31: AH | L31: AmSpec
A32: New Orleans (Destrehan), LA | B32: =VLOOKUP(Table245[[#This Row],[Location (drop-down)]],'List source'!D$2:E$60,2,FALSE) -> 170 | C32: 031 | D32: ="A" & C32 & "-" & B32 & "-" & "24" -> A031-170-24 | E32: 45369 | F32: 45372 | G32: 45391 | H32: Internal | I32: Inspection & Laboratory | J32: KA | K32: KA / MT / RB | L32: AmSpec | N32: Annual internal quality systems assessment (ISO 9001)
A33: New Orleans (Destrehan), LA | B33: =VLOOKUP(Table245[[#This Row],[Location (drop-down)]],'List source'!D$2:E$60,2,FALSE) -> 170 | C33: 032 | D33: ="A" & C33 & "-" & B33 & "-" & "24" -> A032-170-24 | E33: 45369 | F33: 45372 | G33: 45391 | H33: Internal | I33: Laboratory | J33: KA | K33: KA / MT / RB | L33: AmSpec | N33: Annual internal quality systems assessment (ISO 17025)
A34: New Orleans (Destrehan), LA | B34: =VLOOKUP(Table245[[#This Row],[Location (drop-down)]],'List source'!D$2:E$60,2,FALSE) -> 170 | C34: 033 | D34: ="A" & C34 & "-" & B34 & "-" & "24" -> A033-170-24 | E34: 45369 | F34: 45372 | G34: 45391 | H34: Internal | I34: Laboratory | J34: KA | K34: KA / MT / RB | L34: AmSpec | N34: Annual internal quality systems assessment (BQ-9000)
A35: New Orleans (Destrehan), LA | B35: =VLOOKUP(Table245[[#This Row],[Location (drop-down)]],'List source'!D$2:E$60,2,FALSE) -> 170 | C35: 034 | D35: ="A" & C35 & "-" & B35 & "-" & "24" -> A034-170-24 | E35: 45359 | F35: 45359 | G35: 45393 | H35: Customer | I35: Inspection & Laboratory | J35: DA | K35: S. Anthony | L35: Shell
A36: Ft Lauderdale (Davie), FL | B36: =VLOOKUP(Table245[[#This Row],[Location (drop-down)]],'List source'!D$2:E$60,2,FALSE) -> 125 | C36: 035 | D36: ="A" & C36 & "-" & B36 & "-" & "24" -> A035-125-24 | E36: 45376 | F36: 45379 | G36: 45398 | H36: Internal | I36: Inspection & Laboratory | J36: AH | K36: AH | L36: AmSpec | N36: Annual internal quality systems assessment (ISO 9001)
A37: VOIDED ASSMT/CAR/PAR NO | B37: =VLOOKUP(Table245[[#This Row],[Location (drop-down)]],'List source'!D$2:E$60,2,FALSE) -> VOID | C37: 036 | D37: ="A" & C37 & "-" & B37 & "-" & "24" -> A036-VOID-24 | E37: 45344 | F37: 45344 | G37: VOID | H37: VOID | I37: Inspection & Laboratory | J37: RB | K37: VOID | L37: VOID | N37: AmSpec Annual HSSE Audit by Louis
A38: Levis (Quebec City), Quebec | B38: =VLOOKUP(Table245[[#This Row],[Location (drop-down)]],'List source'!D$2:E$60,2,FALSE) -> 194 | C38: 037 | D38: ="A" & C38 & "-" & B38 & "-" & "24" -> A037-194-24 | E38: 45383 | F38: 45384 | G38: 45390 | H38: Internal | I38: Inspection & Laboratory | J38: MT | K38: MT | L38: AmSpec
A39: Levis (Quebec City), Quebec | B39: =VLOOKUP(Table245[[#This Row],[Location (drop-down)]],'List source'!D$2:E$60,2,FALSE) -> 194 | C39: 038 | D39: ="A" & C39 & "-" & B39 & "-" & "24" -> A038-194-24 | E39: 45383 | F39: 45384 | G39: 45390 | H39: Internal | I39: Laboratory | J39: MT | K39: MT | L39: AmSpec
A40: Houston (HTC), TX | B40: =VLOOKUP(Table245[[#This Row],[Location (drop-down)]],'List source'!D$2:E$60,2,FALSE) -> 120 | C40: 039 | D40: ="A" & C40 & "-" & B40 & "-" & "24" -> A039-120-24 | E40: 45373 | F40: 45373 | H40: Customer | I40: Laboratory | J40: HB | K40: Jonathan Bobbett | L40: BP Oil | N40: BP Laboratory Audit Report
...

Sheet PTO 2024
A1: Location (drop-down) | B1: Location ID | C1: # | D1: PTO # | E1: BRIEF DESCRIPTION OF NC if VOID: "VOID, Location, details (initials, date)" | F1: PT Program | G1: Parameter (s) | H1: Z-score (s) | I1: PTO initialized date | J1: QA team member initials | K1: Effectiveness Review & date deemed effective | L1: Notes | M1: Number (for sorting) | N1: Days open if not closed
A2: Avenel (NYH), NJ | B2: =VLOOKUP(Table27[[#This Row],[Location (drop-down)]],'List source'!D$2:E$60,2,FALSE) -> 110 | C2: 001 | D2: ="PTO" & C2 & "-" & B2 & "-" & "24" -> PTO001-110-24 | E2: PT: ETOH2308; D7319 - Sulfate, Existent, by DI-IC | F2: {=MID(LEFT(Table27[[#This Row],[BRIEF DESCRIPTION OF NC if VOID: "VOID, Location, details (initials, date)"]], INDEX(_xlfn._xlws.FILTER(ROW(INDIRECT("1:" & LEN(Table27[[#This Row],[BRIEF DESCRIPTION OF NC if VOID: "VOID, Location, details (initials, date)"]]))), (48 <= CODE(MID(Table27[[#This Row],[BRIEF DESCRIPTION OF NC if VOID: "VOID, Location, details (initials, date)"]], ROW(INDIRECT("1:" & LEN(Table27[[#This Row],[BRIEF DESCRIPTION OF NC if VOID: "VOID, Location, details (initials, date)"]]))), 1))) * (CODE(MID(Table27[[#This Row],[BRIEF DESCRIPTION OF NC if VOID: "VOID, Location, details (initials, date)"]], ROW(INDIRECT("1:" & LEN(Table27[[#This Row],[BRIEF DESCRIPTION OF NC if VOID: "VOID, Location, details (initials, date)"]]))), 1)) <= 57)), 1) - 1), FIND(":", Table27[[#This Row],[BRIEF DESCRIPTION OF NC if VOID: "VOID, Location, details (initials, date)"]]) + 2, LEN(Table27[[#This Row],[BRIEF DESCRIPTION OF NC if VOID: "VOID, Location, details (initials, date)"]]))} -> ETOH | G2: =MID(LEFT(Table27[[#This Row],[BRIEF DESCRIPTION OF NC if VOID: "VOID, Location, details (initials, date)"]], FIND(",", Table27[[#This Row],[BRIEF DESCRIPTION OF NC if VOID: "VOID, Location, details (initials, date)"]]) - 1), FIND("{token}", SUBSTITUTE(Table27[[#This Row],[BRIEF DESCRIPTION OF NC if VOID: "VOID, Location, details (initials, date)"]], " ", "{token}", 2)) + 1, LEN(Table27[[#This Row],[BRIEF DESCRIPTION OF NC if VOID: "VOID, Location, details (initials, date)"]])) -> D7319 - Sulfate | H2: 2.12 | I2: 45301 | J2: JN | K2: 45301 | L2: Meets both the precision performance and reproducibility criteria. | M2: 1 | N2: =IF(ISBLANK(K2), TODAY()-(I2), "CLOSED") -> CLOSED
A3: Avenel (NYH), NJ | B3: =VLOOKUP(Table27[[#This Row],[Location (drop-down)]],'List source'!D$2:E$60,2,FALSE) -> 110 | C3: 002 | D3: ="PTO" & C3 & "-" & B3 & "-" & "24" -> PTO002-110-24 | E3: PT: ETOH2308; E1064 - Water, by Coul KF, Z-Score = 12.14 | F3: {=MID(LEFT(Table27[[#This Row],[BRIEF DESCRIPTION OF NC if VOID: "VOID, Location, details (initials, date)"]], INDEX(_xlfn._xlws.FILTER(ROW(INDIRECT("1:" & LEN(Table27[[#This Row],[BRIEF DESCRIPTION OF NC if VOID: "VOID, Location, details (initials, date)"]]))), (48 <= CODE(MID(Table27[[#This Row],[BRIEF DESCRIPTION OF NC if VOID: "VOID, Location, details (initials, date)"]], ROW(INDIRECT("1:" & LEN(Table27[[#This Row],[BRIEF DESCRIPTION OF NC if VOID: "VOID, Location, details (initials, date)"]]))), 1))) * (CODE(MID(Table27[[#This Row],[BRIEF DESCRIPTION OF NC if VOID: "VOID, Location, details (initials, date)"]], ROW(INDIRECT("1:" & LEN(Table27[[#This Row],[BRIEF DESCRIPTION OF NC if VOID: "VOID, Location, details (initials, date)"]]))), 1)) <= 57)), 1) - 1), FIND(":", Table27[[#This Row],[BRIEF DESCRIPTION OF NC if VOID: "VOID, Location, details (initials, date)"]]) + 2, LEN(Table27[[#This Row],[BRIEF DESCRIPTION OF NC if VOID: "VOID, Location, details (initials, date)"]]))} -> ETOH | G3: =MID(LEFT(Table27[[#This Row],[BRIEF DESCRIPTION OF NC if VOID: "VOID, Location, details (initials, date)"]], FIND(",", Table27[[#This Row],[BRIEF DESCRIPTION OF NC if VOID: "VOID, Location, details (initials, date)"]]) - 1), FIND("{token}", SUBSTITUTE(Table27[[#This Row],[BRIEF DESCRIPTION OF NC if VOID: "VOID, Location, details (initials, date)"]], " ", "{token}", 2)) + 1, LEN(Table27[[#This Row],[BRIEF DESCRIPTION OF NC if VOID: "VOID, Location, details (initials, date)"]])) -> E1064 - Water | H3: 12.14 | I3: 45301 | J3: Eco | K3: 45610 | M3: 2 | N3: =IF(ISBLANK(K3), TODAY()-(I3), "CLOSED") -> CLOSED
A4: Houston (HTC), TX | B4: =VLOOKUP(Table27[[#This Row],[Location (drop-down)]],'List source'!D$2:E$60,2,FALSE) -> 120 | C4: 003 | D4: ="PTO" & C4 & "-" & B4 & "-" & "24" -> PTO003-120-24 | E4: PT: ETOH2308; D4052 - Density, Relative, @ 15.56 °C, Z-Score = 6.24 | F4: {=MID(LEFT(Table27[[#This Row],[BRIEF DESCRIPTION OF NC if VOID: "VOID, Location, details (initials, date)"]], INDEX(_xlfn._xlws.FILTER(ROW(INDIRECT("1:" & LEN(Table27[[#This Row],[BRIEF DESCRIPTION OF NC if VOID: "VOID, Location, details (initials, date)"]]))), (48 <= CODE(MID(Table27[[#This Row],[BRIEF DESCRIPTION OF NC if VOID: "VOID, Location, details (initials, date)"]], ROW(INDIRECT("1:" & LEN(Table27[[#This Row],[BRIEF DESCRIPTION OF NC if VOID: "VOID, Location, details (initials, date)"]]))), 1))) * (CODE(MID(Table27[[#This Row],[BRIEF DESCRIPTION OF NC if VOID: "VOID, Location, details (initials, date)"]], ROW(INDIRECT("1:" & LEN(Table27[[#This Row],[BRIEF DESCRIPTION OF NC if VOID: "VOID, Location, details (initials, date)"]]))), 1)) <= 57)), 1) - 1), FIND(":", Table27[[#This Row],[BRIEF DESCRIPTION OF NC if VOID: "VOID, Location, details (initials, date)"]]) + 2, LEN(Table27[[#This Row],[BRIEF DESCRIPTION OF NC if VOID: "VOID, Location, details (initials, date)"]]))} -> ETOH | G4: =MID(LEFT(Table27[[#This Row],[BRIEF DESCRIPTION OF NC if VOID: "VOID, Location, details (initials, date)"]], FIND(",", Table27[[#This Row],[BRIEF DESCRIPTION OF NC if VOID: "VOID, Location, details (initials, date)"]]) - 1), FIND("{token}", SUBSTITUTE(Table27[[#This Row],[BRIEF DESCRIPTION OF NC if VOID: "VOID, Location, details (initials, date)"]], " ", "{token}", 2)) + 1, LEN(Table27[[#This Row],[BRIEF DESCRIPTION OF NC if VOID: "VOID, Location, details (initials, date)"]])) -> D4052 - Density | H4: 6.24 | I4: 45301 | J4: ECu | K4: 45559 | M4: 3 | N4: =IF(ISBLANK(K4), TODAY()-(I4), "CLOSED") -> CLOSED
A5: San Francisco (Concord), CA | B5: =VLOOKUP(Table27[[#This Row],[Location (drop-down)]],'List source'!D$2:E$60,2,FALSE) -> 131 | C5: 004 | D5: ="PTO" & C5 & "-" & B5 & "-" & "24" -> PTO004-131-24 | E5: PT: ETOH2308; D7319 - Sulfate, Existent, by DI-IC | F5: {=MID(LEFT(Table27[[#This Row],[BRIEF DESCRIPTION OF NC if VOID: "VOID, Location, details (initials, date)"]], INDEX(_xlfn._xlws.FILTER(ROW(INDIRECT("1:" & LEN(Table27[[#This Row],[BRIEF DESCRIPTION OF NC if VOID: "VOID, Location, details (initials, date)"]]))), (48 <= CODE(MID(Table27[[#This Row],[BRIEF DESCRIPTION OF NC if VOID: "VOID, Location, details (initials, date)"]], ROW(INDIRECT("1:" & LEN(Table27[[#This Row],[BRIEF DESCRIPTION OF NC if VOID: "VOID, Location, details (initials, date)"]]))), 1))) * (CODE(MID(Table27[[#This Row],[BRIEF DESCRIPTION OF NC if VOID: "VOID, Location, details (initials, date)"]], ROW(INDIRECT("1:" & LEN(Table27[[#This Row],[BRIEF DESCRIPTION OF NC if VOID: "VOID, Location, details (initials, date)"]]))), 1)) <= 57)), 1) - 1), FIND(":", Table27[[#This Row],[BRIEF DESCRIPTION OF NC if VOID: "VOID, Location, details (initials, date)"]]) + 2, LEN(Table27[[#This Row],[BRIEF DESCRIPTION OF NC if VOID: "VOID, Location, details (initials, date)"]]))} -> ETOH | G5: =MID(LEFT(Table27[[#This Row],[BRIEF DESCRIPTION OF NC if VOID: "VOID, Location, details (initials, date)"]], FIND(",", Table27[[#This Row],[BRIEF DESCRIPTION OF NC if VOID: "VOID, Location, details (initials, date)"]]) - 1), FIND("{token}", SUBSTITUTE(Table27[[#This Row],[BRIEF DESCRIPTION OF NC if VOID: "VOID, Location, details (initials, date)"]], " ", "{token}", 2)) + 1, LEN(Table27[[#This Row],[BRIEF DESCRIPTION OF NC if VOID: "VOID, Location, details (initials, date)"]])) -> D7319 - Sulfate | H5: 2.12 | I5: 45301 | J5: JN | K5: 45301 | L5: Meets both the precision performance and reproducibility criteria. | M5: 4 | N5: =IF(ISBLANK(K5), TODAY()-(I5), "CLOSED") -> CLOSED
A6: Chicago, IL | B6: =VLOOKUP(Table27[[#This Row],[Location (drop-down)]],'List source'!D$2:E$60,2,FALSE) -> 136 | C6: 005 | D6: ="PTO" & C6 & "-" & B6 & "-" & "24" -> PTO005-136-24 | E6: PT: ETOH2308; D6423 - pHe, Z-Score = 2.16 | F6: {=MID(LEFT(Table27[[#This Row],[BRIEF DESCRIPTION OF NC if VOID: "VOID, Location, details (initials, date)"]], INDEX(_xlfn._xlws.FILTER(ROW(INDIRECT("1:" & LEN(Table27[[#This Row],[BRIEF DESCRIPTION OF NC if VOID: "VOID, Location, details (initials, date)"]]))), (48 <= CODE(MID(Table27[[#This Row],[BRIEF DESCRIPTION OF NC if VOID: "VOID, Location, details (initials, date)"]], ROW(INDIRECT("1:" & LEN(Table27[[#This Row],[BRIEF DESCRIPTION OF NC if VOID: "VOID, Location, details (initials, date)"]]))), 1))) * (CODE(MID(Table27[[#This Row],[BRIEF DESCRIPTION OF NC if VOID: "VOID, Location, details (initials, date)"]], ROW(INDIRECT("1:" & LEN(Table27[[#This Row],[BRIEF DESCRIPTION OF NC if VOID: "VOID, Location, details (initials, date)"]]))), 1)) <= 57)), 1) - 1), FIND(":", Table27[[#This Row],[BRIEF DESCRIPTION OF NC if VOID: "VOID, Location, details (initials, date)"]]) + 2, LEN(Table27[[#This Row],[BRIEF DESCRIPTION OF NC if VOID: "VOID, Location, details (initials, date)"]]))} -> ETOH | G6: =MID(LEFT(Table27[[#This Row],[BRIEF DESCRIPTION OF NC if VOID: "VOID, Location, details (initials, date)"]], FIND(",", Table27[[#This Row],[BRIEF DESCRIPTION OF NC if VOID: "VOID, Location, details (initials, date)"]]) - 1), FIND("{token}", SUBSTITUTE(Table27[[#This Row],[BRIEF DESCRIPTION OF NC if VOID: "VOID, Location, details (initials, date)"]], " ", "{token}", 2)) + 1, LEN(Table27[[#This Row],[BRIEF DESCRIPTION OF NC if VOID: "VOID, Location, details (initials, date)"]])) -> D6423 - pHe | H6: 2.16 | I6: 45301 | J6: LJ | K6: 45330 | M6: 5 | N6: =IF(ISBLANK(K6), TODAY()-(I6), "CLOSED") -> CLOSED
A7: Providence, RI | B7: =VLOOKUP(Table27[[#This Row],[Location (drop-down)]],'List source'!D$2:E$60,2,FALSE) -> 140 | C7: 006 | D7: ="PTO" & C7 & "-" & B7 & "-" & "24" -> PTO006-140-24 | E7: PT: ETOH2308; D5501 - Methanol, By GC, Z-Score = 2.45 | F7: {=MID(LEFT(Table27[[#This Row],[BRIEF DESCRIPTION OF NC if VOID: "VOID, Location, details (initials, date)"]], INDEX(_xlfn._xlws.FILTER(ROW(INDIRECT("1:" & LEN(Table27[[#This Row],[BRIEF DESCRIPTION OF NC if VOID: "VOID, Location, details (initials, date)"]]))), (48 <= CODE(MID(Table27[[#This Row],[BRIEF DESCRIPTION OF NC if VOID: "VOID, Location, details (initials, date)"]], ROW(INDIRECT("1:" & LEN(Table27[[#This Row],[BRIEF DESCRIPTION OF NC if VOID: "VOID, Location, details (initials, date)"]]))), 1))) * (CODE(MID(Table27[[#This Row],[BRIEF DESCRIPTION OF NC if VOID: "VOID, Location, details (initials, date)"]], ROW(INDIRECT("1:" & LEN(Table27[[#This Row],[BRIEF DESCRIPTION OF NC if VOID: "VOID, Location, details (initials, date)"]]))), 1)) <= 57)), 1) - 1), FIND(":", Table27[[#This Row],[BRIEF DESCRIPTION OF NC if VOID: "VOID, Location, details (initials, date)"]]) + 2, LEN(Table27[[#This Row],[BRIEF DESCRIPTION OF NC if VOID: "VOID, Location, details (initials, date)"]]))} -> ETOH | G7: =MID(LEFT(Table27[[#This Row],[BRIEF DESCRIPTION OF NC if VOID: "VOID, Location, details (initials, date)"]], FIND(",", Table27[[#This Row],[BRIEF DESCRIPTION OF NC if VOID: "VOID, Location, details (initials, date)"]]) - 1), FIND("{token}", SUBSTITUTE(Table27[[#This Row],[BRIEF DESCRIPTION OF NC if VOID: "VOID, Location, details (initials, date)"]], " ", "{token}", 2)) + 1, LEN(Table27[[#This Row],[BRIEF DESCRIPTION OF NC if VOID: "VOID, Location, details (initials, date)"]])) -> D5501 - Methanol | H7: 2.45 | I7: 45301 | J7: ECu | K7: 45539 | M7: 6 | N7: =IF(ISBLANK(K7), TODAY()-(I7), "CLOSED") -> CLOSED
A8: New Haven, CT | B8: =VLOOKUP(Table27[[#This Row],[Location (drop-down)]],'List source'!D$2:E$60,2,FALSE) -> 145 | C8: 007 | D8: ="PTO" & C8 & "-" & B8 & "-" & "24" -> PTO007-145-24 | E8: PT: ETOH2308; D5453 - Sulfur, by UVF, Z-Score = 3.21 | F8: {=MID(LEFT(Table27[[#This Row],[BRIEF DESCRIPTION OF NC if VOID: "VOID, Location, details (initials, date)"]], INDEX(_xlfn._xlws.FILTER(ROW(INDIRECT("1:" & LEN(Table27[[#This Row],[BRIEF DESCRIPTION OF NC if VOID: "VOID, Location, details (initials, date)"]]))), (48 <= CODE(MID(Table27[[#This Row],[BRIEF DESCRIPTION OF NC if VOID: "VOID, Location, details (initials, date)"]], ROW(INDIRECT("1:" & LEN(Table27[[#This Row],[BRIEF DESCRIPTION OF NC if VOID: "VOID, Location, details (initials, date)"]]))), 1))) * (CODE(MID(Table27[[#This Row],[BRIEF DESCRIPTION OF NC if VOID: "VOID, Location, details (initials, date)"]], ROW(INDIRECT("1:" & LEN(Table27[[#This Row],[BRIEF DESCRIPTION OF NC if VOID: "VOID, Location, details (initials, date)"]]))), 1)) <= 57)), 1) - 1), FIND(":", Table27[[#This Row],[BRIEF DESCRIPTION OF NC if VOID: "VOID, Location, details (initials, date)"]]) + 2, LEN(Table27[[#This Row],[BRIEF DESCRIPTION OF NC if VOID: "VOID, Location, details (initials, date)"]]))} -> ETOH | G8: =MID(LEFT(Table27[[#This Row],[BRIEF DESCRIPTION OF NC if VOID: "VOID, Location, details (initials, date)"]], FIND(",", Table27[[#This Row],[BRIEF DESCRIPTION OF NC if VOID: "VOID, Location, details (initials, date)"]]) - 1), FIND("{token}", SUBSTITUTE(Table27[[#This Row],[BRIEF DESCRIPTION OF NC if VOID: "VOID, Location, details (initials, date)"]], " ", "{token}", 2)) + 1, LEN(Table27[[#This Row],[BRIEF DESCRIPTION OF NC if VOID: "VOID, Location, details (initials, date)"]])) -> D5453 - Sulfur | H8: 3.21 | I8: 45301 | J8: ECu | K8: 45356 | M8: 7 | N8: =IF(ISBLANK(K8), TODAY()-(I8), "CLOSED") -> CLOSED
A9: Yorktown (Norfolk), VA | B9: =VLOOKUP(Table27[[#This Row],[Location (drop-down)]],'List source'!D$2:E$61,2,FALSE) -> 185 | C9: 008 | D9: ="PTO" & C9 & "-" & B9 & "-" & "24" -> PTO008-185-24 | E9: PT: ETOH2308; D5501 - Methanol, By GC, Z-Score = 2.92 | F9: {=MID(LEFT(Table27[[#This Row],[BRIEF DESCRIPTION OF NC if VOID: "VOID, Location, details (initials, date)"]], INDEX(_xlfn._xlws.FILTER(ROW(INDIRECT("1:" & LEN(Table27[[#This Row],[BRIEF DESCRIPTION OF NC if VOID: "VOID, Location, details (initials, date)"]]))), (48 <= CODE(MID(Table27[[#This Row],[BRIEF DESCRIPTION OF NC if VOID: "VOID, Location, details (initials, date)"]], ROW(INDIRECT("1:" & LEN(Table27[[#This Row],[BRIEF DESCRIPTION OF NC if VOID: "VOID, Location, details (initials, date)"]]))), 1))) * (CODE(MID(Table27[[#This Row],[BRIEF DESCRIPTION OF NC if VOID: "VOID, Location, details (initials, date)"]], ROW(INDIRECT("1:" & LEN(Table27[[#This Row],[BRIEF DESCRIPTION OF NC if VOID: "VOID, Location, details (initials, date)"]]))), 1)) <= 57)), 1) - 1), FIND(":", Table27[[#This Row],[BRIEF DESCRIPTION OF NC if VOID: "VOID, Location, details (initials, date)"]]) + 2, LEN(Table27[[#This Row],[BRIEF DESCRIPTION OF NC if VOID: "VOID, Location, details (initials, date)"]]))} -> ETOH | G9: =MID(LEFT(Table27[[#This Row],[BRIEF DESCRIPTION OF NC if VOID: "VOID, Location, details (initials, date)"]], FIND(",", Table27[[#This Row],[BRIEF DESCRIPTION OF NC if VOID: "VOID, Location, details (initials, date)"]]) - 1), FIND("{token}", SUBSTITUTE(Table27[[#This Row],[BRIEF DESCRIPTION OF NC if VOID: "VOID, Location, details (initials, date)"]], " ", "{token}", 2)) + 1, LEN(Table27[[#This Row],[BRIEF DESCRIPTION OF NC if VOID: "VOID, Location, details (initials, date)"]])) -> D5501 - Methanol | H9: 2.92 | I9: 45301 | J9: Eco | K9: 45328 | M9: 8 | N9: =IF(ISBLANK(K9), TODAY()-(I9), "CLOSED") -> CLOSED
A10: Yorktown (Norfolk), VA | B10: =VLOOKUP(Table27[[#This Row],[Location (drop-down)]],'List source'!D$2:E$61,2,FALSE) -> 185 | C10: 009 | D10: ="PTO" & C10 & "-" & B10 & "-" & "24" -> PTO009-185-24 | E10: PT: ETOH2308; E1064 - Water, by Coul KF, Z-Score = -6.31 | F10: {=MID(LEFT(Table27[[#This Row],[BRIEF DESCRIPTION OF NC if VOID: "VOID, Location, details (initials, date)"]], INDEX(_xlfn._xlws.FILTER(ROW(INDIRECT("1:" & LEN(Table27[[#This Row],[BRIEF DESCRIPTION OF NC if VOID: "VOID, Location, details (initials, date)"]]))), (48 <= CODE(MID(Table27[[#This Row],[BRIEF DESCRIPTION OF NC if VOID: "VOID, Location, details (initials, date)"]], ROW(INDIRECT("1:" & LEN(Table27[[#This Row],[BRIEF DESCRIPTION OF NC if VOID: "VOID, Location, details (initials, date)"]]))), 1))) * (CODE(MID(Table27[[#This Row],[BRIEF DESCRIPTION OF NC if VOID: "VOID, Location, details (initials, date)"]], ROW(INDIRECT("1:" & LEN(Table27[[#This Row],[BRIEF DESCRIPTION OF NC if VOID: "VOID, Location, details (initials, date)"]]))), 1)) <= 57)), 1) - 1), FIND(":", Table27[[#This Row],[BRIEF DESCRIPTION OF NC if VOID: "VOID, Location, details (initials, date)"]]) + 2, LEN(Table27[[#This Row],[BRIEF DESCRIPTION OF NC if VOID: "VOID, Location, details (initials, date)"]]))} -> ETOH | G10: =MID(LEFT(Table27[[#This Row],[BRIEF DESCRIPTION OF NC if VOID: "VOID, Location, details (initials, date)"]], FIND(",", Table27[[#This Row],[BRIEF DESCRIPTION OF NC if VOID: "VOID, Location, details (initials, date)"]]) - 1), FIND("{token}", SUBSTITUTE(Table27[[#This Row],[BRIEF DESCRIPTION OF NC if VOID: "VOID, Location, details (initials, date)"]], " ", "{token}", 2)) + 1, LEN(Table27[[#This Row],[BRIEF DESCRIPTION OF NC if VOID: "VOID, Location, details (initials, date)"]])) -> E1064 - Water | H10: -6.31 | I10: 45301 | J10: MT | K10: 45337 | M10: 9 | N10: =IF(ISBLANK(K10), TODAY()-(I10), "CLOSED") -> CLOSED
A11: Memphis, TN | B11: =VLOOKUP(Table27[[#This Row],[Location (drop-down)]],'List source'!D$2:E$60,2,FALSE) -> 191 | C11: 010 | D11: ="PTO" & C11 & "-" & B11 & "-" & "24" -> PTO010-191-24 | E11: PT: ETOH2308; D7319 - Chloride, Inorganic, & Sulfate, Existent, by DI-IC | F11: {=MID(LEFT(Table27[[#This Row],[BRIEF DESCRIPTION OF NC if VOID: "VOID, Location, details (initials, date)"]], INDEX(_xlfn._xlws.FILTER(ROW(INDIRECT("1:" & LEN(Table27[[#This Row],[BRIEF DESCRIPTION OF NC if VOID: "VOID, Location, details (initials, date)"]]))), (48 <= CODE(MID(Table27[[#This Row],[BRIEF DESCRIPTION OF NC if VOID: "VOID, Location, details (initials, date)"]], ROW(INDIRECT("1:" & LEN(Table27[[#This Row],[BRIEF DESCRIPTION OF NC if VOID: "VOID, Location, details (initials, date)"]]))), 1))) * (CODE(MID(Table27[[#This Row],[BRIEF DESCRIPTION OF NC if VOID: "VOID, Location, details (initials, date)"]], ROW(INDIRECT("1:" & LEN(Table27[[#This Row],[BRIEF DESCRIPTION OF NC if VOID: "VOID, Location, details (initials, date)"]]))), 1)) <= 57)), 1) - 1), FIND(":", Table27[[#This Row],[BRIEF DESCRIPTION OF NC if VOID: "VOID, Location, details (initials, date)"]]) + 2, LEN(Table27[[#This Row],[BRIEF DESCRIPTION OF NC if VOID: "VOID, Location, details (initials, date)"]]))} -> ETOH | G11: =MID(LEFT(Table27[[#This Row],[BRIEF DESCRIPTION OF NC if VOID: "VOID, Location, details (initials, date)"]], FIND(",", Table27[[#This Row],[BRIEF DESCRIPTION OF NC if VOID: "VOID, Location, details (initials, date)"]]) - 1), FIND("{token}", SUBSTITUTE(Table27[[#This Row],[BRIEF DESCRIPTION OF NC if VOID: "VOID, Location, details (initials, date)"]], " ", "{token}", 2)) + 1, LEN(Table27[[#This Row],[BRIEF DESCRIPTION OF NC if VOID: "VOID, Location, details (initials, date)"]])) -> D7319 - Chloride | H11: 2.7 | I11: 45301 | J11: JN | K11: 45301 | L11: Meets both the precision performance and reproducibility criteria. | M11: 10 | N11: =IF(ISBLANK(K11), TODAY()-(I11), "CLOSED") -> CLOSED
A12: Memphis, TN | B12: =VLOOKUP(Table27[[#This Row],[Location (drop-down)]],'List source'!D$2:E$60,2,FALSE) -> 191 | C12: 011 | D12: ="PTO" & C12 & "-" & B12 & "-" & "24" -> PTO011-191-24 | E12: PT: ETOH2308; D5501 - Methanol, By GC, Z-Score = 2.45 | F12: {=MID(LEFT(Table27[[#This Row],[BRIEF DESCRIPTION OF NC if VOID: "VOID, Location, details (initials, date)"]], INDEX(_xlfn._xlws.FILTER(ROW(INDIRECT("1:" & LEN(Table27[[#This Row],[BRIEF DESCRIPTION OF NC if VOID: "VOID, Location, details (initials, date)"]]))), (48 <= CODE(MID(Table27[[#This Row],[BRIEF DESCRIPTION OF NC if VOID: "VOID, Location, details (initials, date)"]], ROW(INDIRECT("1:" & LEN(Table27[[#This Row],[BRIEF DESCRIPTION OF NC if VOID: "VOID, Location, details (initials, date)"]]))), 1))) * (CODE(MID(Table27[[#This Row],[BRIEF DESCRIPTION OF NC if VOID: "VOID, Location, details (initials, date)"]], ROW(INDIRECT("1:" & LEN(Table27[[#This Row],[BRIEF DESCRIPTION OF NC if VOID: "VOID, Location, details (initials, date)"]]))), 1)) <= 57)), 1) - 1), FIND(":", Table27[[#This Row],[BRIEF DESCRIPTION OF NC if VOID: "VOID, Location, details (initials, date)"]]) + 2, LEN(Table27[[#This Row],[BRIEF DESCRIPTION OF NC if VOID: "VOID, Location, details (initials, date)"]]))} -> ETOH | G12: =MID(LEFT(Table27[[#This Row],[BRIEF DESCRIPTION OF NC if VOID: "VOID, Location, details (initials, date)"]], FIND(",", Table27[[#This Row],[BRIEF DESCRIPTION OF NC if VOID: "VOID, Location, details (initials, date)"]]) - 1), FIND("{token}", SUBSTITUTE(Table27[[#This Row],[BRIEF DESCRIPTION OF NC if VOID: "VOID, Location, details (initials, date)"]], " ", "{token}", 2)) + 1, LEN(Table27[[#This Row],[BRIEF DESCRIPTION OF NC if VOID: "VOID, Location, details (initials, date)"]])) -> D5501 - Methanol | H12: 2.45 | I12: 45301 | J12: LJ | K12: 45422 | M12: 11 | N12: =IF(ISBLANK(K12), TODAY()-(I12), "CLOSED") -> CLOSED
A13: Montreal, QC | B13: =VLOOKUP(Table27[[#This Row],[Location (drop-down)]],'List source'!D$2:E$60,2,FALSE) -> 197 | C13: 012 | D13: ="PTO" & C13 & "-" & B13 & "-" & "24" -> PTO012-197-24 | E13: PT: ETOH2308; D5501 - Ethanol, By GC, Z-Score = 2.95 | F13: {=MID(LEFT(Table27[[#This Row],[BRIEF DESCRIPTION OF NC if VOID: "VOID, Location, details (initials, date)"]], INDEX(_xlfn._xlws.FILTER(ROW(INDIRECT("1:" & LEN(Table27[[#This Row],[BRIEF DESCRIPTION OF NC if VOID: "VOID, Location, details (initials, date)"]]))), (48 <= CODE(MID(Table27[[#This Row],[BRIEF DESCRIPTION OF NC if VOID: "VOID, Location, details (initials, date)"]], ROW(INDIRECT("1:" & LEN(Table27[[#This Row],[BRIEF DESCRIPTION OF NC if VOID: "VOID, Location, details (initials, date)"]]))), 1))) * (CODE(MID(Table27[[#This Row],[BRIEF DESCRIPTION OF NC if VOID: "VOID, Location, details (initials, date)"]], ROW(INDIRECT("1:" & LEN(Table27[[#This Row],[BRIEF DESCRIPTION OF NC if VOID: "VOID, Location, details (initials, date)"]]))), 1)) <= 57)), 1) - 1), FIND(":", Table27[[#This Row],[BRIEF DESCRIPTION OF NC if VOID: "VOID, Location, details (initials, date)"]]) + 2, LEN(Table27[[#This Row],[BRIEF DESCRIPTION OF NC if VOID: "VOID, Location, details (initials, date)"]]))} -> ETOH | G13: =MID(LEFT(Table27[[#This Row],[BRIEF DESCRIPTION OF NC if VOID: "VOID, Location, details (initials, date)"]], FIND(",", Table27[[#This Row],[BRIEF DESCRIPTION OF NC if VOID: "VOID, Location, details (initials, date)"]]) - 1), FIND("{token}", SUBSTITUTE(Table27[[#This Row],[BRIEF DESCRIPTION OF NC if VOID: "VOID, Location, details (initials, date)"]], " ", "{token}", 2)) + 1, LEN(Table27[[#This Row],[BRIEF DESCRIPTION OF NC if VOID: "VOID, Location, details (initials, date)"]])) -> D5501 - Ethanol | H13: 2.95 | I13: 45301 | J13: KA | K13: 45657 | M13: 12 | N13: =IF(ISBLANK(K13), TODAY()-(I13), "CLOSED") -> CLOSED
A14: Montreal, QC | B14: =VLOOKUP(Table27[[#This Row],[Location (drop-down)]],'List source'!D$2:E$60,2,FALSE) -> 197 | C14: 013 | D14: ="PTO" & C14 & "-" & B14 & "-" & "24" -> PTO013-197-24 | E14: PT: ETOH2308; E1064 - Water, by Coul KF, Z-Score = 11.49 | F14: {=MID(LEFT(Table27[[#This Row],[BRIEF DESCRIPTION OF NC if VOID: "VOID, Location, details (initials, date)"]], INDEX(_xlfn._xlws.FILTER(ROW(INDIRECT("1:" & LEN(Table27[[#This Row],[BRIEF DESCRIPTION OF NC if VOID: "VOID, Location, details (initials, date)"]]))), (48 <= CODE(MID(Table27[[#This Row],[BRIEF DESCRIPTION OF NC if VOID: "VOID, Location, details (initials, date)"]], ROW(INDIRECT("1:" & LEN(Table27[[#This Row],[BRIEF DESCRIPTION OF NC if VOID: "VOID, Location, details (initials, date)"]]))), 1))) * (CODE(MID(Table27[[#This Row],[BRIEF DESCRIPTION OF NC if VOID: "VOID, Location, details (initials, date)"]], ROW(INDIRECT("1:" & LEN(Table27[[#This Row],[BRIEF DESCRIPTION OF NC if VOID: "VOID, Location, details (initials, date)"]]))), 1)) <= 57)), 1) - 1), FIND(":", Table27[[#This Row],[BRIEF DESCRIPTION OF NC if VOID: "VOID, Location, details (initials, date)"]]) + 2, LEN(Table27[[#This Row],[BRIEF DESCRIPTION OF NC if VOID: "VOID, Location, details (initials, date)"]]))} -> ETOH | G14: =MID(LEFT(Table27[[#This Row],[BRIEF DESCRIPTION OF NC if VOID: "VOID, Location, details (initials, date)"]], FIND(",", Table27[[#This Row],[BRIEF DESCRIPTION OF NC if VOID: "VOID, Location, details (initials, date)"]]) - 1), FIND("{token}", SUBSTITUTE(Table27[[#This Row],[BRIEF DESCRIPTION OF NC if VOID: "VOID, Location, details (initials, date)"]], " ", "{token}", 2)) + 1, LEN(Table27[[#This Row],[BRIEF DESCRIPTION OF NC if VOID: "VOID, Location, details (initials, date)"]])) -> E1064 - Water | H14: 11.49 | I14: 45301 | J14: KA | K14: 45601 | M14: 13 | N14: =IF(ISBLANK(K14), TODAY()-(I14), "CLOSED") -> CLOSED
A15: Collins (Purvis), MS | B15: =VLOOKUP(Table27[[#This Row],[Location (drop-down)]],'List source'!D$2:E$60,2,FALSE) -> 115 | C15: 014 | D15: ="PTO" & C15 & "-" & B15 & "-" & "24" -> PTO014-115-24 | E15: PT: CE511; D86 - Distillation, Auto, 20% , Z-Score = 3.46 | F15: {=MID(LEFT(Table27[[#This Row],[BRIEF DESCRIPTION OF NC if VOID: "VOID, Location, details (initials, date)"]], INDEX(_xlfn._xlws.FILTER(ROW(INDIRECT("1:" & LEN(Table27[[#This Row],[BRIEF DESCRIPTION OF NC if VOID: "VOID, Location, details (initials, date)"]]))), (48 <= CODE(MID(Table27[[#This Row],[BRIEF DESCRIPTION OF NC if VOID: "VOID, Location, details (initials, date)"]], ROW(INDIRECT("1:" & LEN(Table27[[#This Row],[BRIEF DESCRIPTION OF NC if VOID: "VOID, Location, details (initials, date)"]]))), 1))) * (CODE(MID(Table27[[#This Row],[BRIEF DESCRIPTION OF NC if VOID: "VOID, Location, details (initials, date)"]], ROW(INDIRECT("1:" & LEN(Table27[[#This Row],[BRIEF DESCRIPTION OF NC if VOID: "VOID, Location, details (initials, date)"]]))), 1)) <= 57)), 1) - 1), FIND(":", Table27[[#This Row],[BRIEF DESCRIPTION OF NC if VOID: "VOID, Location, details (initials, date)"]]) + 2, LEN(Table27[[#This Row],[BRIEF DESCRIPTION OF NC if VOID: "VOID, Location, details (initials, date)"]]))} -> CE | G15: =MID(LEFT(Table27[[#This Row],[BRIEF DESCRIPTION OF NC if VOID: "VOID, Location, details (initials, date)"]], FIND(",", Table27[[#This Row],[BRIEF DESCRIPTION OF NC if VOID: "VOID, Location, details (initials, date)"]]) - 1), FIND("{token}", SUBSTITUTE(Table27[[#This Row],[BRIEF DESCRIPTION OF NC if VOID: "VOID, Location, details (initials, date)"]], " ", "{token}", 2)) + 1, LEN(Table27[[#This Row],[BRIEF DESCRIPTION OF NC if VOID: "VOID, Location, details (initials, date)"]])) -> D86 - Distillation | H15: 3.46 | I15: 45301 | J15: JN | K15: 45303 | L15: Confirmed Transcription Error. | M15: 14 | N15: =IF(ISBLANK(K15), TODAY()-(I15), "CLOSED") -> CLOSED
A16: Chicago, IL | B16: =VLOOKUP(Table27[[#This Row],[Location (drop-down)]],'List source'!D$2:E$60,2,FALSE) -> 136 | C16: 015 | D16: ="PTO" & C16 & "-" & B16 & "-" & "24" -> PTO015-136-24 | E16: PT: CE511; D5453 - Sulfur, by UVF | F16: {=MID(LEFT(Table27[[#This Row],[BRIEF DESCRIPTION OF NC if VOID: "VOID, Location, details (initials, date)"]], INDEX(_xlfn._xlws.FILTER(ROW(INDIRECT("1:" & LEN(Table27[[#This Row],[BRIEF DESCRIPTION OF NC if VOID: "VOID, Location, details (initials, date)"]]))), (48 <= CODE(MID(Table27[[#This Row],[BRIEF DESCRIPTION OF NC if VOID: "VOID, Location, details (initials, date)"]], ROW(INDIRECT("1:" & LEN(Table27[[#This Row],[BRIEF DESCRIPTION OF NC if VOID: "VOID, Location, details (initials, date)"]]))), 1))) * (CODE(MID(Table27[[#This Row],[BRIEF DESCRIPTION OF NC if VOID: "VOID, Location, details (initials, date)"]], ROW(INDIRECT("1:" & LEN(Table27[[#This Row],[BRIEF DESCRIPTION OF NC if VOID: "VOID, Location, details (initials, date)"]]))), 1)) <= 57)), 1) - 1), FIND(":", Table27[[#This Row],[BRIEF DESCRIPTION OF NC if VOID: "VOID, Location, details (initials, date)"]]) + 2, LEN(Table27[[#This Row],[BRIEF DESCRIPTION OF NC if VOID: "VOID, Location, details (initials, date)"]]))} -> CE | G16: =MID(LEFT(Table27[[#This Row],[BRIEF DESCRIPTION OF NC if VOID: "VOID, Location, details (initials, date)"]], FIND(",", Table27[[#This Row],[BRIEF DESCRIPTION OF NC if VOID: "VOID, Location, details (initials, date)"]]) - 1), FIND("{token}", SUBSTITUTE(Table27[[#This Row],[BRIEF DESCRIPTION OF NC if VOID: "VOID, Location, details (initials, date)"]], " ", "{token}", 2)) + 1, LEN(Table27[[#This Row],[BRIEF DESCRIPTION OF NC if VOID: "VOID, Location, details (initials, date)"]])) -> D5453 - Sulfur | H16: 2.13 | I16: 45301 | J16: JN | K16: 45301 | L16: Meets both the precision performance and reproducibility criteria. | M16: 15 | N16: =IF(ISBLANK(K16), TODAY()-(I16), "CLOSED") -> CLOSED
A17: Chicago, IL | B17: =VLOOKUP(Table27[[#This Row],[Location (drop-down)]],'List source'!D$2:E$60,2,FALSE) -> 136 | C17: 016 | D17: ="PTO" & C17 & "-" & B17 & "-" & "24" -> PTO016-136-24 | E17: PT: CE511; D5188 - V/L Temp, Z-Score = -2.50 | F17: {=MID(LEFT(Table27[[#This Row],[BRIEF DESCRIPTION OF NC if VOID: "VOID, Location, details (initials, date)"]], INDEX(_xlfn._xlws.FILTER(ROW(INDIRECT("1:" & LEN(Table27[[#This Row],[BRIEF DESCRIPTION OF NC if VOID: "VOID, Location, details (initials, date)"]]))), (48 <= CODE(MID(Table27[[#This Row],[BRIEF DESCRIPTION OF NC if VOID: "VOID, Location, details (initials, date)"]], ROW(INDIRECT("1:" & LEN(Table27[[#This Row],[BRIEF DESCRIPTION OF NC if VOID: "VOID, Location, details (initials, date)"]]))), 1))) * (CODE(MID(Table27[[#This Row],[BRIEF DESCRIPTION OF NC if VOID: "VOID, Location, details (initials, date)"]], ROW(INDIRECT("1:" & LEN(Table27[[#This Row],[BRIEF DESCRIPTION OF NC if VOID: "VOID, Location, details (initials, date)"]]))), 1)) <= 57)), 1) - 1), FIND(":", Table27[[#This Row],[BRIEF DESCRIPTION OF NC if VOID: "VOID, Location, details (initials, date)"]]) + 2, LEN(Table27[[#This Row],[BRIEF DESCRIPTION OF NC if VOID: "VOID, Location, details (initials, date)"]]))} -> CE | G17: =MID(LEFT(Table27[[#This Row],[BRIEF DESCRIPTION OF NC if VOID: "VOID, Location, details (initials, date)"]], FIND(",", Table27[[#This Row],[BRIEF DESCRIPTION OF NC if VOID: "VOID, Location, details (initials, date)"]]) - 1), FIND("{token}", SUBSTITUTE(Table27[[#This Row],[BRIEF DESCRIPTION OF NC if VOID: "VOID, Location, details (initials, date)"]], " ", "{token}", 2)) + 1, LEN(Table27[[#This Row],[BRIEF DESCRIPTION OF NC if VOID: "VOID, Location, details (initials, date)"]])) -> D5188 - V/L Temp | H17: -2.5 | I17: 45301 | J17: LJ | K17: 45315 | M17: 16 | N17: =IF(ISBLANK(K17), TODAY()-(I17), "CLOSED") -> CLOSED
A18: Memphis, TN | B18: =VLOOKUP(Table27[[#This Row],[Location (drop-down)]],'List source'!D$2:E$60,2,FALSE) -> 191 | C18: 017 | D18: ="PTO" & C18 & "-" & B18 & "-" & "24" -> PTO017-191-24 | E18: PT: CE511; D3606 - Benzene, Z-Score = -3.01 | F18: {=MID(LEFT(Table27[[#This Row],[BRIEF DESCRIPTION OF NC if VOID: "VOID, Location, details (initials, date)"]], INDEX(_xlfn._xlws.FILTER(ROW(INDIRECT("1:" & LEN(Table27[[#This Row],[BRIEF DESCRIPTION OF NC if VOID: "VOID, Location, details (initials, date)"]]))), (48 <= CODE(MID(Table27[[#This Row],[BRIEF DESCRIPTION OF NC if VOID: "VOID, Location, details (initials, date)"]], ROW(INDIRECT("1:" & LEN(Table27[[#This Row],[BRIEF DESCRIPTION OF NC if VOID: "VOID, Location, details (initials, date)"]]))), 1))) * (CODE(MID(Table27[[#This Row],[BRIEF DESCRIPTION OF NC if VOID: "VOID, Location, details (initials, date)"]], ROW(INDIRECT("1:" & LEN(Table27[[#This Row],[BRIEF DESCRIPTION OF NC if VOID: "VOID, Location, details (initials, date)"]]))), 1)) <= 57)), 1) - 1), FIND(":", Table27[[#This Row],[BRIEF DESCRIPTION OF NC if VOID: "VOID, Location, details (initials, date)"]]) + 2, LEN(Table27[[#This Row],[BRIEF DESCRIPTION OF NC if VOID: "VOID, Location, details (initials, date)"]]))} -> CE | G18: =MID(LEFT(Table27[[#This Row],[BRIEF DESCRIPTION OF NC if VOID: "VOID, Location, details (initials, date)"]], FIND(",", Table27[[#This Row],[BRIEF DESCRIPTION OF NC if VOID: "VOID, Location, details (initials, date)"]]) - 1), FIND("{token}", SUBSTITUTE(Table27[[#This Row],[BRIEF DESCRIPTION OF NC if VOID: "VOID, Location, details (initials, date)"]], " ", "{token}", 2)) + 1, LEN(Table27[[#This Row],[BRIEF DESCRIPTION OF NC if VOID: "VOID, Location, details (initials, date)"]])) -> D3606 - Benzene | H18: -3.01 | I18: 45301 | J18: LJ | K18: 45595 | M18: 17 | N18: =IF(ISBLANK(K18), TODAY()-(I18), "CLOSED") -> CLOSED
A19: Collins (Purvis), MS | B19: =VLOOKUP(Table27[[#This Row],[Location (drop-down)]],'List source'!D$2:E$60,2,FALSE) -> 115 | C19: 018 | D19: ="PTO" & C19 & "-" & B19 & "-" & "24" -> PTO018-115-24 | E19: PT: CE512; D86 - Distillation, Auto, 30%, 40%, 50%, & E200 | F19: {=MID(LEFT(Table27[[#This Row],[BRIEF DESCRIPTION OF NC if VOID: "VOID, Location, details (initials, date)"]], INDEX(_xlfn._xlws.FILTER(ROW(INDIRECT("1:" & LEN(Table27[[#This Row],[BRIEF DESCRIPTION OF NC if VOID: "VOID, Location, details (initials, date)"]]))), (48 <= CODE(MID(Table27[[#This Row],[BRIEF DESCRIPTION OF NC if VOID: "VOID, Location, details (initials, date)"]], ROW(INDIRECT("1:" & LEN(Table27[[#This Row],[BRIEF DESCRIPTION OF NC if VOID: "VOID, Location, details (initials, date)"]]))), 1))) * (CODE(MID(Table27[[#This Row],[BRIEF DESCRIPTION OF NC if VOID: "VOID, Location, details (initials, date)"]], ROW(INDIRECT("1:" & LEN(Table27[[#This Row],[BRIEF DESCRIPTION OF NC if VOID: "VOID, Location, details (initials, date)"]]))), 1)) <= 57)), 1) - 1), FIND(":", Table27[[#This Row],[BRIEF DESCRIPTION OF NC if VOID: "VOID, Location, details (initials, date)"]]) + 2, LEN(Table27[[#This Row],[BRIEF DESCRIPTION OF NC if VOID: "VOID, Location, details (initials, date)"]]))} -> CE | G19: =MID(LEFT(Table27[[#This Row],[BRIEF DESCRIPTION OF NC if VOID: "VOID, Location, details (initials, date)"]], FIND(",", Table27[[#This Row],[BRIEF DESCRIPTION OF NC if VOID: "VOID, Location, details (initials, date)"]]) - 1), FIND("{token}", SUBSTITUTE(Table27[[#This Row],[BRIEF DESCRIPTION OF NC if VOID: "VOID, Location, details (initials, date)"]], " ", "{token}", 2)) + 1, LEN(Table27[[#This Row],[BRIEF DESCRIPTION OF NC if VOID: "VOID, Location, details (initials, date)"]])) -> D86 - Distillation | H19: 2.28, 2.38, 2.01, & -2.52 | I19: 45302 | J19: JN | K19: 45302 | L19: Meets both the precision performance and reproducibility criteria. | M19: 18 | N19: =IF(ISBLANK(K19), TODAY()-(I19), "CLOSED") -> CLOSED
A20: Collins (Purvis), MS | B20: =VLOOKUP(Table27[[#This Row],[Location (drop-down)]],'List source'!D$2:E$60,2,FALSE) -> 115 | C20: 019 | D20: ="PTO" & C20 & "-" & B20 & "-" & "24" -> PTO019-115-24 | E20: PT: CE512; D2699 - Research Octane Number, Z-Score = 2.45 | F20: {=MID(LEFT(Table27[[#This Row],[BRIEF DESCRIPTION OF NC if VOID: "VOID, Location, details (initials, date)"]], INDEX(_xlfn._xlws.FILTER(ROW(INDIRECT("1:" & LEN(Table27[[#This Row],[BRIEF DESCRIPTION OF NC if VOID: "VOID, Location, details (initials, date)"]]))), (48 <= CODE(MID(Table27[[#This Row],[BRIEF DESCRIPTION OF NC if VOID: "VOID, Location, details (initials, date)"]], ROW(INDIRECT("1:" & LEN(Table27[[#This Row],[BRIEF DESCRIPTION OF NC if VOID: "VOID, Location, details (initials, date)"]]))), 1))) * (CODE(MID(Table27[[#This Row],[BRIEF DESCRIPTION OF NC if VOID: "VOID, Location, details (initials, date)"]], ROW(INDIRECT("1:" & LEN(Table27[[#This Row],[BRIEF DESCRIPTION OF NC if VOID: "VOID, Location, details (initials, date)"]]))), 1)) <= 57)), 1) - 1), FIND(":", Table27[[#This Row],[BRIEF DESCRIPTION OF NC if VOID: "VOID, Location, details (initials, date)"]]) + 2, LEN(Table27[[#This Row],[BRIEF DESCRIPTION OF NC if VOID: "VOID, Location, details (initials, date)"]]))} -> CE | G20: =MID(LEFT(Table27[[#This Row],[BRIEF DESCRIPTION OF NC if VOID: "VOID, Location, details (initials, date)"]], FIND(",", Table27[[#This Row],[BRIEF DESCRIPTION OF NC if VOID: "VOID, Location, details (initials, date)"]]) - 1), FIND("{token}", SUBSTITUTE(Table27[[#This Row],[BRIEF DESCRIPTION OF NC if VOID: "VOID, Location, details (initials, date)"]], " ", "{token}", 2)) + 1, LEN(Table27[[#This Row],[BRIEF DESCRIPTION OF NC if VOID: "VOID, Location, details (initials, date)"]])) -> D2699 - Research Octane Number | H20: 2.45 | I20: 45302 | J20: JN | K20: 45303 | L20: Confirmed Transcription Error. | M20: 19 | N20: =IF(ISBLANK(K20), TODAY()-(I20), "CLOSED") -> CLOSED
A21: Chicago, IL | B21: =VLOOKUP(Table27[[#This Row],[Location (drop-down)]],'List source'!D$2:E$60,2,FALSE) -> 136 | C21: 020 | D21: ="PTO" & C21 & "-" & B21 & "-" & "24" -> PTO020-136-24 | E21: PT: CE512; D86 - Distillation, Auto, 80% , Z-Score = -6.32 | F21: {=MID(LEFT(Table27[[#This Row],[BRIEF DESCRIPTION OF NC if VOID: "VOID, Location, details (initials, date)"]], INDEX(_xlfn._xlws.FILTER(ROW(INDIRECT("1:" & LEN(Table27[[#This Row],[BRIEF DESCRIPTION OF NC if VOID: "VOID, Location, details (initials, date)"]]))), (48 <= CODE(MID(Table27[[#This Row],[BRIEF DESCRIPTION OF NC if VOID: "VOID, Location, details (initials, date)"]], ROW(INDIRECT("1:" & LEN(Table27[[#This Row],[BRIEF DESCRIPTION OF NC if VOID: "VOID, Location, details (initials, date)"]]))), 1))) * (CODE(MID(Table27[[#This Row],[BRIEF DESCRIPTION OF NC if VOID: "VOID, Location, details (initials, date)"]], ROW(INDIRECT("1:" & LEN(Table27[[#This Row],[BRIEF DESCRIPTION OF NC if VOID: "VOID, Location, details (initials, date)"]]))), 1)) <= 57)), 1) - 1), FIND(":", Table27[[#This Row],[BRIEF DESCRIPTION OF NC if VOID: "VOID, Location, details (initials, date)"]]) + 2, LEN(Table27[[#This Row],[BRIEF DESCRIPTION OF NC if VOID: "VOID, Location, details (initials, date)"]]))} -> CE | G21: =MID(LEFT(Table27[[#This Row],[BRIEF DESCRIPTION OF NC if VOID: "VOID, Location, details (initials, date)"]], FIND(",", Table27[[#This Row],[BRIEF DESCRIPTION OF NC if VOID: "VOID, Location, details (initials, date)"]]) - 1), FIND("{token}", SUBSTITUTE(Table27[[#This Row],[BRIEF DESCRIPTION OF NC if VOID: "VOID, Location, details (initials, date)"]], " ", "{token}", 2)) + 1, LEN(Table27[[#This Row],[BRIEF DESCRIPTION OF NC if VOID: "VOID, Location, details (initials, date)"]])) -> D86 - Distillation | H21: -6.32 | I21: 45302 | J21: LJ | K21: 45371 | M21: 20 | N21: =IF(ISBLANK(K21), TODAY()-(I21), "CLOSED") -> CLOSED
A22: Mobile, AL | B22: =VLOOKUP(Table27[[#This Row],[Location (drop-down)]],'List source'!D$2:E$60,2,FALSE) -> 146 | C22: 021 | D22: ="PTO" & C22 & "-" & B22 & "-" & "24" -> PTO021-146-24 | E22: PT: CE512; D4052 - API, | F22: {=MID(LEFT(Table27[[#This Row],[BRIEF DESCRIPTION OF NC if VOID: "VOID, Location, details (initials, date)"]], INDEX(_xlfn._xlws.FILTER(ROW(INDIRECT("1:" & LEN(Table27[[#This Row],[BRIEF DESCRIPTION OF NC if VOID: "VOID, Location, details (initials, date)"]]))), (48 <= CODE(MID(Table27[[#This Row],[BRIEF DESCRIPTION OF NC if VOID: "VOID, Location, details (initials, date)"]], ROW(INDIRECT("1:" & LEN(Table27[[#This Row],[BRIEF DESCRIPTION OF NC if VOID: "VOID, Location, details (initials, date)"]]))), 1))) * (CODE(MID(Table27[[#This Row],[BRIEF DESCRIPTION OF NC if VOID: "VOID, Location, details (initials, date)"]], ROW(INDIRECT("1:" & LEN(Table27[[#This Row],[BRIEF DESCRIPTION OF NC if VOID: "VOID, Location, details (initials, date)"]]))), 1)) <= 57)), 1) - 1), FIND(":", Table27[[#This Row],[BRIEF DESCRIPTION OF NC if VOID: "VOID, Location, details (initials, date)"]]) + 2, LEN(Table27[[#This Row],[BRIEF DESCRIPTION OF NC if VOID: "VOID, Location, details (initials, date)"]]))} -> CE | G22: =MID(LEFT(Table27[[#This Row],[BRIEF DESCRIPTION OF NC if VOID: "VOID, Location, details (initials, date)"]], FIND(",", Table27[[#This Row],[BRIEF DESCRIPTION OF NC if VOID: "VOID, Location, details (initials, date)"]]) - 1), FIND("{token}", SUBSTITUTE(Table27[[#This Row],[BRIEF DESCRIPTION OF NC if VOID: "VOID, Location, details (initials, date)"]], " ", "{token}", 2)) + 1, LEN(Table27[[#This Row],[BRIEF DESCRIPTION OF NC if VOID: "VOID, Location, details (initials, date)"]])) -> D4052 - API | H22: 2.16 | I22: 45302 | J22: JN | K22: 45302 | L22: Meets both the precision performance and reproducibility criteria. | M22: 21 | N22: =IF(ISBLANK(K22), TODAY()-(I22), "CLOSED") -> CLOSED
A23: New Orleans (Destrehan), LA | B23: =VLOOKUP(Table27[[#This Row],[Location (drop-down)]],'List source'!D$2:E$60,2,FALSE) -> 170 | C23: 022 | D23: ="PTO" & C23 & "-" & B23 & "-" & "24" -> PTO022-170-24 | E23: PT: CE512; D86 - Distillation, Auto, 95%, Recovery, & Residue | F23: {=MID(LEFT(Table27[[#This Row],[BRIEF DESCRIPTION OF NC if VOID: "VOID, Location, details (initials, date)"]], INDEX(_xlfn._xlws.FILTER(ROW(INDIRECT("1:" & LEN(Table27[[#This Row],[BRIEF DESCRIPTION OF NC if VOID: "VOID, Location, details (initials, date)"]]))), (48 <= CODE(MID(Table27[[#This Row],[BRIEF DESCRIPTION OF NC if VOID: "VOID, Location, details (initials, date)"]], ROW(INDIRECT("1:" & LEN(Table27[[#This Row],[BRIEF DESCRIPTION OF NC if VOID: "VOID, Location, details (initials, date)"]]))), 1))) * (CODE(MID(Table27[[#This Row],[BRIEF DESCRIPTION OF NC if VOID: "VOID, Location, details (initials, date)"]], ROW(INDIRECT("1:" & LEN(Table27[[#This Row],[BRIEF DESCRIPTION OF NC if VOID: "VOID, Location, details (initials, date)"]]))), 1)) <= 57)), 1) - 1), FIND(":", Table27[[#This Row],[BRIEF DESCRIPTION OF NC if VOID: "VOID, Location, details (initials, date)"]]) + 2, LEN(Table27[[#This Row],[BRIEF DESCRIPTION OF NC if VOID: "VOID, Location, details (initials, date)"]]))} -> CE | G23: =MID(LEFT(Table27[[#This Row],[BRIEF DESCRIPTION OF NC if VOID: "VOID, Location, details (initials, date)"]], FIND(",", Table27[[#This Row],[BRIEF DESCRIPTION OF NC if VOID: "VOID, Location, details (initials, date)"]]) - 1), FIND("{token}", SUBSTITUTE(Table27[[#This Row],[BRIEF DESCRIPTION OF NC if VOID: "VOID, Location, details (initials, date)"]], " ", "{token}", 2)) + 1, LEN(Table27[[#This Row],[BRIEF DESCRIPTION OF NC if VOID: "VOID, Location, details (initials, date)"]])) -> D86 - Distillation | H23: -2.01, 2.13, & -2.31 | I23: 45302 | J23: JN | K23: 45302 | L23: Meets both the precision performance and reproducibility criteria. | M23: 22 | N23: =IF(ISBLANK(K23), TODAY()-(I23), "CLOSED") -> CLOSED
A24: New Orleans (Destrehan), LA | B24: =VLOOKUP(Table27[[#This Row],[Location (drop-down)]],'List source'!D$2:E$60,2,FALSE) -> 170 | C24: 023 | D24: ="PTO" & C24 & "-" & B24 & "-" & "24" -> PTO023-170-24 | E24: PT: CE512; D5580 - C9+ Aromatics, | F24: {=MID(LEFT(Table27[[#This Row],[BRIEF DESCRIPTION OF NC if VOID: "VOID, Location, details (initials, date)"]], INDEX(_xlfn._xlws.FILTER(ROW(INDIRECT("1:" & LEN(Table27[[#This Row],[BRIEF DESCRIPTION OF NC if VOID: "VOID, Location, details (initials, date)"]]))), (48 <= CODE(MID(Table27[[#This Row],[BRIEF DESCRIPTION OF NC if VOID: "VOID, Location, details (initials, date)"]], ROW(INDIRECT("1:" & LEN(Table27[[#This Row],[BRIEF DESCRIPTION OF NC if VOID: "VOID, Location, details (initials, date)"]]))), 1))) * (CODE(MID(Table27[[#This Row],[BRIEF DESCRIPTION OF NC if VOID: "VOID, Location, details (initials, date)"]], ROW(INDIRECT("1:" & LEN(Table27[[#This Row],[BRIEF DESCRIPTION OF NC if VOID: "VOID, Location, details (initials, date)"]]))), 1)) <= 57)), 1) - 1), FIND(":", Table27[[#This Row],[BRIEF DESCRIPTION OF NC if VOID: "VOID, Location, details (initials, date)"]]) + 2, LEN(Table27[[#This Row],[BRIEF DESCRIPTION OF NC if VOID: "VOID, Location, details (initials, date)"]]))} -> CE | G24: =MID(LEFT(Table27[[#This Row],[BRIEF DESCRIPTION OF NC if VOID: "VOID, Location, details (initials, date)"]], FIND(",", Table27[[#This Row],[BRIEF DESCRIPTION OF NC if VOID: "VOID, Location, details (initials, date)"]]) - 1), FIND("{token}", SUBSTITUTE(Table27[[#This Row],[BRIEF DESCRIPTION OF NC if VOID: "VOID, Location, details (initials, date)"]], " ", "{token}", 2)) + 1, LEN(Table27[[#This Row],[BRIEF DESCRIPTION OF NC if VOID: "VOID, Location, details (initials, date)"]])) -> D5580 - C9+ Aromatics | H24: 2.27 | I24: 45302 | J24: JN | K24: 45302 | L24: Meets both the precision performance and reproducibility criteria. | M24: 23 | N24: =IF(ISBLANK(K24), TODAY()-(I24), "CLOSED") -> CLOSED
