Workbook

Sheet Assessment '25
A1: Cushing, OK | B1: Location ID | C1: # | D1: Assessment # | E1: Start Date | F1: End Date | G1: Report Issued | H1: Type of Assessment (drop-down) | I1: Scope of Assessment (drop-down) | J1: QA In Charge (Get a copy of assessment report or summary) | K1: Assessor(s) / Auditor(s) name(s) | L1: Assessor's company | M1: Agency Type (Regulatory / certification / accreditation agency) (drop-down) | N1: Brief description of assessment scope
A2: San Francisco (Concord), CA | B2: =VLOOKUP(Table245[[#This Row],[Cushing, OK]],'List source'!D$2:E$71,2,FALSE) -> 131 | C2: 001 | D2: ="A" & C2 & "-" & B2 & "-" & "25" -> A001-131-25 | E2: 45297 | F2: 45300 | G2: 45689 | H2: Internal | I2: Inspection & Laboratory | J2: ECu | K2: ECu / KA | L2: AmSpec | N2: Annual internal quality systems assessment (ISO 9001) | O2: Annual internal quality systems assessment (ISO 9001)
A3: San Francisco (Concord), CA | B3: =VLOOKUP(Table245[[#This Row],[Cushing, OK]],'List source'!D$2:E$71,2,FALSE) -> 131 | C3: 002 | D3: ="A" & C3 & "-" & B3 & "-" & "25" -> A002-131-25 | E3: 45297 | F3: 45300 | G3: 45689 | H3: Internal | I3: Inspection & Laboratory | J3: ECu | K3: ECu / KA | L3: AmSpec | N3: Annual internal quality systems assessment (ISO 17025) | O3: Annual internal quality systems assessment (ISO 17025)
A4: Brownsville, TX | B4: =VLOOKUP(Table245[[#This Row],[Cushing, OK]],'List source'!D$2:E$71,2,FALSE) -> 158 | C4: 003 | D4: ="A" & C4 & "-" & B4 & "-" & "25" -> A003-158-25 | E4: 45663 | F4: 45666 | G4: 45684 | H4: Internal | I4: Inspection & Laboratory | J4: AH | K4: AH / HB | L4: AmSpec | N4: Annual internal quality systems assessment (ISO 9001) | O4: Annual internal quality systems assessment (BQ-9000)
A5: Brownsville, TX | B5: =VLOOKUP(Table245[[#This Row],[Cushing, OK]],'List source'!D$2:E$71,2,FALSE) -> 158 | C5: 004 | D5: ="A" & C5 & "-" & B5 & "-" & "25" -> A004-158-25 | E5: 45663 | F5: 45666 | G5: 45684 | H5: Internal | I5: Laboratory | J5: AH | K5: AH / HB | L5: AmSpec | N5: Annual internal quality systems assessment (ISO 17025) | O5: A2LA renewal assessment (ISO 17025)
A6: Mont Belvieu, TX | B6: =VLOOKUP(Table245[[#This Row],[Cushing, OK]],'List source'!D$2:E$71,2,FALSE) -> 120a | C6: 005 | D6: ="A" & C6 & "-" & B6 & "-" & "25" -> A005-120a-25 | E6: 45674 | F6: 45674 | G6: 45681 | H6: Internal | I6: Inspection & Laboratory | J6: MT | K6: MT | L6: AmSpec | N6: Annual internal quality systems assessment (ISO 9001) | O6: BQ9000 Renewal Accreditation
A7: St Croix, USVI | B7: =VLOOKUP(Table245[[#This Row],[Cushing, OK]],'List source'!D$2:E$71,2,FALSE) -> 210 | C7: 006 | D7: ="A" & C7 & "-" & B7 & "-" & "25" -> A006-210-25 | E7: 45677 | F7: 45678 | G7: 45680 | H7: Certifications | I7: Laboratory | J7: MT | K7: M. Cahill | L7: A2LA | N7: A2LA Initial Assessment | O7: USCBP Triennial audit
A8: Yorktown (Norfolk), VA | B8: =VLOOKUP(Table245[[#This Row],[Cushing, OK]],'List source'!D$2:E$71,2,FALSE) -> 185 | C8: 007 | D8: ="A" & C8 & "-" & B8 & "-" & "25" -> A007-185-25 | E8: 45677 | F8: 45680 | G8: 45706 | H8: Internal | I8: Inspection & Laboratory | J8: AH | K8: AH | L8: AmSpec | N8: Annual internal quality systems assessment (ISO 9001)
A9: Corpus Christi, TX | B9: =VLOOKUP(Table245[[#This Row],[Cushing, OK]],'List source'!D$2:E$71,2,FALSE) -> 155 | C9: 008 | D9: ="A" & C9 & "-" & B9 & "-" & "25" -> A008-155-25 | E9: 45678 | F9: 45680 | G9: 45706 | H9: Internal | I9: Inspection & Laboratory | J9: KA | K9: KA / ECu | L9: AmSpec | N9: Annual internal quality systems assessment (ISO 9001)
A10: Corpus Christi, TX | B10: =VLOOKUP(Table245[[#This Row],[Cushing, OK]],'List source'!D$2:E$71,2,FALSE) -> 155 | C10: 009 | D10: ="A" & C10 & "-" & B10 & "-" & "25" -> A009-155-25 | E10: 45678 | F10: 45680 | G10: 45706 | H10: Internal | I10: Laboratory | J10: KA | K10: KA / ECu | L10: AmSpec | N10: Annual internal quality systems assessment (ISO 17025)
A11: St Louis, MO | B11: =VLOOKUP(Table245[[#This Row],[Cushing, OK]],'List source'!D$2:E$71,2,FALSE) -> 139 | C11: 010 | D11: ="A" & C11 & "-" & B11 & "-" & "25" -> A010-139-25 | E11: 45684 | F11: 45686 | G11: 45701 | H11: Internal | I11: Inspection & Laboratory | J11: ECu | K11: ECu | L11: AmSpec | N11: Annual internal quality systems assessment (ISO 9001)
A12: HOFTI / Channelview, TX | B12: =VLOOKUP(Table245[[#This Row],[Cushing, OK]],'List source'!D$2:E$71,2,FALSE) -> 128 | C12: 011 | D12: ="A" & C12 & "-" & B12 & "-" & "25" -> A011-128-25 | E12: 45693 | F12: 45694 | G12: 45709 | H12: Internal | I12: Inspection & Laboratory | J12: AH | K12: AH / ECu | L12: AmSpec | N12: Annual internal quality systems assessment (ISO 9001)
A13: Mobile, AL | B13: =VLOOKUP(Table245[[#This Row],[Cushing, OK]],'List source'!D$2:E$71,2,FALSE) -> 146 | C13: 012 | D13: ="A" & C13 & "-" & B13 & "-" & "25" -> A012-146-25 | E13: 45692 | F13: 45694 | G13: 45694 | H13: Certifications | I13: Laboratory | J13: KA | K13: L. DeWitt | L13: A2LA | N13: A2LA renewal assessment
A14: Pittsburgh, PA | B14: =VLOOKUP(Table245[[#This Row],[Cushing, OK]],'List source'!D$2:E$71,2,FALSE) -> 178 | C14: 013 | D14: ="A" & C14 & "-" & B14 & "-" & "25" -> A013-178-25 | E14: 45692 | F14: 45693 | G14: 45695 | H14: Internal | I14: Inspection & Laboratory | J14: MT | K14: MT | L14: AmSpec | N14: Annual internal quality systems assessment (ISO 9001)
A15: Albany, NY | B15: =VLOOKUP(Table245[[#This Row],[Cushing, OK]],'List source'!D$2:E$71,2,FALSE) -> 111 | C15: 014 | D15: ="A" & C15 & "-" & B15 & "-" & "25" -> A014-111-25 | E15: 45701 | F15: 45701 | G15: 45705 | H15: Internal | I15: Inspection | J15: KA | K15: KA | L15: AmSpec | N15: Annual internal quality systems assessment (ISO 9001)
A16: Cincinnati (Erlanger), OH | B16: =VLOOKUP(Table245[[#This Row],[Cushing, OK]],'List source'!D$2:E$71,2,FALSE) -> 138 | C16: 015 | D16: ="A" & C16 & "-" & B16 & "-" & "25" -> A015-138-25 | E16: 45706 | F16: 45708 | G16: 45716 | H16: Internal | I16: Inspection & Laboratory | J16: MT | K16: MT | L16: AmSpec | N16: Annual internal quality systems assessment (ISO 9001)
A17: Boston (Everett), MA | B17: =VLOOKUP(Table245[[#This Row],[Cushing, OK]],'List source'!D$2:E$71,2,FALSE) -> 141 | C17: 016 | D17: ="A" & C17 & "-" & B17 & "-" & "25" -> A016-141-25 | E17: 45712 | F17: 45714 | G17: 45716 | H17: Internal | I17: Inspection & Laboratory | J17: KA | K17: KA | L17: AmSpec | N17: Annual internal quality systems assessment (ISO 9001)
A18: Cape Canaveral, FL | B18: =VLOOKUP(Table245[[#This Row],[Cushing, OK]],'List source'!D$2:E$71,2,FALSE) -> 127 | C18: 017 | D18: ="A" & C18 & "-" & B18 & "-" & "25" -> A017-127-25 | E18: 45713 | F18: 45716 | G18: 45743 | H18: Internal | I18: Inspection & Laboratory | J18: AH | K18: AH | L18: AmSpec | N18: Annual internal quality systems assessment (ISO 9001)
A19: Portland, ME | B19: =VLOOKUP(Table245[[#This Row],[Cushing, OK]],'List source'!D$2:E$71,2,FALSE) -> 142 | C19: 018 | D19: ="A" & C19 & "-" & B19 & "-" & "25" -> A018-142-25 | E19: 45712 | F19: 45714 | G19: 45720 | H19: Internal | I19: Inspection & Laboratory | J19: ECu | K19: ECu | L19: AmSpec | N19: Annual internal quality systems assessment (ISO 9001)
... A25: Baton Rouge (Gonzales), LA | B25: =VLOOKUP(Table245[[#This Row],[Cushing, OK]],'List source'!D$2:E$71,2,FALSE) -> 190 | C25: 024 | D25: ="A" & C25 & "-" & B25 & "-" & "25" -> A024-190-25 | E25: 45721 | F25: 45723 | G25: 45727 | H25: Internal | I25: Laboratory | J25: MT | K25: MT | L25: AmSpec | N25: Annual internal quality systems assessment (ISO 17025)
A26: Houston (HTC), TX | B26: =VLOOKUP(Table245[[#This Row],[Cushing, OK]],'List source'!D$2:E$71,2,FALSE) -> 120 | C26: 025 | D26: ="A" & C26 & "-" & B26 & "-" & "25" -> A025-120-25 | E26: 45721 | F26: 45721 | G26: 45721 | H26: Certifications | I26: Laboratory | J26: AH | K26: Robert Japikse | L26: Clean Fuels | M26: Certifications | N26: 12 month BQ9000 surveillance (C116 + C117-120-25)
A27: Halifax (Dartmouth), NS | B27: =VLOOKUP(Table245[[#This Row],[Cushing, OK]],'List source'!D$2:E$71,2,FALSE) -> 198 | C27: 026 | D27: ="A" & C27 & "-" & B27 & "-" & "25" -> A026-198-25 | E27: 45708 | F27: 45709 | G27: 45721 | H27: Customer | I27: Laboratory | J27: GF | K27: Kerry Costain | L27: Irving Oil | N27: Annual laboratory audit
A28: Bahamas (Freeport), GBI | B28: =VLOOKUP(Table245[[#This Row],[Cushing, OK]],'List source'!D$2:E$71,2,FALSE) -> 215 | C28: 027 | D28: ="A" & C28 & "-" & B28 & "-" & "25" -> A027-215-25 | E28: 45726 | F28: 45730 | G28: 45743 | H28: Internal | I28: Inspection & Laboratory | J28: KA | K28: KA | L28: AmSpec | N28: Annual internal quality systems assessment (ISO 9001)
A29: New Orleans (Destrehan), LA | B29: =VLOOKUP(Table245[[#This Row],[Cushing, OK]],'List source'!D$2:E$71,2,FALSE) -> 170 | C29: 028 | D29: ="A" & C29 & "-" & B29 & "-" & "25" -> A028-170-25 | E29: 45706 | F29: 45706 | H29: Customer | I29: Inspection & Laboratory | J29: DA | K29: Yossias Yohannes | L29: Chevron | N29: Lab/Ops/Safety Audit
A30: Baton Rouge (Gonzales), LA | B30: =VLOOKUP(Table245[[#This Row],[Cushing, OK]],'List source'!D$2:E$71,2,FALSE) -> 190 | C30: 029 | D30: ="A" & C30 & "-" & B30 & "-" & "25" -> A029-190-25 | E30: 45707 | F30: 45707 | H30: Customer | I30: Inspection & Laboratory | J30: DA | K30: Yossias Yohannes | L30: Chevron | N30: Lab/Ops/Safety Audit
A31: New Orleans (Destrehan), LA | B31: =VLOOKUP(Table245[[#This Row],[Cushing, OK]],'List source'!D$2:E$71,2,FALSE) -> 170 | C31: 030 | D31: ="A" & C31 & "-" & B31 & "-" & "25" -> A030-170-25 | E31: 45728 | F31: 45728 | H31: Certifications | I31: Laboratory | J31: DA | K31: Monty Fox | L31: Clean Fuels | M31: Certifications | N31: 12 month BQ9000 surveillance audit
A32: Ft Lauderdale (Davie), FL | B32: =VLOOKUP(Table245[[#This Row],[Cushing, OK]],'List source'!D$2:E$71,2,FALSE) -> 125 | C32: 031 | D32: ="A" & C32 & "-" & B32 & "-" & "25" -> A031-125-25 | E32: 45735 | F32: 45737 | G32: 45740 | H32: Internal | I32: Inspection & Laboratory | J32: MT | K32: MT | L32: AmSpec | N32: Annual internal quality systems assessment (ISO 9001)
A33: New Orleans (Destrehan), LA | B33: =VLOOKUP(Table245[[#This Row],[Cushing, OK]],'List source'!D$2:E$71,2,FALSE) -> 170 | C33: 032 | D33: ="A" & C33 & "-" & B33 & "-" & "25" -> A032-170-25 | E33: 45733 | F33: 45736 | G33: 45782 | H33: Internal | I33: Inspection & Laboratory | J33: AH | K33: AH / ECu | L33: AmSpec | N33: Annual internal quality systems assessment (ISO 9001)
A34: New Orleans (Destrehan), LA | B34: =VLOOKUP(Table245[[#This Row],[Cushing, OK]],'List source'!D$2:E$71,2,FALSE) -> 170 | C34: 033 | D34: ="A" & C34 & "-" & B34 & "-" & "25" -> A033-170-25 | E34: 45733 | F34: 45736 | G34: 45782 | H34: Internal | I34: Laboratory | J34: AH | K34: AH / ECu | L34: AmSpec | N34: Annual internal quality systems assessment (ISO 17025)
A35: New Orleans (Destrehan), LA | B35: =VLOOKUP(Table245[[#This Row],[Cushing, OK]],'List source'!D$2:E$71,2,FALSE) -> 170 | C35: 034 | D35: ="A" & C35 & "-" & B35 & "-" & "25" -> A034-170-25 | E35: 45733 | F35: 45736 | G35: 45782 | H35: Internal | I35: Laboratory | J35: AH | K35: AH / ECu | L35: AmSpec | N35: Annual internal quality systems assessment (BQ 9000)
A36: Puerto Rico | B36: =VLOOKUP(Table245[[#This Row],[Cushing, OK]],'List source'!D$2:E$71,2,FALSE) -> 192 | C36: 035 | D36: ="A" & C36 & "-" & B36 & "-" & "25" -> A035-192-25 | E36: 45747 | F36: 45749 | G36: 45754 | H36: Internal | I36: Inspection & Laboratory | J36: AH | K36: MT / AH | L36: AmSpec | N36: Annual internal quality systems assessment (ISO 9001)
A37: Halifax (Dartmouth), NS | B37: =VLOOKUP(Table245[[#This Row],[Cushing, OK]],'List source'!D$2:E$71,2,FALSE) -> 198 | C37: 036 | D37: ="A" & C37 & "-" & B37 & "-" & "25" -> A036-198-25 | E37: 45726 | F37: 45726 | H37: Regulatory | I37: Laboratory | J37: GF | K37: Andrea McMullin | L37: Contractor for Irving Oil | M37: Regulatory | N37: Annual compliance for gasoline audit
A38: New Haven, CT | B38: =VLOOKUP(Table245[[#This Row],[Cushing, OK]],'List source'!D$2:E$71,2,FALSE) -> 145 | C38: 037 | D38: ="A" & C38 & "-" & B38 & "-" & "25" -> A037-145-25 | E38: 45747 | F38: 45749 | G38: 45756 | H38: Internal | I38: Inspection & Laboratory | J38: KA | K38: KA | L38: AmSpec | N38: Annual internal quality systems assessment (ISO 9001)
A39: Levis (Quebec City), Quebec | B39: =VLOOKUP(Table245[[#This Row],[Cushing, OK]],'List source'!D$2:E$71,2,FALSE) -> 194 | C39: 038 | D39: ="A" & C39 & "-" & B39 & "-" & "25" -> A038-194-25 | E39: 45754 | F39: 45757 | G39: 45767 | H39: Internal | I39: Inspection & Laboratory | J39: ECu | K39: Ecu | L39: AmSpec | N39: Annual internal quality systems assessment (ISO 9001)
A40: Levis (Quebec City), Quebec | B40: =VLOOKUP(Table245[[#This Row],[Cushing, OK]],'List source'!D$2:E$71,2,FALSE) -> 194 | C40: 039 | D40: ="A" & C40 & "-" & B40 & "-" & "25" -> A039-194-25 | E40: 45754 | F40: 45757 | G40: 45767 | H40: Internal | I40: Laboratory | J40: ECu | K40: Ecu | L40: AmSpec | N40: Annual internal quality systems assessment (ISO 17025)
A41: AGRI (HTC) | B41: =VLOOKUP(Table245[[#This Row],[Cushing, OK]],'List source'!D$2:E$71,2,FALSE) -> 119 | C41: 040 | D41: ="A" & C41 & "-" & B41 & "-" & "25" -> A040-119-25 | E41: 45761 | F41: 45763 | G41: 45783 | H41: Internal | I41: Inspection & Laboratory | J41: AH | K41: AH | L41: AmSpec | N41: Annual internal quality systems assessment (ISO 9001)
A42: Lake Charles (Sulfur), LA | B42: =VLOOKUP(Table245[[#This Row],[Cushing, OK]],'List source'!D$2:E$71,2,FALSE) -> 165 | C42: 041 | D42: ="A" & C42 & "-" & B42 & "-" & "25" -> A041-165-25 | E42: 45782 | F42: 45785 | G42: 45799 | H42: Internal | I42: Laboratory | J42: KA | K42: KA / ECu | L42: AmSpec | N42: Annual internal quality systems assessment (ISO 17025)
A43: Lake Charles (Sulfur), LA | B43: =VLOOKUP(Table245[[#This Row],[Cushing, OK]],'List source'!D$2:E$71,2,FALSE) -> 165 | C43: 042 | D43: ="A" & C43 & "-" & B43 & "-" & "25" -> A042-165-25 | E43: 45782 | F43: 45785 | G43: 45799 | H43: Internal | I43: Inspection & Laboratory | J43: KA | K43: KA / ECu | L43: AmSpec | N43: Annual internal quality systems assessment (ISO 9001)
A44: Lake Charles (Sulfur), LA | B44: =VLOOKUP(Table245[[#This Row],[Cushing, OK]],'List source'!D$2:E$71,2,FALSE) -> 165 | C44: 043 | D44: ="A" & C44 & "-" & B44 & "-" & "25" -> A043-165-25 | E44: 46010 | F44: 46010 | G44: 46010 | H44: Certifications | I44: Inspection & Laboratory | J44: KA | K44: Yatish Patel | L44: DNV | N44: ISO 9001 2025 certification audit
A45: Halifax (Dartmouth), NS | B45: =VLOOKUP(Table245[[#This Row],[Cushing, OK]],'List source'!D$2:E$71,2,FALSE) -> 198 | C45: 044 | D45: ="A" & C45 & "-" & B45 & "-" & "25" -> A044-198-25 | E45: 45847 | F45: 45847 | G45: 46010 | H45: Certifications | I45: Inspection & Laboratory | J45: KA | K45: Yatish Patel | L45: DNV | N45: ISO 9001 2025 certification audit
...

Sheet CAR '25
A1: Location (drop-down) | B1: Location ID | C1: # | D1: CAR # | E1: CAR Type | F1: ASSOCIATED ORGANIZATION (required for Complaints, Customer audits/alerts, 3rd party audits) | G1: BRIEF DESCRIPTION OF NC if VOID: "VOID, Location, type, details (initials, date)" | H1: Area (Lab, Ops, Misc.) (drop-down) | I1: QA team member initials | J1: CAR initialized date | K1: Action Plan submitted by due date? (Yes/No) | L1: Corrective Action Completion Date | M1: Complete corrective actions (Approved Date) | N1: Agreed Actions completed by due date? (Yes/No) | O1: Effectiveness Review (Closed Date) | P1: Effective? (Yes/No) | Q1: Notes | R1: Cause (for Assessments only) | S1: Days open if not closed
A2: Port Arthur (Beaumont), TX | B2: =VLOOKUP(Table2[[#This Row],[Location (drop-down)]],'List source'!D$2:E$71,2,FALSE) -> 160 | C2: 164 | D2: ="C" & C2 &"-" & B2 & "-" & "25" -> C164-160-25 | E2: Complaint | F2: ATA | G2: Transcription error on D1160 | H2: Lab | I2: MT | J2: 45744 | M2: 45782 | S2: =IF(ISBLANK(Table2[[#This Row],[Complete corrective actions (Approved Date)]]), TODAY()-Table2[[#This Row],[CAR initialized date]], "CLOSED") -> CLOSED
A3: Bellingham (Ferndale), WA | B3: =VLOOKUP(Table2[[#This Row],[Location (drop-down)]],'List source'!D$2:E$71,2,FALSE) -> 132 | C3: 001 | D3: ="C" & C3 &"-" & B3 & "-" & "25" -> C001-132-25 | E3: Complaint | F3: PBF | G3: The client was not informed of the vessel's short loading due to draft restrictions | H3: Operations | I3: HM | J3: 45664 | M3: 45678 | Q3: The CAR form was closed on 1/14/25 and revised based on the client's recommendation, then closed again on 1/21/25 | S3: =IF(ISBLANK(Table2[[#This Row],[Complete corrective actions (Approved Date)]]), TODAY()-Table2[[#This Row],[CAR initialized date]], "CLOSED") -> CLOSED
A4: Bellingham (Ferndale), WA | B4: =VLOOKUP(Table2[[#This Row],[Location (drop-down)]],'List source'!D$2:E$71,2,FALSE) -> 132 | C4: 002 | D4: ="C" & C4 &"-" & B4 & "-" & "25" -> C002-132-25 | E4: Other (QC, customer alert, improper procedure) | F4: Amspec | G4: CQI reporting | H4: Operations | I4: HM | J4: 45664 | M4: 45671 | S4: =IF(ISBLANK(Table2[[#This Row],[Complete corrective actions (Approved Date)]]), TODAY()-Table2[[#This Row],[CAR initialized date]], "CLOSED") -> CLOSED
A5: San Francisco (Concord), CA | B5: =VLOOKUP(Table2[[#This Row],[Location (drop-down)]],'List source'!D$2:E$71,2,FALSE) -> 131 | C5: 003 | D5: ="C" & C5 &"-" & B5 & "-" & "25" -> C003-131-25 | E5: Other (QC, customer alert, improper procedure) | F5: Amspec | G5: CQI Reporting | H5: Operations | I5: HM | J5: 45666 | M5: 45679 | S5: =IF(ISBLANK(Table2[[#This Row],[Complete corrective actions (Approved Date)]]), TODAY()-Table2[[#This Row],[CAR initialized date]], "CLOSED") -> CLOSED
A6: Boston (Everett), MA | B6: =VLOOKUP(Table2[[#This Row],[Location (drop-down)]],'List source'!D$2:E$71,2,FALSE) -> 141 | C6: 004 | D6: ="C" & C6 &"-" & B6 & "-" & "25" -> C004-141-25 | E6: Complaint | F6: Irving | G6: Failing to send email to correct distribution | H6: Operations | I6: MT | J6: 45667 | M6: 45674 | S6: =IF(ISBLANK(Table2[[#This Row],[Complete corrective actions (Approved Date)]]), TODAY()-Table2[[#This Row],[CAR initialized date]], "CLOSED") -> CLOSED
A7: San Francisco (Concord), CA | B7: =VLOOKUP(Table2[[#This Row],[Location (drop-down)]],'List source'!D$2:E$71,2,FALSE) -> 131 | C7: 005 | D7: ="C" & C7 &"-" & B7 & "-" & "25" -> C005-131-25 | E7: Customer audit | F7: Chevron | G7: D6299: Chilling of the Toluene Standard Fuel | H7: Lab | I7: HM | J7: 45671 | M7: 45698 | R7: People (miscommunication, complacency, competency) | S7: =IF(ISBLANK(Table2[[#This Row],[Complete corrective actions (Approved Date)]]), TODAY()-Table2[[#This Row],[CAR initialized date]], "CLOSED") -> CLOSED
A8: San Francisco (Concord), CA | B8: =VLOOKUP(Table2[[#This Row],[Location (drop-down)]],'List source'!D$2:E$71,2,FALSE) -> 131 | C8: 006 | D8: ="C" & C8 &"-" & B8 & "-" & "25" -> C006-131-25 | E8: Customer audit | F8: Chevron | G8: D445: Incorrect Determinability | H8: Lab | I8: HM | J8: 45671 | M8: 45707 | R8: People (miscommunication, complacency, competency) | S8: =IF(ISBLANK(Table2[[#This Row],[Complete corrective actions (Approved Date)]]), TODAY()-Table2[[#This Row],[CAR initialized date]], "CLOSED") -> CLOSED
A9: San Francisco (Concord), CA | B9: =VLOOKUP(Table2[[#This Row],[Location (drop-down)]],'List source'!D$2:E$71,2,FALSE) -> 131 | C9: 007 | D9: ="C" & C9 &"-" & B9 & "-" & "25" -> C007-131-25 | E9: Customer audit | F9: Chevron | G9: D3948: QA chart failing TPI. | H9: Lab | I9: HM | J9: 45671 | M9: 45792 | R9: People (miscommunication, complacency, competency) | S9: =IF(ISBLANK(Table2[[#This Row],[Complete corrective actions (Approved Date)]]), TODAY()-Table2[[#This Row],[CAR initialized date]], "CLOSED") -> CLOSED
A10: San Francisco (Concord), CA | B10: =VLOOKUP(Table2[[#This Row],[Location (drop-down)]],'List source'!D$2:E$71,2,FALSE) -> 131 | C10: 008 | D10: ="C" & C10 &"-" & B10 & "-" & "25" -> C008-131-25 | E10: Customer audit | F10: Chevron | G10: D445: Inconsistent Bath Temperature | H10: Lab | I10: HM | J10: 45671 | M10: 45722 | R10: Equipment (malfunction, maintenance, calibration/verification, incorrect setting) | S10: =IF(ISBLANK(Table2[[#This Row],[Complete corrective actions (Approved Date)]]), TODAY()-Table2[[#This Row],[CAR initialized date]], "CLOSED") -> CLOSED
A11: Mont Belvieu, TX | B11: =VLOOKUP(Table2[[#This Row],[Location (drop-down)]],'List source'!D$2:E$71,2,FALSE) -> 120a | C11: 009 | D11: ="C" & C11 &"-" & B11 & "-" & "25" -> C009-120a-25 | E11: Internal assessment (9001 & 17025) | G11: Technical Record | H11: Lab | I11: MT | J11: 45681 | M11: 45725 | R11: People (miscommunication, complacency, competency) | S11: =IF(ISBLANK(Table2[[#This Row],[Complete corrective actions (Approved Date)]]), TODAY()-Table2[[#This Row],[CAR initialized date]], "CLOSED") -> CLOSED
A12: Mont Belvieu, TX | B12: =VLOOKUP(Table2[[#This Row],[Location (drop-down)]],'List source'!D$2:E$71,2,FALSE) -> 120a | C12: 010 | D12: ="C" & C12 &"-" & B12 & "-" & "25" -> C010-120a-25 | E12: Internal assessment (9001 & 17025) | G12: TMA | H12: Lab | I12: MT | J12: 45681 | M12: 45727 | R12: People (miscommunication, complacency, competency) | S12: =IF(ISBLANK(Table2[[#This Row],[Complete corrective actions (Approved Date)]]), TODAY()-Table2[[#This Row],[CAR initialized date]], "CLOSED") -> CLOSED
A13: Mont Belvieu, TX | B13: =VLOOKUP(Table2[[#This Row],[Location (drop-down)]],'List source'!D$2:E$71,2,FALSE) -> 120a | C13: 011 | D13: ="C" & C13 &"-" & B13 & "-" & "25" -> C011-120a-25 | E13: Internal assessment (9001 & 17025) | G13: SQC | H13: Lab | I13: MT | J13: 45681 | M13: 45727 | R13: People (miscommunication, complacency, competency) | S13: =IF(ISBLANK(Table2[[#This Row],[Complete corrective actions (Approved Date)]]), TODAY()-Table2[[#This Row],[CAR initialized date]], "CLOSED") -> CLOSED
A14: CORPORATE, NJ | B14: =VLOOKUP(Table2[[#This Row],[Location (drop-down)]],'List source'!D$2:E$71,2,FALSE) -> 101 | C14: 012 | D14: ="C" & C14 &"-" & B14 & "-" & "25" -> C012-101-25 | E14: Other (QC, customer alert, improper procedure) | F14: Methanex | G14: Delay in investigating PT outlier | H14: Lab | I14: MT | J14: 45681 | M14: 45699 | S14: =IF(ISBLANK(Table2[[#This Row],[Complete corrective actions (Approved Date)]]), TODAY()-Table2[[#This Row],[CAR initialized date]], "CLOSED") -> CLOSED
A15: Brownsville, TX | B15: =VLOOKUP(Table2[[#This Row],[Location (drop-down)]],'List source'!D$2:E$71,2,FALSE) -> 158 | C15: 013 | D15: ="C" & C15 &"-" & B15 & "-" & "25" -> C013-158-25 | E15: Internal assessment (9001 & 17025) | G15: Cal certs for field inspection equipment not reviewed | H15: Operations | I15: AH | J15: 45684 | M15: 45769 | R15: People (miscommunication, complacency, competency) | S15: =IF(ISBLANK(Table2[[#This Row],[Complete corrective actions (Approved Date)]]), TODAY()-Table2[[#This Row],[CAR initialized date]], "CLOSED") -> CLOSED
A16: Brownsville, TX | B16: =VLOOKUP(Table2[[#This Row],[Location (drop-down)]],'List source'!D$2:E$71,2,FALSE) -> 158 | C16: 014 | D16: ="C" & C16 &"-" & B16 & "-" & "25" -> C014-158-25 | E16: Internal assessment (9001 & 17025) | G16: ISO 17025 Clause 7.2.1 Test witnessing | H16: Lab | I16: AH | J16: 45684 | M16: 45768 | R16: People (miscommunication, complacency, competency) | S16: =IF(ISBLANK(Table2[[#This Row],[Complete corrective actions (Approved Date)]]), TODAY()-Table2[[#This Row],[CAR initialized date]], "CLOSED") -> CLOSED
A17: Brownsville, TX | B17: =VLOOKUP(Table2[[#This Row],[Location (drop-down)]],'List source'!D$2:E$71,2,FALSE) -> 158 | C17: 015 | D17: ="C" & C17 &"-" & B17 & "-" & "25" -> C015-158-25 | E17: Internal assessment (9001 & 17025) | G17: ISO 17025 Clause 7.5 Technical records | H17: Lab | I17: AH | J17: 45684 | M17: 45818 | R17: People (miscommunication, complacency, competency) | S17: =IF(ISBLANK(Table2[[#This Row],[Complete corrective actions (Approved Date)]]), TODAY()-Table2[[#This Row],[CAR initialized date]], "CLOSED") -> CLOSED
A18: Brownsville, TX | B18: =VLOOKUP(Table2[[#This Row],[Location (drop-down)]],'List source'!D$2:E$71,2,FALSE) -> 158 | C18: 016 | D18: ="C" & C18 &"-" & B18 & "-" & "25" -> C016-158-25 | E18: Internal assessment (9001 & 17025) | G18: ISO 17025 Clause 7.8 Reporting results | H18: Lab | I18: AH | J18: 45684 | M18: 45768 | R18: People (miscommunication, complacency, competency) | S18: =IF(ISBLANK(Table2[[#This Row],[Complete corrective actions (Approved Date)]]), TODAY()-Table2[[#This Row],[CAR initialized date]], "CLOSED") -> CLOSED
A19: Brownsville, TX | B19: =VLOOKUP(Table2[[#This Row],[Location (drop-down)]],'List source'!D$2:E$71,2,FALSE) -> 158 | C19: 017 | D19: ="C" & C19 &"-" & B19 & "-" & "25" -> C017-158-25 | E19: Internal assessment (9001 & 17025) | G19: ISO 17025 Clause 8.2, 8.3 Document control | H19: Lab | I19: AH | J19: 45684 | M19: 45743 | R19: Management (Lack of accountability, inadequate risk assessment) | S19: =IF(ISBLANK(Table2[[#This Row],[Complete corrective actions (Approved Date)]]), TODAY()-Table2[[#This Row],[CAR initialized date]], "CLOSED") -> CLOSED
A20: Brownsville, TX | B20: =VLOOKUP(Table2[[#This Row],[Location (drop-down)]],'List source'!D$2:E$71,2,FALSE) -> 158 | C20: 018 | D20: ="C" & C20 &"-" & B20 & "-" & "25" -> C018-158-25 | E20: Internal assessment (9001 & 17025) | G20: ISO 17025 Clause 6.4 Solutions prep records | H20: Lab | I20: AH | J20: 45684 | M20: 45721 | R20: People (miscommunication, complacency, competency) | S20: =IF(ISBLANK(Table2[[#This Row],[Complete corrective actions (Approved Date)]]), TODAY()-Table2[[#This Row],[CAR initialized date]], "CLOSED") -> CLOSED
A21: Brownsville, TX | B21: =VLOOKUP(Table2[[#This Row],[Location (drop-down)]],'List source'!D$2:E$71,2,FALSE) -> 158 | C21: 019 | D21: ="C" & C21 &"-" & B21 & "-" & "25" -> C019-158-25 | E21: Internal assessment (9001 & 17025) | G21: ISO 17025 Clause 6.2 Training records | H21: Lab | I21: AH | J21: 45684 | M21: 45807 | R21: People (miscommunication, complacency, competency) | S21: =IF(ISBLANK(Table2[[#This Row],[Complete corrective actions (Approved Date)]]), TODAY()-Table2[[#This Row],[CAR initialized date]], "CLOSED") -> CLOSED
A22: Mobile, AL | B22: =VLOOKUP(Table2[[#This Row],[Location (drop-down)]],'List source'!D$2:E$71,2,FALSE) -> 146 | C22: 020 | D22: ="C" & C22 &"-" & B22 & "-" & "25" -> C020-146-25 | E22: Other (QC, customer alert, improper procedure) | G22: CAR and PTO are not closed in timely manner | H22: Lab | I22: MT | J22: 45681 | M22: 45825 | S22: =IF(ISBLANK(Table2[[#This Row],[Complete corrective actions (Approved Date)]]), TODAY()-Table2[[#This Row],[CAR initialized date]], "CLOSED") -> CLOSED
A23: Bellingham (Ferndale), WA | B23: =VLOOKUP(Table2[[#This Row],[Location (drop-down)]],'List source'!D$2:E$71,2,FALSE) -> 132 | C23: 021 | D23: ="C" & C23 &"-" & B23 & "-" & "25" -> C021-132-25 | E23: Other (QC, customer alert, improper procedure) | F23: AmSpec | G23: The API used for volumetric calculations in the final report was incorrect | H23: Operations | I23: HM | J23: 45684 | M23: 45701 | S23: =IF(ISBLANK(Table2[[#This Row],[Complete corrective actions (Approved Date)]]), TODAY()-Table2[[#This Row],[CAR initialized date]], "CLOSED") -> CLOSED
A24: Bellingham (Ferndale), WA | B24: =VLOOKUP(Table2[[#This Row],[Location (drop-down)]],'List source'!D$2:E$71,2,FALSE) -> 132 | C24: 022 | D24: ="C" & C24 &"-" & B24 & "-" & "25" -> C022-132-25 | E24: Other (QC, customer alert, improper procedure) | F24: AmSpec | G24: Customer Recheck Request for D2624 Result on Job #132-24-01470 (Sample-072) Due to Discrepancy in Conductivity Test | H24: Lab | I24: HM | J24: 45685 | M24: 45688 | S24: =IF(ISBLANK(Table2[[#This Row],[Complete corrective actions (Approved Date)]]), TODAY()-Table2[[#This Row],[CAR initialized date]], "CLOSED") -> CLOSED
A25: Avenel (NYH), NJ | B25: =VLOOKUP(Table2[[#This Row],[Location (drop-down)]],'List source'!D$2:E$71,2,FALSE) -> 110 | C25: 023 | D25: ="C" & C25 &"-" & B25 & "-" & "25" -> C023-110-25 | E25: Complaint | F25: Irving Oil | G25: Irving - using additives not registered with EPA | H25: Operations | I25: MT | J25: 45686 | M25: 45687 | S25: =IF(ISBLANK(Table2[[#This Row],[Complete corrective actions (Approved Date)]]), TODAY()-Table2[[#This Row],[CAR initialized date]], "CLOSED") -> CLOSED
A26: San Francisco (Concord), CA | B26: =VLOOKUP(Table2[[#This Row],[Location (drop-down)]],'List source'!D$2:E$71,2,FALSE) -> 131 | C26: 024 | D26: ="C" & C26 &"-" & B26 & "-" & "25" -> C024-131-25 | E26: Internal assessment (9001 & 17025) | G26: Technical Bulletin Review | H26: Lab | I26: ECu | J26: 45687 | M26: 45742 | R26: Management (Lack of accountability, inadequate risk assessment) | S26: =IF(ISBLANK(Table2[[#This Row],[Complete corrective actions (Approved Date)]]), TODAY()-Table2[[#This Row],[CAR initialized date]], "CLOSED") -> CLOSED
A27: San Francisco (Concord), CA | B27: =VLOOKUP(Table2[[#This Row],[Location (drop-down)]],'List source'!D$2:E$71,2,FALSE) -> 131 | C27: 025 | D27: ="C" & C27 &"-" & B27 & "-" & "25" -> C025-131-25 | E27: Internal assessment (9001 & 17025) | G27: Inspector Training Records | H27: Operations | I27: ECu | J27: 45687 | M27: 45742 | R27: People (miscommunication, complacency, competency) | S27: =IF(ISBLANK(Table2[[#This Row],[Complete corrective actions (Approved Date)]]), TODAY()-Table2[[#This Row],[CAR initialized date]], "CLOSED") -> CLOSED
A28: San Francisco (Concord), CA | B28: =VLOOKUP(Table2[[#This Row],[Location (drop-down)]],'List source'!D$2:E$71,2,FALSE) -> 131 | C28: 026 | D28: ="C" & C28 &"-" & B28 & "-" & "25" -> C026-131-25 | E28: Internal assessment (9001 & 17025) | G28: Job File Review | H28: Lab & Ops | I28: ECu | J28: 45687 | M28: 45777 | R28: Management (Lack of accountability, inadequate risk assessment) | S28: =IF(ISBLANK(Table2[[#This Row],[Complete corrective actions (Approved Date)]]), TODAY()-Table2[[#This Row],[CAR initialized date]], "CLOSED") -> CLOSED
A29: San Francisco (Concord), CA | B29: =VLOOKUP(Table2[[#This Row],[Location (drop-down)]],'List source'!D$2:E$71,2,FALSE) -> 131 | C29: 027 | D29: ="C" & C29 &"-" & B29 & "-" & "25" -> C027-131-25 | E29: Internal assessment (9001 & 17025) | G29: Incomplete / missing MOCs | H29: Lab | I29: ECu | J29: 45687 | M29: 45705 | R29: Management (Lack of accountability, inadequate risk assessment) | S29: =IF(ISBLANK(Table2[[#This Row],[Complete corrective actions (Approved Date)]]), TODAY()-Table2[[#This Row],[CAR initialized date]], "CLOSED") -> CLOSED
A30: San Francisco (Concord), CA | B30: =VLOOKUP(Table2[[#This Row],[Location (drop-down)]],'List source'!D$2:E$71,2,FALSE) -> 131 | C30: 028 | D30: ="C" & C30 &"-" & B30 & "-" & "25" -> C028-131-25 | E30: Internal assessment (9001 & 17025) | G30: Chemical inventory | H30: Lab | I30: ECu | J30: 45687 | M30: 45756 | R30: Management (Lack of accountability, inadequate risk assessment) | S30: =IF(ISBLANK(Table2[[#This Row],[Complete corrective actions (Approved Date)]]), TODAY()-Table2[[#This Row],[CAR initialized date]], "CLOSED") -> CLOSED
A31: San Francisco (Concord), CA | B31: =VLOOKUP(Table2[[#This Row],[Location (drop-down)]],'List source'!D$2:E$71,2,FALSE) -> 131 | C31: 029 | D31: ="C" & C31 &"-" & B31 & "-" & "25" -> C029-131-25 | E31: Internal assessment (9001 & 17025) | G31: ISO 17025 Clause 6.2.5 Training records | H31: Lab | I31: ECu | J31: 45687 | M31: 45806 | R31: Management (Lack of accountability, inadequate risk assessment) | S31: =IF(ISBLANK(Table2[[#This Row],[Complete corrective actions (Approved Date)]]), TODAY()-Table2[[#This Row],[CAR initialized date]], "CLOSED") -> CLOSED
A32: San Francisco (Concord), CA | B32: =VLOOKUP(Table2[[#This Row],[Location (drop-down)]],'List source'!D$2:E$71,2,FALSE) -> 131 | C32: 030 | D32: ="C" & C32 &"-" & B32 & "-" & "25" -> C030-131-25 | E32: Internal assessment (9001 & 17025) | G32: ISO 17025 Clause 6.4 Equipment Records | H32: Lab | I32: ECu | J32: 45687 | M32: 45799 | R32: Management (Lack of accountability, inadequate risk assessment) | S32: =IF(ISBLANK(Table2[[#This Row],[Complete corrective actions (Approved Date)]]), TODAY()-Table2[[#This Row],[CAR initialized date]], "CLOSED") -> CLOSED
A33: San Francisco (Concord), CA | B33: =VLOOKUP(Table2[[#This Row],[Location (drop-down)]],'List source'!D$2:E$71,2,FALSE) -> 131 | C33: 031 | D33: ="C" & C33 &"-" & B33 & "-" & "25" -> C031-131-25 | E33: Internal assessment (9001 & 17025) | G33: ISO 17025 Clause 6.4.9 and 7.10 Deviation | H33: Lab | I33: ECu | J33: 45687 | M33: 45756 | R33: People (miscommunication, complacency, competency) | S33: =IF(ISBLANK(Table2[[#This Row],[Complete corrective actions (Approved Date)]]), TODAY()-Table2[[#This Row],[CAR initialized date]], "CLOSED") -> CLOSED
A34: San Francisco (Concord), CA | B34: =VLOOKUP(Table2[[#This Row],[Location (drop-down)]],'List source'!D$2:E$71,2,FALSE) -> 131 | C34: 032 | D34: ="C" & C34 &"-" & B34 & "-" & "25" -> C032-131-25 | E34: Internal assessment (9001 & 17025) | G34: ISO 17025 Clause 6.5.1 Metrological Traceability | H34: Lab | I34: ECu | J34: 45687 | M34: 45916 | S34: =IF(ISBLANK(Table2[[#This Row],[Complete corrective actions (Approved Date)]]), TODAY()-Table2[[#This Row],[CAR initialized date]], "CLOSED") -> CLOSED
A35: San Francisco (Concord), CA | B35: =VLOOKUP(Table2[[#This Row],[Location (drop-down)]],'List source'!D$2:E$71,2,FALSE) -> 131 | C35: 033 | D35: ="C" & C35 &"-" & B35 & "-" & "25" -> C033-131-25 | E35: Internal assessment (9001 & 17025) | G35: ISO 17025 Clause 6.6.2c Ext. Products | H35: Lab | I35: ECu | J35: 45687 | M35: 45799 | R35: Management (Lack of accountability, inadequate risk assessment) | S35: =IF(ISBLANK(Table2[[#This Row],[Complete corrective actions (Approved Date)]]), TODAY()-Table2[[#This Row],[CAR initialized date]], "CLOSED") -> CLOSED
A36: San Francisco (Concord), CA | B36: =VLOOKUP(Table2[[#This Row],[Location (drop-down)]],'List source'!D$2:E$71,2,FALSE) -> 131 | C36: 034 | D36: ="C" & C36 &"-" & B36 & "-" & "25" -> C034-131-25 | E36: Internal assessment (9001 & 17025) | G36: ISO 17025 Clause 7.1 Contract Review | H36: Lab & Ops | I36: ECu | J36: 45687 | M36: 45777 | R36: People (miscommunication, complacency, competency) | S36: =IF(ISBLANK(Table2[[#This Row],[Complete corrective actions (Approved Date)]]), TODAY()-Table2[[#This Row],[CAR initialized date]], "CLOSED") -> CLOSED
A37: San Francisco (Concord), CA | B37: =VLOOKUP(Table2[[#This Row],[Location (drop-down)]],'List source'!D$2:E$71,2,FALSE) -> 131 | C37: 035 | D37: ="C" & C37 &"-" & B37 & "-" & "25" -> C035-131-25 | E37: Internal assessment (9001 & 17025) | G37: ISO 17025 Clause 7.2.1 Test witnessing | H37: Lab | I37: ECu | J37: 45687 | M37: 45799 | R37: People (miscommunication, complacency, competency) | S37: =IF(ISBLANK(Table2[[#This Row],[Complete corrective actions (Approved Date)]]), TODAY()-Table2[[#This Row],[CAR initialized date]], "CLOSED") -> CLOSED
A38: San Francisco (Concord), CA | B38: =VLOOKUP(Table2[[#This Row],[Location (drop-down)]],'List source'!D$2:E$71,2,FALSE) -> 131 | C38: 036 | D38: ="C" & C38 &"-" & B38 & "-" & "25" -> C036-131-25 | E38: Internal assessment (9001 & 17025) | G38: ISO 17025 Clause 7.5 Technical records | H38: Lab | I38: ECu | J38: 45687 | M38: 45777 | O38: 45861 | P38: Yes | Q38: CAR completed - pending effectiveness review 07.25 | R38: People (miscommunication, complacency, competency) | S38: =IF(ISBLANK(Table2[[#This Row],[Complete corrective actions (Approved Date)]]), TODAY()-Table2[[#This Row],[CAR initialized date]], "CLOSED") -> CLOSED
A39: San Francisco (Concord), CA | B39: =VLOOKUP(Table2[[#This Row],[Location (drop-down)]],'List source'!D$2:E$71,2,FALSE) -> 131 | C39: 037 | D39: ="C" & C39 &"-" & B39 & "-" & "25" -> C037-131-25 | E39: Internal assessment (9001 & 17025) | G39: ISO 17025 Clause 7.7.1 Validity of Results | H39: Lab | I39: ECu | J39: 45687 | M39: 45868 | R39: Management (Lack of accountability, inadequate risk assessment) | S39: =IF(ISBLANK(Table2[[#This Row],[Complete corrective actions (Approved Date)]]), TODAY()-Table2[[#This Row],[CAR initialized date]], "CLOSED") -> CLOSED
A40: San Francisco (Concord), CA | B40: =VLOOKUP(Table2[[#This Row],[Location (drop-down)]],'List source'!D$2:E$71,2,FALSE) -> 131 | C40: 038 | D40: ="C" & C40 &"-" & B40 & "-" & "25" -> C038-131-25 | E40: Internal assessment (9001 & 17025) | G40: ISO 17025 Clause 7.8 Reporting results | H40: Lab | I40: ECu | J40: 45687 | M40: 45777 | O40: 45877 | P40: No | Q40: repeating issue, see C351 | R40: People (miscommunication, complacency, competency) | S40: =IF(ISBLANK(Table2[[#This Row],[Complete corrective actions (Approved Date)]]), TODAY()-Table2[[#This Row],[CAR initialized date]], "CLOSED") -> CLOSED
...

Sheet PAR '25
A1: Location (drop-down) | B1: Location ID | C1: # | D1: PAR # | E1: PAR type | F1: BRIEF DESCRIPTION OF PAR if VOID: Location, type, details (initials, date) | G1: PAR initialized date | H1: QA team member initials | I1: Date closed | J1: Area (Ops, Lab, Misc.) (drop-down) | K1: Notes
A2: San Francisco (Concord), CA | B2: =VLOOKUP(Table24[[#This Row],[Location (drop-down)]],'List source'!D$2:E$71,2,FALSE) -> 131 | C2: 001 | D2: ="P" & C2 & "-" & B2 & "-" & "25" -> P001-131-25 | E2: Customer audit | F2: Suggest utilizing new tools for better maintenance, monitoring, and traceability on the D2966 Research Engine. | G2: 45671 | H2: HM | I2: 45826 | J2: Lab
A3: St Croix, USVI | B3: =VLOOKUP(Table24[[#This Row],[Location (drop-down)]],'List source'!D$2:E$71,2,FALSE) -> 210 | C3: 002 | D3: ="P" & C3 & "-" & B3 & "-" & "25" -> P002-210-25 | E3: 3rd party audit (DNV, A2LA, AASHTO…) | F3: Relating to requirement 6.4.8 - Witnessed that at ASTM D5002 workstation, lab’s green internal ID label w/ cal-related info had this Anton Paar instrument for use as (only) as D4052 instrument (though it’s capable of both method). | G3: 45680 | H3: JP | I3: 45958 | J3: Lab
A4: St Croix, USVI | B4: =VLOOKUP(Table24[[#This Row],[Location (drop-down)]],'List source'!D$2:E$71,2,FALSE) -> 210 | C4: 003 | D4: ="P" & C4 & "-" & B4 & "-" & "25" -> P003-210-25 | E4: 3rd party audit (DNV, A2LA, AASHTO…) | F4: Relating to requirement 7.5.1 - Observation 2 a & b – a) At ASTM D445 Kinematic Viscosity workstation witnessed technician documenting results to scrap paper (to later be transferred to bench data sheet), lacking specifics of task, e.g., method number, time and date reading were made. b) – at ASTM D1298 and D287 workstations acting bench sheet is a sticky note, tech said info (w/ equip serial num and result) from there is THEN transferred to laptop. It’s understood that this was not the normal SOP, but was a work around for the assessment’s non-actual samples. | G4: 45680 | H4: JP | I4: 45958 | J4: Lab
A5: St Croix, USVI | B5: =VLOOKUP(Table24[[#This Row],[Location (drop-down)]],'List source'!D$2:E$71,2,FALSE) -> 210 | C5: 004 | D5: ="P" & C5 & "-" & B5 & "-" & "25" -> P004-210-25 | E5: 3rd party audit (DNV, A2LA, AASHTO…) | F5: Be careful not to accumulate uncontrolled, not-dated, irrelevant labels such as at this instrument such as was found at the OptiDist instrument at method D86 workstation | G5: 45680 | H5: JP | I5: 45958 | J5: Lab
A6: San Francisco (Concord), CA | B6: =VLOOKUP(Table24[[#This Row],[Location (drop-down)]],'List source'!D$2:E$71,2,FALSE) -> 131 | C6: 005 | D6: ="P" & C6 & "-" & B6 & "-" & "25" -> P005-131-25 | E6: Internal assessment (9001 & 17025) | F6: D445-The local logbook will be updated, and the lab will use different viscometers for duplicate analysis. | G6: 45687 | H6: HM | I6: 45838 | J6: Lab
A7: San Francisco (Concord), CA | B7: =VLOOKUP(Table24[[#This Row],[Location (drop-down)]],'List source'!D$2:E$71,2,FALSE) -> 131 | C7: 006 | D7: ="P" & C7 & "-" & B7 & "-" & "25" -> P006-131-25 | E7: Internal assessment (9001 & 17025) | F7: Update the calibration/verification schedule with necessary activities for each instrument. Recalibrate instruments before use (e.g., tachometer, flow meter), replace thermometer with faded IDs, and address AOC items 11, 14, 15, 17, 18, 19, and 20 from the ISO 9001 IA report. | G7: 45687 | H7: HM | I7: 45838 | J7: Lab
A8: San Francisco (Concord), CA | B8: =VLOOKUP(Table24[[#This Row],[Location (drop-down)]],'List source'!D$2:E$71,2,FALSE) -> 131 | C8: 007 | D8: ="P" & C8 & "-" & B8 & "-" & "25" -> P007-131-25 | E8: Internal assessment (9001 & 17025) | F8: Instrument binders still utilizing 10 tab system. Uncontroled methods (obsolete revision) observed in the binders. AOC item # 6 & 7. ISO 9001 IA report. | G8: 45687 | H8: HM | I8: 45838 | J8: Lab
A9: San Francisco (Concord), CA | B9: =VLOOKUP(Table24[[#This Row],[Location (drop-down)]],'List source'!D$2:E$71,2,FALSE) -> 131 | C9: 008 | D9: ="P" & C9 & "-" & B9 & "-" & "25" -> P008-131-25 | E9: Internal assessment (9001 & 17025) | F9: Method specific TMAs are not being utilized. | G9: 45687 | H9: HM | I9: 45868 | J9: Lab
A10: San Francisco (Concord), CA | B10: =VLOOKUP(Table24[[#This Row],[Location (drop-down)]],'List source'!D$2:E$71,2,FALSE) -> 131 | C10: 009 | D10: ="P" & C10 & "-" & B10 & "-" & "25" -> P009-131-25 | E10: Internal assessment (9001 & 17025) | F10: Incomplete inspector binders. Item# 5 and 13 ISO 9001 IA report. | G10: 45687 | H10: HM | I10: 45868 | J10: Lab
A11: Mobile, AL | B11: =VLOOKUP(Table24[[#This Row],[Location (drop-down)]],'List source'!D$2:E$71,2,FALSE) -> 146 | C11: 010 | D11: ="P" & C11 & "-" & B11 & "-" & "25" -> P010-146-25 | E11: Other (QC, customer alert, improper procedure) | F11: Not reporting PT on 17025 scope; has capabilities, but was not reported (response to A2LA assessor discussion) | G11: 45694 | H11: KA | I11: 45742 | J11: Lab
A12: CORPORATE, NJ | B12: =VLOOKUP(Table24[[#This Row],[Location (drop-down)]],'List source'!D$2:E$71,2,FALSE) -> 101 | C12: 011 | D12: ="P" & C12 & "-" & B12 & "-" & "25" -> P011-101-25 | E12: Other (QC, customer alert, improper procedure) | F12: Improve communication of external audit findings | G12: 45659 | H12: MT | I12: 45732 | J12: Lab & Ops
A13: VOIDED ASSMT/CAR/PAR NO | B13: =VLOOKUP(Table24[[#This Row],[Location (drop-down)]],'List source'!D$2:E$71,2,FALSE) -> VOID | C13: 012 | D13: ="P" & C13 & "-" & B13 & "-" & "25" -> P012-VOID-25 | E13: VOID | F13: VOID: Mickleton, 2024 PBMS Attest Prep (AH, 04/23/2025) | G13: VOID | H13: VOID | I13: VOID | J13: VOID | K13: PAR initiated Feb 2025, upgraded to CAR Apr 2025. See C179-180-25
A14: Port Arthur (Beaumont), TX | B14: =VLOOKUP(Table24[[#This Row],[Location (drop-down)]],'List source'!D$2:E$71,2,FALSE) -> 160 | C14: 013 | D14: ="P" & C14 & "-" & B14 & "-" & "25" -> P013-160-25 | E14: Other (QC, customer alert, improper procedure) | F14: Regularly reviewing and updating company controlled documents | G14: 45726 | H14: HB | I14: 45838 | J14: Lab
A15: Port Arthur (Beaumont), TX | B15: =VLOOKUP(Table24[[#This Row],[Location (drop-down)]],'List source'!D$2:E$71,2,FALSE) -> 160 | C15: 014 | D15: ="P" & C15 & "-" & B15 & "-" & "25" -> P014-160-25 | E15: Other (QC, customer alert, improper procedure) | F15: Implementing new safety training programs for lab staff | G15: 45726 | H15: HB | I15: 45839 | J15: Lab
A16: Baton Rouge (Gonzales), LA | B16: =VLOOKUP(Table24[[#This Row],[Location (drop-down)]],'List source'!D$2:E$71,2,FALSE) -> 190 | C16: 015 | D16: ="P" & C16 & "-" & B16 & "-" & "25" -> P015-190-25 | E16: Internal assessment (9001 & 17025) | F16: Training Record | G16: 45729 | H16: MT | I16: 45905
A17: Baton Rouge (Gonzales), LA | B17: =VLOOKUP(Table24[[#This Row],[Location (drop-down)]],'List source'!D$2:E$71,2,FALSE) -> 190 | C17: 016 | D17: ="P" & C17 & "-" & B17 & "-" & "25" -> P016-190-25 | E17: Internal assessment (9001 & 17025) | F17: No PAR issued | G17: 45729 | H17: MT | I17: 45785
A18: Baton Rouge (Gonzales), LA | B18: =VLOOKUP(Table24[[#This Row],[Location (drop-down)]],'List source'!D$2:E$71,2,FALSE) -> 190 | C18: 017 | D18: ="P" & C18 & "-" & B18 & "-" & "25" -> P017-190-25 | E18: Internal assessment (9001 & 17025) | F18: TMA schedule | G18: 45729 | H18: MT | I18: 45793
A19: Baton Rouge (Gonzales), LA | B19: =VLOOKUP(Table24[[#This Row],[Location (drop-down)]],'List source'!D$2:E$71,2,FALSE) -> 190 | C19: 018 | D19: ="P" & C19 & "-" & B19 & "-" & "25" -> P018-190-25 | E19: Internal assessment (9001 & 17025) | F19: MOC | G19: 45729 | H19: MT | I19: 45785
A20: Baytown, TX | B20: =VLOOKUP(Table24[[#This Row],[Location (drop-down)]],'List source'!D$2:E$71,2,FALSE) -> 161 | C20: 019 | D20: ="P" & C20 & "-" & B20 & "-" & "25" -> P019-161-25 | E20: Other (QC, customer alert, improper procedure) | F20: Sampling questions | G20: 45726 | H20: CS | I20: 45751 | J20: Operations | K20: CAF011-161-25
A21: Houston (HTC), TX | B21: =VLOOKUP(Table24[[#This Row],[Location (drop-down)]],'List source'!D$2:E$71,2,FALSE) -> 120 | C21: 020 | D21: ="P" & C21 & "-" & B21 & "-" & "25" -> P020-120-25 | E21: Complaint | F21: ATA claim on Approximate volumes | G21: 45764 | H21: HB | I21: 45804 | J21: Operations | K21: CAF014-120-25
A22: New Orleans (Destrehan), LA | B22: =VLOOKUP(Table24[[#This Row],[Location (drop-down)]],'List source'!D$2:E$71,2,FALSE) -> 170 | C22: 021 | D22: ="P" & C22 & "-" & B22 & "-" & "25" -> P021-170-25 | E22: Complaint | F22: ATA - Iron/Org Chloride reporting and rounding results | G22: 45768 | H22: DA
A23: Levis (Quebec City), Quebec | B23: =VLOOKUP(Table24[[#This Row],[Location (drop-down)]],'List source'!D$2:E$71,2,FALSE) -> 194 | C23: 022 | D23: ="P" & C23 & "-" & B23 & "-" & "25" -> P022-194-25 | E23: Internal assessment (9001 & 17025) | F23: Equipment - Calibrations / Documentation | G23: 45772 | H23: Ecu | I23: 45777 | J23: Lab
A24: Los Angeles (Signal Hill), CA | B24: =VLOOKUP(Table24[[#This Row],[Location (drop-down)]],'List source'!D$2:E$71,2,FALSE) -> 130 | C24: 023 | D24: ="P" & C24 & "-" & B24 & "-" & "25" -> P023-130-25 | E24: Customer audit | F24: Chevron - D4294 Instrument to be adjusted to only perform one single reading instead of triplicates per run. | G24: 45782 | H24: HM | I24: 45784 | J24: Lab
A25: Los Angeles (Signal Hill), CA | B25: =VLOOKUP(Table24[[#This Row],[Location (drop-down)]],'List source'!D$2:E$71,2,FALSE) -> 130 | C25: 024 | D25: ="P" & C25 & "-" & B25 & "-" & "25" -> P024-130-25 | E25: Customer audit | F25: Chevron - D4294 Record investigation on SQC chart violations (comments) | G25: 45782 | H25: HM | I25: 45784 | J25: Lab
A26: Los Angeles (Signal Hill), CA | B26: =VLOOKUP(Table24[[#This Row],[Location (drop-down)]],'List source'!D$2:E$71,2,FALSE) -> 130 | C26: 025 | D26: ="P" & C26 & "-" & B26 & "-" & "25" -> P025-130-25 | E26: Customer audit | F26: Chevron - D5002 No laboratory control sample (LCS) for crude oil. | G26: 45782 | H26: HM | I26: 45786 | J26: Lab
A27: Baytown, TX | B27: =VLOOKUP(Table24[[#This Row],[Location (drop-down)]],'List source'!D$2:E$71,2,FALSE) -> 161 | C27: 026 | D27: ="P" & C27 & "-" & B27 & "-" & "25" -> P026-161-25 | E27: Other (QC, customer alert, improper procedure) | F27: Inspector used vessels equipment without following Exxon Baytown’s procedures in notifying the marine supervisor’s permission to gauge | G27: 45784 | H27: HB | J27: Operations
A28: St Croix, USVI | B28: =VLOOKUP(Table24[[#This Row],[Location (drop-down)]],'List source'!D$2:E$71,2,FALSE) -> 210 | C28: 027 | D28: ="P" & C28 & "-" & B28 & "-" & "25" -> P027-210-25 | E28: Other (QC, customer alert, improper procedure) | F28: Thermometer in use (12F SN: 4274) lacked initial calibration certificates as required; nonconformance with ISO/IEC 17025:2017 clauses 6.4.4 and 6.5.1. | G28: 45791 | H28: JP | I28: 45958 | J28: Lab
A29: Los Angeles (Signal Hill), CA | B29: =VLOOKUP(Table24[[#This Row],[Location (drop-down)]],'List source'!D$2:E$71,2,FALSE) -> 130 | C29: 028 | D29: ="P" & C29 & "-" & B29 & "-" & "25" -> P028-130-25 | E29: Customer audit | F29: MPC - Building evacuation plans were not adequately displayed (new admin area) | G29: 45807 | H29: HM | J29: Lab & Ops
A30: Los Angeles (Signal Hill), CA | B30: =VLOOKUP(Table24[[#This Row],[Location (drop-down)]],'List source'!D$2:E$71,2,FALSE) -> 130 | C30: 029 | D30: ="P" & C30 & "-" & B30 & "-" & "25" -> P029-130-25 | E30: Customer audit | F30: MPC - Inspector has expired PET and H2S bump test not completed monthly. | G30: 45807 | H30: HM | I30: 45940 | J30: Operations
A31: Los Angeles (Signal Hill), CA | B31: =VLOOKUP(Table24[[#This Row],[Location (drop-down)]],'List source'!D$2:E$71,2,FALSE) -> 130 | C31: 030 | D31: ="P" & C31 & "-" & B31 & "-" & "25" -> P030-130-25 | E31: Customer audit | F31: MPC - D7169 Lack of maintenance record and consider additional ventilation when handling CS2. | G31: 45807 | H31: HM | J31: Lab
A32: Mobile, AL | B32: =VLOOKUP(Table24[[#This Row],[Location (drop-down)]],'List source'!D$2:E$71,2,FALSE) -> 146 | C32: 031 | D32: ="P" & C32 & "-" & B32 & "-" & "25" -> P031-146-25 | E32: Customer audit | F32: Chevron Pascagoula - H2S Bump Test records | G32: 45862 | H32: AH | I32: 45873 | J32: Operations | K32: Audit No.: A094-146-25
A33: New Orleans (Destrehan), LA | B33: =VLOOKUP(Table24[[#This Row],[Location (drop-down)]],'List source'!D$2:E$71,2,FALSE) -> 170 | C33: 032 | D33: ="P" & C33 & "-" & B33 & "-" & "25" -> P032-170-25 | E33: Internal assessment (9001 & 17025) | F33: Sample Management - Lab composite samples were not recorded on SR-1s and AIMS labels are placed over inspector raw data. | G33: 45810 | H33: DA
A34: New Orleans (Destrehan), LA | B34: =VLOOKUP(Table24[[#This Row],[Location (drop-down)]],'List source'!D$2:E$71,2,FALSE) -> 170 | C34: 033 | D34: ="P" & C34 & "-" & B34 & "-" & "25" -> P033-170-25 | E34: Internal assessment (9001 & 17025) | F34: Lab Training - Ethics and Data Integrity training for 2025 still pending for some lab staff. Several FL13.1a and FL13.1b missing approval initial and date. | G34: 45810 | H34: DA
A35: Mickleton (Philly), NJ | B35: =VLOOKUP(Table24[[#This Row],[Location (drop-down)]],'List source'!D$2:E$71,2,FALSE) -> 180 | C35: 034 | D35: ="P" & C35 & "-" & B35 & "-" & "25" -> P034-180-25 | E35: Other (QC, customer alert, improper procedure) | F35: New revision of LC 101 not updated for local phosphorus calibration | G35: 45882 | H35: AH | I35: 45930 | J35: Lab | K35: Requested by K. Briggs Aug 13
A36: St John, NB | B36: =VLOOKUP(Table24[[#This Row],[Location (drop-down)]],'List source'!D$2:E$71,2,FALSE) -> 199 | C36: 035 | D36: ="P" & C36 & "-" & B36 & "-" & "25" -> P035-199-25 | E36: Internal assessment (9001 & 17025) | F36: Several items from the audit A090-199-25 under the heading Opportunities for Improvement and Areas of Concern | G36: 45888 | H36: GF | I36: 45905 | J36: Operations
A37: Hamilton (Burlington), ON | B37: =VLOOKUP(Table24[[#This Row],[Location (drop-down)]],'List source'!D$2:E$71,2,FALSE) -> 189 | C37: 036 | D37: ="P" & C37 & "-" & B37 & "-" & "25" -> P036-189-25 | E37: Internal assessment (9001 & 17025) | F37: OFIs from audit #A068-189-25 | G37: 45894 | H37: KA | I37: 46010 | J37: Lab & Ops
A38: Hamilton (Burlington), ON | B38: =VLOOKUP(Table24[[#This Row],[Location (drop-down)]],'List source'!D$2:E$71,2,FALSE) -> 189 | C38: 037 | D38: ="P" & C38 & "-" & B38 & "-" & "25" -> P037-189-25 | E38: Internal assessment (9001 & 17025) | F38: AOCs from audit #A068-189-25 | G38: 45894 | H38: KA | I38: 46010 | J38: Lab & Ops
A39: Yorktown (Norfolk), VA | B39: =VLOOKUP(Table24[[#This Row],[Location (drop-down)]],'List source'!D$2:E$71,2,FALSE) -> 185 | C39: 038 | D39: ="P" & C39 & "-" & B39 & "-" & "25" -> P038-185-25 | E39: Customer audit | F39: Recommend inspectors keep DOT box to transport samples in their vehicle | G39: 45897 | H39: JP | J39: Operations | K39: Marathon Audit A091-185-25
A40: Yorktown (Norfolk), VA | B40: =VLOOKUP(Table24[[#This Row],[Location (drop-down)]],'List source'!D$2:E$71,2,FALSE) -> 185 | C40: 039 | D40: ="P" & C40 & "-" & B40 & "-" & "25" -> P039-185-25 | E40: Customer audit | F40: Recommend properly sealing octane reference fuel dispensing lines to avoid contamination | G40: 45897 | H40: JP | I40: 45930 | J40: Lab | K40: Marathon Audit A091-185-25
...

Sheet List source
A1: Types of Deficiency | B1: Types of Root Cause | C1: CAR / PAR Area | D1: Location | E1: Location ID | F1: Area
A2: Equipment & Reagent status | B2: Communication | C2: Lab | D2: A&B Labs - Baton Rouge, LA | E2: A&B-BR | I2: Yes
A3: Management (CQI, Quality Policy posting, PO, AVL, CAR/PAR) | B3: Equipment/ calibration | C3: Operations | D3: A&B Labs - Houston, TX | E3: A&B-HOU | I3: No
A4: PT | B4: Ineffective/ Lack system/ procedure | C4: Lab & Ops | D4: A&B Labs - Nederland, TX | E4: A&B-NED
A5: Safety | B5: Negligence (typo, no review) | C5: Misc | D5: A&B Labs - Tempe, AZ | E5: A&B-TEM
A6: Technical (Calibration/ Verification/ Maintenance/ PT/ method deviation) | B6: Normal statistics variance - no CA | C6: VOID | D6: AGRI (HTC) | E6: 119 | F6: USGC
A7: Traceability and records (SR-1, raw data) | B7: Training/ competency | D7: Albany, NY | E7: 111 | F7: USNE, USMW & Canada
A8: Training (include quality, safety, ethics) | B8: Unmanaged risks | D8: Avenel (NYH), NJ | E8: 110 | F8: USNE, USMW & Canada
A9: VOID | B9: VOID | D9: Bahamas (Freeport), GBI | E9: 215 | F9: SE & Caribbean
D10: Baltimore (Glen Burnie), MD | E10: 195 | F10: SE & Caribbean
B11: Cause of NC | D11: Baton Rouge (Gonzales), LA | E11: 190 | F11: SE & Caribbean
B12: People (miscommunication, complacency, competency) | D12: Baytown, TX | E12: 161 | F12: USGC
A13: CAR Type | B13: Equipment (malfunction, maintenance, calibration/verification, incorrect setting) | D13: Belle Chasse, LA | E13: 116 | F13: SE & Caribbean
A14: Complaint | B14: Methods (Inadequate / Deviation from Procedures) | D14: Bellingham (Ferndale), WA | E14: 132 | F14: USWC
A15: Customer audit | B15: Management (Lack of accountability, inadequate risk assessment) | D15: Bostco, TX | E15: 124 | F15: USGC
A16: 3rd party audit (DNV, A2LA, AASHTO…) | B16: Environment (Poor housekeeping, insufficient space, clutter) | D16: Boston (Everett), MA | E16: 141 | F16: USNE, USMW & Canada
A17: Internal assessment (9001 & 17025) | C17: CAF Area | D17: Brownsville, TX | E17: 158 | F17: USGC
A18: Other (QC, customer alert, improper procedure) | C18: Lab | D18: Cape Canaveral, FL | E18: 127 | F18: SE & Caribbean
A19: VOID | C19: Ops | D19: Chicago, IL | E19: 136 | F19: SE & Caribbean
C20: Lab & Ops | D20: Cincinnati (Erlanger), OH | E20: 138 | F20: SE & Caribbean
B21: Scope (assessment tracking) | C21: Admin | D21: Collins (Purvis), MS | E21: 115 | F21: SE & Caribbean
B22: Inspection | C22: Other | D22: CORPORATE, NJ | E22: 101 | F22: Corporate
B23: Laboratory | C23: VOID | D23: Corpus Christi, TX | E23: 155 | F23: USGC
A24: Type of Assessment (Assessment tracking) | B24: Inspection & Laboratory | D24: Corpus Christi, TX (CITGO Lab) | E24: 154 | F24: USGC
A25: Internal | B25: VOID | D25: Cushing, OK | E25: 159 | F25: USGC
A26: Customer | D26: Decatur, AL | E26: 147 | F26: SE & Caribbean
A27: Certifications | D27: Freeport, TX | E27: 157 | F27: USGC
A28: Regulatory | D28: Ft Lauderdale (Davie), FL | E28: 125 | F28: SE & Caribbean
A29: VOID | D29: Halifax (Dartmouth), NS | E29: 198 | F29: USNE, USMW & Canada
D30: Hamilton (Burlington), ON | E30: 189 | F30: USNE, USMW & Canada
A31: Agency type (Assessment Tracking) | D31: HOFTI / Channelview, TX | E31: 128 | F31: USGC
A32: Regulatory | D32: Houston (HTC), TX | E32: 120 | F32: USGC
A33: Certifications | D33: HST Weights & Measures | E33: 120W | F33: Calibration
A34: Accredited agency | D34: Ingleside, TX | E34: 155A | F34: USGC
A35: VOID | D35: Kenai, AK | E35: 133 | F35: USWC
D36: Lake Charles (Sulfur), LA | E36: 165 | F36: USGC
D37: Levis (Quebec City), Quebec | E37: 194 | F37: USNE, USMW & Canada
D38: Los Angeles (Signal Hill), CA | E38: 130 | F38: USWC
D39: Marcus Hook, PA | E39: 179 | F39: SE & Caribbean
D40: Memphis, TN | E40: 191 | F40: SE & Caribbean
...

Sheet CAF '25
A1: Location (drop-down) | B1: Location ID | C1: # | D1: CAF# | E1: Area | F1: Date initiated | G1: Date shared w/ customer | H1: Corrective Action completed, CAR approved. | I1: Brief description of complaint | J1: Area (Lab, Ops, Lab & Ops, Admin, Other, Void) (drop-down) | K1: CAR / PAR # (if applicable) | L1: Notes
A2: Bellingham (Ferndale), WA | B2: =VLOOKUP(Table2456[[#This Row],[Location (drop-down)]],'List source'!D$2:E$71,2,FALSE) -> 132 | C2: 001 | D2: ="CAF" & C2 & "-" & B2 & "-" & "25" -> CAF001-132-25 | E2: =VLOOKUP(Table2456[[#This Row],[Location (drop-down)]],Table1[#All],3,FALSE) -> USWC | F2: 45664 | G2: 45673 | H2: 45671 | I2: PBF - The client was not informed of the vessel's short loading due to draft restrictions | J2: Ops | K2: C001-132-25
A3: Boston (Everett), MA | B3: =VLOOKUP(Table2456[[#This Row],[Location (drop-down)]],'List source'!D$2:E$71,2,FALSE) -> 141 | C3: 002 | D3: ="CAF" & C3 & "-" & B3 & "-" & "25" -> CAF002-141-25 | E3: =VLOOKUP(Table2456[[#This Row],[Location (drop-down)]],Table1[#All],3,FALSE) -> USNE, USMW & Canada | F3: 45667 | G3: 45677 | H3: 45674 | I3: Irving - Repeatedly failing to send emails to Irving with the correct email distribution | J3: Ops | K3: C004-141-25
A4: Avenel (NYH), NJ | B4: =VLOOKUP(Table2456[[#This Row],[Location (drop-down)]],'List source'!D$2:E$71,2,FALSE) -> 110 | C4: 003 | D4: ="CAF" & C4 & "-" & B4 & "-" & "25" -> CAF003-110-25 | E4: =VLOOKUP(Table2456[[#This Row],[Location (drop-down)]],Table1[#All],3,FALSE) -> USNE, USMW & Canada | F4: 45686 | G4: 45687 | H4: 45740 | I4: Irving - Using additives not registered with EPA. | J4: Ops | K4: C023-110-25
A5: Decatur, AL | B5: =VLOOKUP(Table2456[[#This Row],[Location (drop-down)]],'List source'!D$2:E$71,2,FALSE) -> 147 | C5: 004 | D5: ="CAF" & C5 & "-" & B5 & "-" & "25" -> CAF004-147-25 | E5: =VLOOKUP(Table2456[[#This Row],[Location (drop-down)]],Table1[#All],3,FALSE) -> SE & Caribbean | F5: 45708 | G5: 45726 | H5: 45726 | I5: Citgo - Equipment/Probe Checks and In-Transit Difference Comparisons. | J5: Ops | K5: C086-147-25
A6: CORPORATE, NJ | B6: =VLOOKUP(Table2456[[#This Row],[Location (drop-down)]],'List source'!D$2:E$71,2,FALSE) -> 101 | C6: 005 | D6: ="CAF" & C6 & "-" & B6 & "-" & "25" -> CAF005-101-25 | E6: =VLOOKUP(Table2456[[#This Row],[Location (drop-down)]],Table1[#All],3,FALSE) -> Corporate | F6: 45708 | I6: Irving Oil - Inspectors sampler tape and tube fell into vessels tank. | J6: Ops | K6: C087-101-25
A7: San Francisco (Concord), CA | B7: =VLOOKUP(Table2456[[#This Row],[Location (drop-down)]],'List source'!D$2:E$71,2,FALSE) -> 131 | C7: 006 | D7: ="CAF" & C7 & "-" & B7 & "-" & "25" -> CAF006-131-25 | E7: =VLOOKUP(Table2456[[#This Row],[Location (drop-down)]],Table1[#All],3,FALSE) -> USWC | F7: 45708 | G7: 45716 | H7: 45716 | I7: Valero - Cetane Engine Fluctuating Readings and Lack of Action Leading to Client Request for Recheck on Two Samples | J7: Lab | K7: C099-131-25
A8: New Orleans (Destrehan), LA | B8: =VLOOKUP(Table2456[[#This Row],[Location (drop-down)]],'List source'!D$2:E$71,2,FALSE) -> 170 | C8: 007 | D8: ="CAF" & C8 & "-" & B8 & "-" & "25" -> CAF007-170-25 | E8: =VLOOKUP(Table2456[[#This Row],[Location (drop-down)]],Table1[#All],3,FALSE) -> SE & Caribbean | F8: 45723 | G8: 45757 | H8: 45757 | I8: PBF - SimDIst bias result for heavy crude oil. | J8: Lab | K8: C120-170-25
A9: Los Angeles (Signal Hill), CA | B9: =VLOOKUP(Table2456[[#This Row],[Location (drop-down)]],'List source'!D$2:E$71,2,FALSE) -> 130 | C9: 008 | D9: ="CAF" & C9 & "-" & B9 & "-" & "25" -> CAF008-130-25 | E9: =VLOOKUP(Table2456[[#This Row],[Location (drop-down)]],Table1[#All],3,FALSE) -> USWC | F9: 45740 | G9: 45776 | H9: 45776 | I9: PBF - Inspector compiling/providing an incorrect VEF | J9: Ops | K9: C040-130-25
