Workbook

Sheet Assessment '26
A1: Location (drop-down) | B1: Location ID | C1: # | D1: Assessment # | E1: Start Date | F1: End Date | G1: Report Issued | H1: Type of Assessment (drop-down) | I1: Scope of Assessment (drop-down) | J1: QA In Charge (Get a copy of assessment report or summary) | K1: Assessor(s) / Auditor(s) name(s) | L1: Assessor's company | M1: Agency Type (Regulatory / certification / accreditation agency) (drop-down) | N1: Brief description of assessment scope
A2: San Francisco (Concord), CA | B2: =VLOOKUP(Table245[[#This Row],[Location (drop-down)]],'List source'!D$2:E$71,2,FALSE) -> 131 | C2: 001 | D2: ="A" & C2 & "-" & B2 & "-" & "26" -> A001-131-26 | E2: 46027 | F2: 46029 | G2: 46048 | H2: Internal | I2: Inspection & Laboratory | J2: AH | K2: AH/JP | L2: AmSpec | N2: Annual internal quality systems assessment (ISO 9001)
A3: San Francisco (Concord), CA | B3: =VLOOKUP(Table245[[#This Row],[Location (drop-down)]],'List source'!D$2:E$71,2,FALSE) -> 131 | C3: 002 | D3: ="A" & C3 & "-" & B3 & "-" & "26" -> A002-131-26 | E3: 46027 | F3: 46029 | G3: 46048 | H3: Internal | I3: Laboratory | J3: AH | K3: AH/JP | L3: AmSpec | N3: Annual internal quality systems assessment (ISO 17025)
A4: Brownsville, TX | B4: =VLOOKUP(Table245[[#This Row],[Location (drop-down)]],'List source'!D$2:E$71,2,FALSE) -> 158 | C4: 003 | D4: ="A" & C4 & "-" & B4 & "-" & "26" -> A003-158-26 | E4: 46034 | F4: 46037 | G4: 46045 | H4: Internal | I4: Inspection & Laboratory | J4: KA | K4: KA/ECu | L4: AmSpec | N4: Annual internal quality systems assessment (ISO 9001) | O4: Annual internal quality systems assessment (BQ-9000)
A5: Brownsville, TX | B5: =VLOOKUP(Table245[[#This Row],[Location (drop-down)]],'List source'!D$2:E$71,2,FALSE) -> 158 | C5: 004 | D5: ="A" & C5 & "-" & B5 & "-" & "26" -> A004-158-26 | E5: 46034 | F5: 46037 | G5: 46045 | H5: Internal | I5: Laboratory | J5: KA | K5: KA/ECu | L5: AmSpec | N5: Annual internal quality systems assessment (ISO 17025) | O5: A2LA renewal assessment (ISO 17025)
A6: Corpus Christi, TX | B6: =VLOOKUP(Table245[[#This Row],[Location (drop-down)]],'List source'!D$2:E$71,2,FALSE) -> 155 | C6: 005 | D6: ="A" & C6 & "-" & B6 & "-" & "26" -> A005-155-26 | E6: 46041 | F6: 46044 | H6: Internal | I6: Inspection & Laboratory | J6: JP | K6: AH/JP | L6: AmSpec | N6: Annual internal quality systems assessment (ISO 9001)
A7: Corpus Christi, TX | B7: =VLOOKUP(Table245[[#This Row],[Location (drop-down)]],'List source'!D$2:E$71,2,FALSE) -> 155 | C7: 006 | D7: ="A" & C7 & "-" & B7 & "-" & "26" -> A006-155-26 | E7: 46041 | F7: 46044 | H7: Internal | I7: Laboratory | J7: JP | K7: AH/JP | L7: AmSpec | N7: Annual internal quality systems assessment (ISO 17025)
A8: Baton Rouge (Gonzales), LA | B8: =VLOOKUP(Table245[[#This Row],[Location (drop-down)]],'List source'!D$2:E$71,2,FALSE) -> 190 | C8: 007 | D8: ="A" & C8 & "-" & B8 & "-" & "26" -> A007-190-26 | E8: 46049 | F8: 46051 | H8: Internal | I8: Inspection & Laboratory | J8: KA | K8: KA/MT/JP | L8: AmSpec | N8: Annual internal quality systems assessment (ISO 9001)
A9: Baton Rouge (Gonzales), LA | B9: =VLOOKUP(Table245[[#This Row],[Location (drop-down)]],'List source'!D$2:E$71,2,FALSE) -> 190 | C9: 008 | D9: ="A" & C9 & "-" & B9 & "-" & "26" -> A008-190-26 | E9: 46049 | F9: 46051 | H9: Internal | I9: Laboratory | J9: KA | K9: KA/MT/JP | L9: AmSpec | N9: Annual internal quality systems assessment (ISO 17025)
A10: St Croix, USVI | B10: =VLOOKUP(Table245[[#This Row],[Location (drop-down)]],'List source'!D$2:E$71,2,FALSE) -> 210 | C10: 009 | D10: ="A" & C10 & "-" & B10 & "-" & "26" -> A009-210-26 | E10: 46055 | F10: 46059 | H10: Internal | I10: Inspection & Laboratory | J10: AH | K10: AH/JP | L10: AmSpec | N10: Annual internal quality systems assessment (ISO 9001)
A11: St Croix, USVI | B11: =VLOOKUP(Table245[[#This Row],[Location (drop-down)]],'List source'!D$2:E$71,2,FALSE) -> 210 | C11: 010 | D11: ="A" & C11 & "-" & B11 & "-" & "26" -> A010-210-26 | E11: 46055 | F11: 46059 | H11: Internal | I11: Laboratory | J11: AH | K11: AH/JP | L11: AmSpec | N11: Annual internal quality systems assessment (ISO 17025)
A12: Los Angeles (Signal Hill), CA | B12: =VLOOKUP(Table245[[#This Row],[Location (drop-down)]],'List source'!D$2:E$71,2,FALSE) -> 130 | C12: 011 | D12: ="A" & C12 & "-" & B12 & "-" & "26" -> A011-130-26 | E12: 46056 | F12: 46057 | G12: 46057 | H12: Customer | I12: Inspection & Laboratory | J12: HM | K12: Scott Anthony / Craig Hoaglin | L12: Shell | N12: Lab and Ops
A13: HOFTI / Channelview, TX | B13: =VLOOKUP(Table245[[#This Row],[Location (drop-down)]],'List source'!D$2:E$71,2,FALSE) -> 128 | C13: 012 | D13: ="A" & C13 & "-" & B13 & "-" & "26" -> A012-128-26 | E13: 46062 | F13: 46064 | H13: Internal | I13: Inspection & Laboratory | J13: KA | K13: KA | L13: AmSpec | N13: Annual internal quality systems assessment (ISO 9001)
A14: Cincinnati (Erlanger), OH | B14: =VLOOKUP(Table245[[#This Row],[Location (drop-down)]],'List source'!D$2:E$71,2,FALSE) -> 138 | C14: 013 | D14: ="A" & C14 & "-" & B14 & "-" & "26" -> A013-138-26 | E14: 46063 | F14: 46065 | H14: Internal | I14: Inspection & Laboratory | J14: Ecu | K14: Ecu | L14: AmSpec | N14: Annual internal quality systems assessment (ISO 9001)
B15: =VLOOKUP(Table245[[#This Row],[Location (drop-down)]],'List source'!D$2:E$71,2,FALSE) -> #N/A | C15: 014 | D15: ="A" & C15 & "-" & B15 & "-" & "26" -> #N/A
B16: =VLOOKUP(Table245[[#This Row],[Location (drop-down)]],'List source'!D$2:E$71,2,FALSE) -> #N/A | C16: 015 | D16: ="A" & C16 & "-" & B16 & "-" & "26" -> #N/A
B17: =VLOOKUP(Table245[[#This Row],[Location (drop-down)]],'List source'!D$2:E$71,2,FALSE) -> #N/A | C17: 016 | D17: ="A" & C17 & "-" & B17 & "-" & "26" -> #N/A
B18: =VLOOKUP(Table245[[#This Row],[Location (drop-down)]],'List source'!D$2:E$71,2,FALSE) -> #N/A | C18: 017 | D18: ="A" & C18 & "-" & B18 & "-" & "26" -> #N/A
B19: =VLOOKUP(Table245[[#This Row],[Location (drop-down)]],'List source'!D$2:E$71,2,FALSE) -> #N/A | C19: 018 | D19: ="A" & C19 & "-" & B19 & "-" & "26" -> #N/A
B20: =VLOOKUP(Table245[[#This Row],[Location (drop-down)]],'List source'!D$2:E$71,2,FALSE) -> #N/A | C20: 019 | D20: ="A" & C20 & "-" & B20 & "-" & "26" -> #N/A
B21: =VLOOKUP(Table245[[#This Row],[Location (drop-down)]],'List source'!D$2:E$71,2,FALSE) -> #N/A | C21: 020 | D21: ="A" & C21 & "-" & B21 & "-" & "26" -> #N/A
B22: =VLOOKUP(Table245[[#This Row],[Location (drop-down)]],'List source'!D$2:E$71,2,FALSE) -> #N/A | C22: 021 | D22: ="A" & C22 & "-" & B22 & "-" & "26" -> #N/A
B23: =VLOOKUP(Table245[[#This Row],[Location (drop-down)]],'List source'!D$2:E$71,2,FALSE) -> #N/A | C23: 022 | D23: ="A" & C23 & "-" & B23 & "-" & "26" -> #N/A
B24: =VLOOKUP(Table245[[#This Row],[Location (drop-down)]],'List source'!D$2:E$71,2,FALSE) -> #N/A | C24: 023 | D24: ="A" & C24 & "-" & B24 & "-" & "26" -> #N/A
B25: =VLOOKUP(Table245[[#This Row],[Location (drop-down)]],'List source'!D$2:E$71,2,FALSE) -> #N/A | C25: 024 | D25: ="A" & C25 & "-" & B25 & "-" & "26" -> #N/A
B26: =VLOOKUP(Table245[[#This Row],[Location (drop-down)]],'List source'!D$2:E$71,2,FALSE) -> #N/A | C26: 025 | D26: ="A" & C26 & "-" & B26 & "-" & "26" -> #N/A
... B201: =VLOOKUP(Table245[[#This Row],[Location (drop-down)]],'List source'!D$2:E$71,2,FALSE) -> #N/A | C201: 200 | D201: ="A" & C201 & "-" & B201 & "-" & "26" -> #N/A

Sheet CAR '26
A1: Location (drop-down) | B1: Location ID | C1: # | D1: CAR # | E1: CAR Type | F1: ASSOCIATED ORGANIZATION (required for Complaints, Customer audits/alerts, 3rd party audits) | G1: BRIEF DESCRIPTION OF NC if VOID: "VOID, Location, type, details (initials, date)" | H1: Area (Lab, Ops, Misc.) (drop-down) | I1: QA team member initials | J1: CAR initialized date | K1: Action Plan submitted by due date? (Yes/No) | L1: Corrective Action Completion Date | M1: Corrective Action Approved Date | N1: Agreed Actions completed by due date? (Yes/No) | O1: Effectiveness Review Date | P1: Effective? (Yes/No) If no include new CAR # on notes | Q1: Days to Close (Cells in red are not closed) | R1: Notes | S1: Cause (for Assessments only)
A2: Seabrook (Chemicals), TX | B2: =VLOOKUP(Table2[[#This Row],[Location (drop-down)]],'List source'!D$2:E$71,2,FALSE) -> 121 | C2: 022 | D2: ="C" & C2 &"-" & B2 & "-" & "26" -> C022-121-26 | E2: Complaint | G2: Lyondell - Incorrect dose of inhibitor | H2: Operations | I2: HB | J2: 46028 | K2: Yes | L2: 46044 | M2: 46050 | N2: Yes | Q2: =IF(ISBLANK(Table2[[#This Row],[Corrective Action Completion Date]]), TODAY()-Table2[[#This Row],[CAR initialized date]], Table2[[#This Row],[Corrective Action Completion Date]]-Table2[[#This Row],[CAR initialized date]]) -> 16 | R2: CAF006-121-26
A3: San Francisco (Concord), CA | B3: =VLOOKUP(Table2[[#This Row],[Location (drop-down)]],'List source'!D$2:E$71,2,FALSE) -> 131 | C3: 001 | D3: ="C" & C3 &"-" & B3 & "-" & "26" -> C001-131-26 | E3: Complaint | F3: P66 | G3: P66 - Lab failed to timely identify a typo in freeze results despite client requesting recheck. (5 hours delay) | H3: Lab | I3: HM | J3: 46036 | K3: Yes | L3: 46045 | M3: 46048 | N3: Yes | Q3: =IF(ISBLANK(Table2[[#This Row],[Corrective Action Completion Date]]), TODAY()-Table2[[#This Row],[CAR initialized date]], Table2[[#This Row],[Corrective Action Completion Date]]-Table2[[#This Row],[CAR initialized date]]) -> 9 | R3: CAF002-131-26
A4: Los Angeles (Signal Hill), CA | B4: =VLOOKUP(Table2[[#This Row],[Location (drop-down)]],'List source'!D$2:E$71,2,FALSE) -> 130 | C4: 002 | D4: ="C" & C4 &"-" & B4 & "-" & "26" -> C002-130-26 | E4: Complaint | F4: P66 | G4: P66 - Lab incorrectly reported freeze point result | H4: Lab | I4: HM | J4: 46037 | K4: Yes | L4: 46045 | M4: 46048 | N4: Yes | Q4: =IF(ISBLANK(Table2[[#This Row],[Corrective Action Completion Date]]), TODAY()-Table2[[#This Row],[CAR initialized date]], Table2[[#This Row],[Corrective Action Completion Date]]-Table2[[#This Row],[CAR initialized date]]) -> 8 | R4: CAF004-130-26
A5: Port Arthur (Beaumont), TX | B5: =VLOOKUP(Table2[[#This Row],[Location (drop-down)]],'List source'!D$2:E$71,2,FALSE) -> 160 | C5: 003 | D5: ="C" & C5 &"-" & B5 & "-" & "26" -> C003-160-26 | E5: Complaint | F5: ExxonMobil | G5: ExxonMobil - Delay release of barges | H5: Operations | I5: HB | J5: 46042 | Q5: =IF(ISBLANK(Table2[[#This Row],[Corrective Action Completion Date]]), TODAY()-Table2[[#This Row],[CAR initialized date]], Table2[[#This Row],[Corrective Action Completion Date]]-Table2[[#This Row],[CAR initialized date]]) -> 25 | R5: CAF005-160-26
A6: Brownsville, TX | B6: =VLOOKUP(Table2[[#This Row],[Location (drop-down)]],'List source'!D$2:E$71,2,FALSE) -> 158 | C6: 004 | D6: ="C" & C6 &"-" & B6 & "-" & "26" -> C004-158-26 | E6: Internal assessment (9001 & 17025) | G6: Clause 6.2.3 and 6.2.5 | H6: Lab | I6: Ecu | J6: 46045 | Q6: =IF(ISBLANK(Table2[[#This Row],[Corrective Action Completion Date]]), TODAY()-Table2[[#This Row],[CAR initialized date]], Table2[[#This Row],[Corrective Action Completion Date]]-Table2[[#This Row],[CAR initialized date]]) -> 22
A7: Brownsville, TX | B7: =VLOOKUP(Table2[[#This Row],[Location (drop-down)]],'List source'!D$2:E$71,2,FALSE) -> 158 | C7: 005 | D7: ="C" & C7 &"-" & B7 & "-" & "26" -> C005-158-26 | E7: Internal assessment (9001 & 17025) | G7: Clause 6.4.4 and 6.4.5 | H7: Lab | I7: Ecu | J7: 46045 | Q7: =IF(ISBLANK(Table2[[#This Row],[Corrective Action Completion Date]]), TODAY()-Table2[[#This Row],[CAR initialized date]], Table2[[#This Row],[Corrective Action Completion Date]]-Table2[[#This Row],[CAR initialized date]]) -> 22
A8: Brownsville, TX | B8: =VLOOKUP(Table2[[#This Row],[Location (drop-down)]],'List source'!D$2:E$71,2,FALSE) -> 158 | C8: 006 | D8: ="C" & C8 &"-" & B8 & "-" & "26" -> C006-158-26 | E8: Internal assessment (9001 & 17025) | G8: Clause 6.4.10 | H8: Lab | I8: Ecu | J8: 46045 | Q8: =IF(ISBLANK(Table2[[#This Row],[Corrective Action Completion Date]]), TODAY()-Table2[[#This Row],[CAR initialized date]], Table2[[#This Row],[Corrective Action Completion Date]]-Table2[[#This Row],[CAR initialized date]]) -> 22
A9: Brownsville, TX | B9: =VLOOKUP(Table2[[#This Row],[Location (drop-down)]],'List source'!D$2:E$71,2,FALSE) -> 158 | C9: 007 | D9: ="C" & C9 &"-" & B9 & "-" & "26" -> C007-158-26 | E9: Internal assessment (9001 & 17025) | G9: Clause 6.5.2 | H9: Lab | I9: Ecu | J9: 46045 | Q9: =IF(ISBLANK(Table2[[#This Row],[Corrective Action Completion Date]]), TODAY()-Table2[[#This Row],[CAR initialized date]], Table2[[#This Row],[Corrective Action Completion Date]]-Table2[[#This Row],[CAR initialized date]]) -> 22
A10: Brownsville, TX | B10: =VLOOKUP(Table2[[#This Row],[Location (drop-down)]],'List source'!D$2:E$71,2,FALSE) -> 158 | C10: 008 | D10: ="C" & C10 &"-" & B10 & "-" & "26" -> C008-158-26 | E10: Internal assessment (9001 & 17025) | G10: Clause 7.2.1.7 | H10: Lab | I10: Ecu | J10: 46045 | Q10: =IF(ISBLANK(Table2[[#This Row],[Corrective Action Completion Date]]), TODAY()-Table2[[#This Row],[CAR initialized date]], Table2[[#This Row],[Corrective Action Completion Date]]-Table2[[#This Row],[CAR initialized date]]) -> 22
A11: Brownsville, TX | B11: =VLOOKUP(Table2[[#This Row],[Location (drop-down)]],'List source'!D$2:E$71,2,FALSE) -> 158 | C11: 009 | D11: ="C" & C11 &"-" & B11 & "-" & "26" -> C009-158-26 | E11: Internal assessment (9001 & 17025) | G11: Clause 7.4.2 | H11: Lab | I11: Ecu | J11: 46045 | Q11: =IF(ISBLANK(Table2[[#This Row],[Corrective Action Completion Date]]), TODAY()-Table2[[#This Row],[CAR initialized date]], Table2[[#This Row],[Corrective Action Completion Date]]-Table2[[#This Row],[CAR initialized date]]) -> 22
A12: Brownsville, TX | B12: =VLOOKUP(Table2[[#This Row],[Location (drop-down)]],'List source'!D$2:E$71,2,FALSE) -> 158 | C12: 010 | D12: ="C" & C12 &"-" & B12 & "-" & "26" -> C010-158-26 | E12: Internal assessment (9001 & 17025) | G12: Clause 7.5.1 | H12: Lab | I12: Ecu | J12: 46045 | Q12: =IF(ISBLANK(Table2[[#This Row],[Corrective Action Completion Date]]), TODAY()-Table2[[#This Row],[CAR initialized date]], Table2[[#This Row],[Corrective Action Completion Date]]-Table2[[#This Row],[CAR initialized date]]) -> 22
A13: Brownsville, TX | B13: =VLOOKUP(Table2[[#This Row],[Location (drop-down)]],'List source'!D$2:E$71,2,FALSE) -> 158 | C13: 011 | D13: ="C" & C13 &"-" & B13 & "-" & "26" -> C011-158-26 | E13: Internal assessment (9001 & 17025) | G13: Clause 7.8.1.2 | H13: Lab | I13: Ecu | J13: 46045 | Q13: =IF(ISBLANK(Table2[[#This Row],[Corrective Action Completion Date]]), TODAY()-Table2[[#This Row],[CAR initialized date]], Table2[[#This Row],[Corrective Action Completion Date]]-Table2[[#This Row],[CAR initialized date]]) -> 22
A14: Brownsville, TX | B14: =VLOOKUP(Table2[[#This Row],[Location (drop-down)]],'List source'!D$2:E$71,2,FALSE) -> 158 | C14: 012 | D14: ="C" & C14 &"-" & B14 & "-" & "26" -> C012-158-26 | E14: Internal assessment (9001 & 17025) | G14: Clause 8.3.2f and QSM Section 22 | H14: Lab & Ops | I14: Ecu | J14: 46045 | Q14: =IF(ISBLANK(Table2[[#This Row],[Corrective Action Completion Date]]), TODAY()-Table2[[#This Row],[CAR initialized date]], Table2[[#This Row],[Corrective Action Completion Date]]-Table2[[#This Row],[CAR initialized date]]) -> 22
A15: San Francisco (Concord), CA | B15: =VLOOKUP(Table2[[#This Row],[Location (drop-down)]],'List source'!D$2:E$71,2,FALSE) -> 131 | C15: 013 | D15: ="C" & C15 &"-" & B15 & "-" & "26" -> C013-131-26 | E15: Internal assessment (9001 & 17025) | G15: QB-00019A | H15: Operations | I15: AH | J15: 46048 | Q15: =IF(ISBLANK(Table2[[#This Row],[Corrective Action Completion Date]]), TODAY()-Table2[[#This Row],[CAR initialized date]], Table2[[#This Row],[Corrective Action Completion Date]]-Table2[[#This Row],[CAR initialized date]]) -> 19
A16: San Francisco (Concord), CA | B16: =VLOOKUP(Table2[[#This Row],[Location (drop-down)]],'List source'!D$2:E$71,2,FALSE) -> 131 | C16: 014 | D16: ="C" & C16 &"-" & B16 & "-" & "26" -> C014-131-26 | E16: Internal assessment (9001 & 17025) | G16: QSM S27.3.e.i | H16: Operations | I16: AH | J16: 46048 | Q16: =IF(ISBLANK(Table2[[#This Row],[Corrective Action Completion Date]]), TODAY()-Table2[[#This Row],[CAR initialized date]], Table2[[#This Row],[Corrective Action Completion Date]]-Table2[[#This Row],[CAR initialized date]]) -> 19
A17: San Francisco (Concord), CA | B17: =VLOOKUP(Table2[[#This Row],[Location (drop-down)]],'List source'!D$2:E$71,2,FALSE) -> 131 | C17: 015 | D17: ="C" & C17 &"-" & B17 & "-" & "26" -> C015-131-26 | E17: Internal assessment (9001 & 17025) | G17: QSM S28.5 | H17: Operations | I17: AH | J17: 46048 | Q17: =IF(ISBLANK(Table2[[#This Row],[Corrective Action Completion Date]]), TODAY()-Table2[[#This Row],[CAR initialized date]], Table2[[#This Row],[Corrective Action Completion Date]]-Table2[[#This Row],[CAR initialized date]]) -> 19
... A23: San Francisco (Concord), CA | B23: =VLOOKUP(Table2[[#This Row],[Location (drop-down)]],'List source'!D$2:E$71,2,FALSE) -> 131 | C23: 021 | D23: ="C" & C23 &"-" & B23 & "-" & "26" -> C021-131-26 | E23: Internal assessment (9001 & 17025) | G23: ISO 17025 Clause 7.5 | H23: Lab | I23: AH | J23: 46048 | Q23: =IF(ISBLANK(Table2[[#This Row],[Corrective Action Completion Date]]), TODAY()-Table2[[#This Row],[CAR initialized date]], Table2[[#This Row],[Corrective Action Completion Date]]-Table2[[#This Row],[CAR initialized date]]) -> 19
A24: San Francisco (Concord), CA | B24: =VLOOKUP(Table2[[#This Row],[Location (drop-down)]],'List source'!D$2:E$71,2,FALSE) -> 131 | C24: 023 | D24: ="C" & C24 &"-" & B24 & "-" & "26" -> C023-131-26 | E24: Complaint | F24: PBF | G24: Wrong sampler tube used affecting water content results (Repeat) | H24: Operations | I24: HM | J24: 46052 | Q24: =IF(ISBLANK(Table2[[#This Row],[Corrective Action Completion Date]]), TODAY()-Table2[[#This Row],[CAR initialized date]], Table2[[#This Row],[Corrective Action Completion Date]]-Table2[[#This Row],[CAR initialized date]]) -> 15 | R24: CAF007-131-26, repeat of C162-131-25
A25: Los Angeles (Signal Hill), CA | B25: =VLOOKUP(Table2[[#This Row],[Location (drop-down)]],'List source'!D$2:E$71,2,FALSE) -> 130 | C25: 024 | D25: ="C" & C25 &"-" & B25 & "-" & "26" -> C024-130-26 | E25: Customer audit | G25: Shell - SQC - No procedure provided covering the validation of released data between in-control and out of control Accuracy/Precision charts. | H25: Lab | I25: HM | J25: 46057 | Q25: =IF(ISBLANK(Table2[[#This Row],[Corrective Action Completion Date]]), TODAY()-Table2[[#This Row],[CAR initialized date]], Table2[[#This Row],[Corrective Action Completion Date]]-Table2[[#This Row],[CAR initialized date]]) -> 10 | R25: A011-130-26
A26: Los Angeles (Signal Hill), CA | B26: =VLOOKUP(Table2[[#This Row],[Location (drop-down)]],'List source'!D$2:E$71,2,FALSE) -> 130 | C26: 025 | D26: ="C" & C26 &"-" & B26 & "-" & "26" -> C025-130-26 | E26: Customer audit | G26: Shell - Proficiency Testing Zscore monitoring, Site has 10 Site has 10, 3 Z-Score failures in the ASTM RFG program for 2025. | H26: Lab | I26: HM | J26: 46057 | Q26: =IF(ISBLANK(Table2[[#This Row],[Corrective Action Completion Date]]), TODAY()-Table2[[#This Row],[CAR initialized date]], Table2[[#This Row],[Corrective Action Completion Date]]-Table2[[#This Row],[CAR initialized date]]) -> 10 | R26: A011-130-26
A27: Los Angeles (Signal Hill), CA | B27: =VLOOKUP(Table2[[#This Row],[Location (drop-down)]],'List source'!D$2:E$71,2,FALSE) -> 130 | C27: 026 | D27: ="C" & C27 &"-" & B27 & "-" & "26" -> C026-130-26 | E27: Customer audit | G27: Shell - Specification Management - Spec limit missing, tests substituted with no documentation, and incompatible spec on CoA. | H27: Lab | I27: HM | J27: 46057 | Q27: =IF(ISBLANK(Table2[[#This Row],[Corrective Action Completion Date]]), TODAY()-Table2[[#This Row],[CAR initialized date]], Table2[[#This Row],[Corrective Action Completion Date]]-Table2[[#This Row],[CAR initialized date]]) -> 10 | R27: A011-130-26
A28: Los Angeles (Signal Hill), CA | B28: =VLOOKUP(Table2[[#This Row],[Location (drop-down)]],'List source'!D$2:E$71,2,FALSE) -> 130 | C28: 027 | D28: ="C" & C28 &"-" & B28 & "-" & "26" -> C027-130-26 | E28: Customer audit | G28: Shell - Training and Competence -Training is not well documented. | H28: Lab | I28: HM | J28: 46057 | Q28: =IF(ISBLANK(Table2[[#This Row],[Corrective Action Completion Date]]), TODAY()-Table2[[#This Row],[CAR initialized date]], Table2[[#This Row],[Corrective Action Completion Date]]-Table2[[#This Row],[CAR initialized date]]) -> 10 | R28: A011-130-26
A29: Los Angeles (Signal Hill), CA | B29: =VLOOKUP(Table2[[#This Row],[Location (drop-down)]],'List source'!D$2:E$71,2,FALSE) -> 130 | C29: 028 | D29: ="C" & C29 &"-" & B29 & "-" & "26" -> C028-130-26 | E29: Customer audit | G29: Shell - Technical records D86, D5580, D5453, D4815, D5769 corr. | H29: Lab | I29: HM | J29: 46057 | Q29: =IF(ISBLANK(Table2[[#This Row],[Corrective Action Completion Date]]), TODAY()-Table2[[#This Row],[CAR initialized date]], Table2[[#This Row],[Corrective Action Completion Date]]-Table2[[#This Row],[CAR initialized date]]) -> 10 | R29: A011-130-26
A30: Los Angeles (Signal Hill), CA | B30: =VLOOKUP(Table2[[#This Row],[Location (drop-down)]],'List source'!D$2:E$71,2,FALSE) -> 130 | C30: 029 | D30: ="C" & C30 &"-" & B30 & "-" & "26" -> C029-130-26 | E30: Customer audit | G30: Shell - Job file review - No EPA Homogeneity sheet in the file | H30: Lab | I30: HM | J30: 46057 | Q30: =IF(ISBLANK(Table2[[#This Row],[Corrective Action Completion Date]]), TODAY()-Table2[[#This Row],[CAR initialized date]], Table2[[#This Row],[Corrective Action Completion Date]]-Table2[[#This Row],[CAR initialized date]]) -> 10 | R30: A011-130-26
A31: Los Angeles (Signal Hill), CA | B31: =VLOOKUP(Table2[[#This Row],[Location (drop-down)]],'List source'!D$2:E$71,2,FALSE) -> 130 | C31: 030 | D31: ="C" & C31 &"-" & B31 & "-" & "26" -> C030-130-26 | E31: Customer audit | G31: Shell - Sampling and sample management - Inspector sampling witnessing | H31: Lab | I31: HM | J31: 46057 | Q31: =IF(ISBLANK(Table2[[#This Row],[Corrective Action Completion Date]]), TODAY()-Table2[[#This Row],[CAR initialized date]], Table2[[#This Row],[Corrective Action Completion Date]]-Table2[[#This Row],[CAR initialized date]]) -> 10 | R31: A011-130-26
A32: New Orleans (Destrehan), LA | B32: =VLOOKUP(Table2[[#This Row],[Location (drop-down)]],'List source'!D$2:E$71,2,FALSE) -> 170 | C32: 031 | D32: ="C" & C32 &"-" & B32 & "-" & "26" -> C031-170-26 | E32: Complaint | G32: PBF - Wrong submitted sample | H32: Lab | I32: DA | J32: 46062 | Q32: =IF(ISBLANK(Table2[[#This Row],[Corrective Action Completion Date]]), TODAY()-Table2[[#This Row],[CAR initialized date]], Table2[[#This Row],[Corrective Action Completion Date]]-Table2[[#This Row],[CAR initialized date]]) -> 5
A33: New Orleans (Destrehan), LA | B33: =VLOOKUP(Table2[[#This Row],[Location (drop-down)]],'List source'!D$2:E$71,2,FALSE) -> 170 | C33: 032 | D33: ="C" & C33 &"-" & B33 & "-" & "26" -> C032-170-26 | E33: Complaint | G33: PBF - Transcription error | H33: Lab | I33: DA | J33: 46062 | Q33: =IF(ISBLANK(Table2[[#This Row],[Corrective Action Completion Date]]), TODAY()-Table2[[#This Row],[CAR initialized date]], Table2[[#This Row],[Corrective Action Completion Date]]-Table2[[#This Row],[CAR initialized date]]) -> 5
A34: New Orleans (Destrehan), LA | B34: =VLOOKUP(Table2[[#This Row],[Location (drop-down)]],'List source'!D$2:E$71,2,FALSE) -> 170 | C34: 033 | D34: ="C" & C34 &"-" & B34 & "-" & "26" -> C033-170-26 | E34: Complaint | G34: PBF - Difference in reporting | H34: Lab | I34: DA | J34: 46062 | Q34: =IF(ISBLANK(Table2[[#This Row],[Corrective Action Completion Date]]), TODAY()-Table2[[#This Row],[CAR initialized date]], Table2[[#This Row],[Corrective Action Completion Date]]-Table2[[#This Row],[CAR initialized date]]) -> 5
A35: St John, NB | B35: =VLOOKUP(Table2[[#This Row],[Location (drop-down)]],'List source'!D$2:E$71,2,FALSE) -> 199 | C35: 034 | D35: ="C" & C35 &"-" & B35 & "-" & "26" -> C034-199-26 | E35: Complaint | G35: Wrong tank samples on vessel | H35: Operations | I35: GF | J35: 46064 | Q35: =IF(ISBLANK(Table2[[#This Row],[Corrective Action Completion Date]]), TODAY()-Table2[[#This Row],[CAR initialized date]], Table2[[#This Row],[Corrective Action Completion Date]]-Table2[[#This Row],[CAR initialized date]]) -> 3
A36: St John, NB | B36: =VLOOKUP(Table2[[#This Row],[Location (drop-down)]],'List source'!D$2:E$71,2,FALSE) -> 199 | C36: 035 | D36: ="C" & C36 &"-" & B36 & "-" & "26" -> C035-199-26 | E36: Complaint | G36: Inspector did not sample crude oil tanks on open guage | H36: Operations | I36: GF | J36: 46064 | Q36: =IF(ISBLANK(Table2[[#This Row],[Corrective Action Completion Date]]), TODAY()-Table2[[#This Row],[CAR initialized date]], Table2[[#This Row],[Corrective Action Completion Date]]-Table2[[#This Row],[CAR initialized date]]) -> 3
A37: Los Angeles (Signal Hill), CA | B37: =VLOOKUP(Table2[[#This Row],[Location (drop-down)]],'List source'!D$2:E$71,2,FALSE) -> 130 | C37: 036 | D37: ="C" & C37 &"-" & B37 & "-" & "26" -> C036-130-26 | E37: Complaint | G37: PBF - D445 and D4052 discrepancy between ST and VTC results | H37: Lab & Ops | I37: HM | J37: 46062 | Q37: =IF(ISBLANK(Table2[[#This Row],[Corrective Action Completion Date]]), TODAY()-Table2[[#This Row],[CAR initialized date]], Table2[[#This Row],[Corrective Action Completion Date]]-Table2[[#This Row],[CAR initialized date]]) -> 5
A38: San Francisco (Concord), CA | B38: =VLOOKUP(Table2[[#This Row],[Location (drop-down)]],'List source'!D$2:E$71,2,FALSE) -> 131 | C38: 037 | D38: ="C" & C38 &"-" & B38 & "-" & "26" -> C037-131-26 | E38: Complaint | G38: Chevron - Quantity deviation from nomination not communicated to client until report was issued | H38: Operations | I38: HM | J38: 46063 | Q38: =IF(ISBLANK(Table2[[#This Row],[Corrective Action Completion Date]]), TODAY()-Table2[[#This Row],[CAR initialized date]], Table2[[#This Row],[Corrective Action Completion Date]]-Table2[[#This Row],[CAR initialized date]]) -> 4
B39: =VLOOKUP(Table2[[#This Row],[Location (drop-down)]],'List source'!D$2:E$71,2,FALSE) -> #N/A | C39: 038 | D39: ="C" & C39 &"-" & B39 & "-" & "26" -> #N/A | Q39: =IF(ISBLANK(Table2[[#This Row],[Corrective Action Completion Date]]), TODAY()-Table2[[#This Row],[CAR initialized date]], Table2[[#This Row],[Corrective Action Completion Date]]-Table2[[#This Row],[CAR initialized date]]) -> 46067
B40: =VLOOKUP(Table2[[#This Row],[Location (drop-down)]],'List source'!D$2:E$71,2,FALSE) -> #N/A | C40: 039 | D40: ="C" & C40 &"-" & B40 & "-" & "26" -> #N/A | Q40: =IF(ISBLANK(Table2[[#This Row],[Corrective Action Completion Date]]), TODAY()-Table2[[#This Row],[CAR initialized date]], Table2[[#This Row],[Corrective Action Completion Date]]-Table2[[#This Row],[CAR initialized date]]) -> 46067
B41: =VLOOKUP(Table2[[#This Row],[Location (drop-down)]],'List source'!D$2:E$71,2,FALSE) -> #N/A | C41: 040 | D41: ="C" & C41 &"-" & B41 & "-" & "26" -> #N/A | Q41: =IF(ISBLANK(Table2[[#This Row],[Corrective Action Completion Date]]), TODAY()-Table2[[#This Row],[CAR initialized date]], Table2[[#This Row],[Corrective Action Completion Date]]-Table2[[#This Row],[CAR initialized date]]) -> 46067
B42: =VLOOKUP(Table2[[#This Row],[Location (drop-down)]],'List source'!D$2:E$71,2,FALSE) -> #N/A | C42: 041 | D42: ="C" & C42 &"-" & B42 & "-" & "26" -> #N/A | Q42: =IF(ISBLANK(Table2[[#This Row],[Corrective Action Completion Date]]), TODAY()-Table2[[#This Row],[CAR initialized date]], Table2[[#This Row],[Corrective Action Completion Date]]-Table2[[#This Row],[CAR initialized date]]) -> 46067
B43: =VLOOKUP(Table2[[#This Row],[Location (drop-down)]],'List source'!D$2:E$71,2,FALSE) -> #N/A | C43: 042 | D43: ="C" & C43 &"-" & B43 & "-" & "26" -> #N/A | Q43: =IF(ISBLANK(Table2[[#This Row],[Corrective Action Completion Date]]), TODAY()-Table2[[#This Row],[CAR initialized date]], Table2[[#This Row],[Corrective Action Completion Date]]-Table2[[#This Row],[CAR initialized date]]) -> 46067
B44: =VLOOKUP(Table2[[#This Row],[Location (drop-down)]],'List source'!D$2:E$71,2,FALSE) -> #N/A | C44: 043 | D44: ="C" & C44 &"-" & B44 & "-" & "26" -> #N/A | Q44: =IF(ISBLANK(Table2[[#This Row],[Corrective Action Completion Date]]), TODAY()-Table2[[#This Row],[CAR initialized date]], Table2[[#This Row],[Corrective Action Completion Date]]-Table2[[#This Row],[CAR initialized date]]) -> 46067
B45: =VLOOKUP(Table2[[#This Row],[Location (drop-down)]],'List source'!D$2:E$71,2,FALSE) -> #N/A | C45: 044 | D45: ="C" & C45 &"-" & B45 & "-" & "26" -> #N/A | Q45: =IF(ISBLANK(Table2[[#This Row],[Corrective Action Completion Date]]), TODAY()-Table2[[#This Row],[CAR initialized date]], Table2[[#This Row],[Corrective Action Completion Date]]-Table2[[#This Row],[CAR initialized date]]) -> 46067
...

Sheet PAR '26
A1: Location (drop-down) | B1: Location ID | C1: # | D1: PAR # | E1: PAR type | F1: BRIEF DESCRIPTION OF PAR if VOID: Location, type, details (initials, date) | G1: PAR initialized date | H1: QA team member initials | I1: Date closed | J1: Area (Ops, Lab, Misc.) (drop-down) | K1: Notes
A2: Texas City, TX | B2: =VLOOKUP(Table24[[#This Row],[Location (drop-down)]],'List source'!D$2:E$71,2,FALSE) -> 150 | C2: 001 | D2: ="P" & C2 & "-" & B2 & "-" & "26" -> P001-150-26 | E2: Complaint | F2: Weather delayed sample transport, and the updated status was not communicated to ATA in real time during a critical decision window. | G2: 46062 | H2: HB | I2: 46064 | J2: Operations | K2: CAF008-150-26
B3: =VLOOKUP(Table24[[#This Row],[Location (drop-down)]],'List source'!D$2:E$71,2,FALSE) -> #N/A | C3: 002 | D3: ="P" & C3 & "-" & B3 & "-" & "26" -> #N/A
B4: =VLOOKUP(Table24[[#This Row],[Location (drop-down)]],'List source'!D$2:E$71,2,FALSE) -> #N/A | C4: 003 | D4: ="P" & C4 & "-" & B4 & "-" & "26" -> #N/A
B5: =VLOOKUP(Table24[[#This Row],[Location (drop-down)]],'List source'!D$2:E$71,2,FALSE) -> #N/A | C5: 004 | D5: ="P" & C5 & "-" & B5 & "-" & "26" -> #N/A
B6: =VLOOKUP(Table24[[#This Row],[Location (drop-down)]],'List source'!D$2:E$71,2,FALSE) -> #N/A | C6: 005 | D6: ="P" & C6 & "-" & B6 & "-" & "26" -> #N/A
B7: =VLOOKUP(Table24[[#This Row],[Location (drop-down)]],'List source'!D$2:E$71,2,FALSE) -> #N/A | C7: 006 | D7: ="P" & C7 & "-" & B7 & "-" & "26" -> #N/A
B8: =VLOOKUP(Table24[[#This Row],[Location (drop-down)]],'List source'!D$2:E$71,2,FALSE) -> #N/A | C8: 007 | D8: ="P" & C8 & "-" & B8 & "-" & "26" -> #N/A
B9: =VLOOKUP(Table24[[#This Row],[Location (drop-down)]],'List source'!D$2:E$71,2,FALSE) -> #N/A | C9: 008 | D9: ="P" & C9 & "-" & B9 & "-" & "26" -> #N/A
B10: =VLOOKUP(Table24[[#This Row],[Location (drop-down)]],'List source'!D$2:E$71,2,FALSE) -> #N/A | C10: 009 | D10: ="P" & C10 & "-" & B10 & "-" & "26" -> #N/A
B11: =VLOOKUP(Table24[[#This Row],[Location (drop-down)]],'List source'!D$2:E$71,2,FALSE) -> #N/A | C11: 010 | D11: ="P" & C11 & "-" & B11 & "-" & "26" -> #N/A
B12: =VLOOKUP(Table24[[#This Row],[Location (drop-down)]],'List source'!D$2:E$71,2,FALSE) -> #N/A | C12: 011 | D12: ="P" & C12 & "-" & B12 & "-" & "26" -> #N/A
B13: =VLOOKUP(Table24[[#This Row],[Location (drop-down)]],'List source'!D$2:E$71,2,FALSE) -> #N/A | C13: 012 | D13: ="P" & C13 & "-" & B13 & "-" & "26" -> #N/A
B14: =VLOOKUP(Table24[[#This Row],[Location (drop-down)]],'List source'!D$2:E$71,2,FALSE) -> #N/A | C14: 013 | D14: ="P" & C14 & "-" & B14 & "-" & "26" -> #N/A
... B501: =VLOOKUP(Table24[[#This Row],[Location (drop-down)]],'List source'!D$2:E$71,2,FALSE) -> #N/A | C501: 500 | D501: ="P" & C501 & "-" & B501 & "-" & "26" -> #N/A

Sheet List source
A1: Types of Deficiency | B1: Types of Root Cause | C1: CAR / PAR Area | D1: Location | E1: Location ID | F1: Area
A2: Equipment & Reagent status | B2: Communication | C2: Lab | D2: A&B Labs - Baton Rouge, LA | E2: A&B-BR | I2: Yes
A3: Management (CQI, Quality Policy posting, PO, AVL, CAR/PAR) | B3: Equipment/ calibration | C3: Operations | D3: A&B Labs - Houston, TX | E3: A&B-HOU | I3: No
A4: PT | B4: Ineffective/ Lack system/ procedure | C4: Lab & Ops | D4: A&B Labs - Nederland, TX | E4: A&B-NED
A5: Safety | B5: Negligence (typo, no review) | C5: Misc | D5: A&B Labs - Tempe, AZ | E5: A&B-TEM
A6: Technical (Calibration/ Verification/ Maintenance/ PT/ method deviation) | B6: Normal statistics variance - no CA | C6: VOID | D6: AGRI (HTC) | E6: 119 | F6: USGC
A7: Traceability and records (SR-1, raw data) | B7: Training/ competency | D7: Albany, NY | E7: 111 | F7: USNE, USMW & Canada
A8: Training (include quality, safety, ethics) | B8: Unmanaged risks | D8: Avenel (NYH), NJ | E8: 110 | F8: USNE, USMW & Canada
A9: VOID | B9: VOID | D9: Bahamas (Freeport), GBI | E9: 215 | F9: SE & Caribbean
D10: Baltimore (Glen Burnie), MD | E10: 195 | F10: SE & Caribbean
B11: Cause of NC | D11: Baton Rouge (Gonzales), LA | E11: 190 | F11: SE & Caribbean
B12: People (miscommunication, complacency, competency) | D12: Baytown, TX | E12: 161 | F12: USGC
A13: CAR Type | B13: Equipment (malfunction, maintenance, calibration/verification, incorrect setting) | D13: Belle Chasse, LA | E13: 116 | F13: SE & Caribbean
A14: Complaint | B14: Methods (Inadequate / Deviation from Procedures) | D14: Bellingham (Ferndale), WA | E14: 132 | F14: USWC
A15: Customer audit | B15: Management (Lack of accountability, inadequate risk assessment) | D15: Bostco, TX | E15: 124 | F15: USGC
A16: 3rd party audit (DNV, A2LA, AASHTO…) | B16: Environment (Poor housekeeping, insufficient space, clutter) | D16: Boston (Everett), MA | E16: 141 | F16: USNE, USMW & Canada
A17: Internal assessment (9001 & 17025) | C17: CAF Area | D17: Brownsville, TX | E17: 158 | F17: USGC
A18: Other (QC, customer alert, improper procedure) | C18: Lab | D18: Cape Canaveral, FL | E18: 127 | F18: SE & Caribbean
A19: VOID | C19: Ops | D19: Chicago, IL | E19: 136 | F19: SE & Caribbean
C20: Lab & Ops | D20: Cincinnati (Erlanger), OH | E20: 138 | F20: SE & Caribbean
B21: Scope (assessment tracking) | C21: Admin | D21: Collins (Purvis), MS | E21: 115 | F21: SE & Caribbean
B22: Inspection | C22: Other | D22: CORPORATE, NJ | E22: 101 | F22: Corporate
B23: Laboratory | C23: VOID | D23: Corpus Christi, TX | E23: 155 | F23: USGC
A24: Type of Assessment (Assessment tracking) | B24: Inspection & Laboratory | D24: Corpus Christi, TX (CITGO Lab) | E24: 154 | F24: USGC
A25: Internal | B25: VOID | D25: Cushing, OK | E25: 159 | F25: USGC
A26: Customer | D26: Decatur, AL | E26: 147 | F26: SE & Caribbean
A27: Certifications | D27: Freeport, TX | E27: 157 | F27: USGC
A28: Regulatory | D28: Ft Lauderdale (Davie), FL | E28: 125 | F28: SE & Caribbean
A29: VOID | D29: Halifax (Dartmouth), NS | E29: 198 | F29: USNE, USMW & Canada
D30: Hamilton (Burlington), ON | E30: 189 | F30: USNE, USMW & Canada
A31: Agency type (Assessment Tracking) | D31: HOFTI / Channelview, TX | E31: 128 | F31: USGC
A32: Regulatory | D32: Houston (HTC), TX | E32: 120 | F32: USGC
A33: Certifications | D33: HST Weights & Measures | E33: 120W | F33: Calibration
A34: Accredited agency | D34: Ingleside, TX | E34: 155A | F34: USGC
A35: VOID | D35: Kenai, AK | E35: 133 | F35: USWC
D36: Lake Charles (Sulfur), LA | E36: 165 | F36: USGC
D37: Levis (Quebec City), Quebec | E37: 194 | F37: USNE, USMW & Canada
D38: Los Angeles (Signal Hill), CA | E38: 130 | F38: USWC
D39: Marcus Hook, PA | E39: 179 | F39: SE & Caribbean
D40: Memphis, TN | E40: 191 | F40: SE & Caribbean
...

Sheet CAF '26
A1: Location (drop-down) | B1: Location ID | C1: # | D1: CAF# | E1: Area | F1: Date initiated | G1: Date shared w/ customer | H1: Corrective Action completed, CAR approved. | I1: Brief description of complaint | J1: Area (Lab, Ops, Lab & Ops, Admin, Other, Void) (drop-down) | K1: CAR / PAR # (if applicable) | L1: Notes
A2: Houston (HTC), TX | B2: =VLOOKUP(Table2456[[#This Row],[Location (drop-down)]],'List source'!D$2:E$71,2,FALSE) -> 120 | C2: 001 | D2: ="CAF" & C2 & "-" & B2 & "-" & "26" -> CAF001-120-26 | E2: =VLOOKUP(Table2456[[#This Row],[Location (drop-down)]],Table1[#All],3,FALSE) -> USGC | F2: 46034 | I2: Irving Complaint - Not gauged to mm and missed temperature measurement. | J2: Ops | K2: CAPA0015-120-26
A3: San Francisco (Concord), CA | B3: =VLOOKUP(Table2456[[#This Row],[Location (drop-down)]],'List source'!D$2:E$71,2,FALSE) -> 131 | C3: 002 | D3: ="CAF" & C3 & "-" & B3 & "-" & "26" -> CAF002-131-26 | E3: =VLOOKUP(Table2456[[#This Row],[Location (drop-down)]],Table1[#All],3,FALSE) -> USWC | F3: 46036 | H3: 46048 | I3: P66 - Lab failed to timely identify a typo in freeze results despite client requesting recheck. (5 hours delay) | J3: Lab | K3: C001-131-26
A4: VOIDED ASSMT/CAR/PAR NO | B4: =VLOOKUP(Table2456[[#This Row],[Location (drop-down)]],'List source'!D$2:E$71,2,FALSE) -> VOID | C4: 003 | D4: ="CAF" & C4 & "-" & B4 & "-" & "26" -> CAF003-VOID-26 | E4: =VLOOKUP(Table2456[[#This Row],[Location (drop-down)]],Table1[#All],3,FALSE) -> VOID | F4: void | G4: void | H4: void | I4: voided | J4: VOID | K4: void | L4: repeat of CAF 001
A5: Los Angeles (Signal Hill), CA | B5: =VLOOKUP(Table2456[[#This Row],[Location (drop-down)]],'List source'!D$2:E$71,2,FALSE) -> 130 | C5: 004 | D5: ="CAF" & C5 & "-" & B5 & "-" & "26" -> CAF004-130-26 | E5: =VLOOKUP(Table2456[[#This Row],[Location (drop-down)]],Table1[#All],3,FALSE) -> USWC | F5: 46037 | H5: 46048 | I5: P66- incorrectly reported freeze point | J5: Lab | K5: C002-130-26
A6: Port Arthur (Beaumont), TX | B6: =VLOOKUP(Table2456[[#This Row],[Location (drop-down)]],'List source'!D$2:E$71,2,FALSE) -> 160 | C6: 005 | D6: ="CAF" & C6 & "-" & B6 & "-" & "26" -> CAF005-160-26 | E6: =VLOOKUP(Table2456[[#This Row],[Location (drop-down)]],Table1[#All],3,FALSE) -> USGC | F6: 46042 | I6: ExxonMobil - Delay release of barges | J6: Ops | K6: C003-160-26
A7: Seabrook (Chemicals), TX | B7: =VLOOKUP(Table2456[[#This Row],[Location (drop-down)]],'List source'!D$2:E$71,2,FALSE) -> 121 | C7: 006 | D7: ="CAF" & C7 & "-" & B7 & "-" & "26" -> CAF006-121-26 | E7: =VLOOKUP(Table2456[[#This Row],[Location (drop-down)]],Table1[#All],3,FALSE) -> USGC | F7: 46028 | G7: 46050 | H7: 46050 | I7: Lyondell - Incorrect dose of inhibitor | J7: Ops | K7: C022-121-26
A8: San Francisco (Concord), CA | B8: =VLOOKUP(Table2456[[#This Row],[Location (drop-down)]],'List source'!D$2:E$71,2,FALSE) -> 131 | C8: 007 | D8: ="CAF" & C8 & "-" & B8 & "-" & "26" -> CAF007-131-26 | E8: =VLOOKUP(Table2456[[#This Row],[Location (drop-down)]],Table1[#All],3,FALSE) -> USWC | F8: 46052 | I8: PBF -Wrong sampler tube used affecting water content results (Repeat) | J8: Ops | K8: C023-131-26
A9: Texas City, TX | B9: =VLOOKUP(Table2456[[#This Row],[Location (drop-down)]],'List source'!D$2:E$71,2,FALSE) -> 150 | C9: 008 | D9: ="CAF" & C9 & "-" & B9 & "-" & "26" -> CAF008-150-26 | E9: =VLOOKUP(Table2456[[#This Row],[Location (drop-down)]],Table1[#All],3,FALSE) -> USGC | F9: 46062 | H9: 46064 | I9: Weather delayed sample transport, and the updated status was not communicated to ATA in real time during a critical decision window. | J9: Ops | K9: P001-150-26
A10: New Orleans (Destrehan), LA | B10: =VLOOKUP(Table2456[[#This Row],[Location (drop-down)]],'List source'!D$2:E$71,2,FALSE) -> 170 | C10: 009 | D10: ="CAF" & C10 & "-" & B10 & "-" & "26" -> CAF009-170-26 | E10: =VLOOKUP(Table2456[[#This Row],[Location (drop-down)]],Table1[#All],3,FALSE) -> SE & Caribbean | F10: 46062 | I10: PBF Blue Wing/Kirby 28081 - Discrepancies in reporting results, wrong submitted sample for ICP | J10: Lab
A11: St John, NB | B11: =VLOOKUP(Table2456[[#This Row],[Location (drop-down)]],'List source'!D$2:E$71,2,FALSE) -> 199 | C11: 010 | D11: ="CAF" & C11 & "-" & B11 & "-" & "26" -> CAF010-199-26 | E11: =VLOOKUP(Table2456[[#This Row],[Location (drop-down)]],Table1[#All],3,FALSE) -> USNE, USMW & Canada | F11: 46064 | I11: Wrong tank samples on vessel | J11: Ops | K11: C034-199-26
A12: St John, NB | B12: =VLOOKUP(Table2456[[#This Row],[Location (drop-down)]],'List source'!D$2:E$71,2,FALSE) -> 199 | C12: 011 | D12: ="CAF" & C12 & "-" & B12 & "-" & "26" -> CAF011-199-26 | E12: =VLOOKUP(Table2456[[#This Row],[Location (drop-down)]],Table1[#All],3,FALSE) -> USNE, USMW & Canada | F12: 46064 | I12: Crude oil tank not sampled on open gauging | J12: Ops | K12: C035-199-26
A13: Los Angeles (Signal Hill), CA | B13: =VLOOKUP(Table2456[[#This Row],[Location (drop-down)]],'List source'!D$2:E$71,2,FALSE) -> 130 | C13: 012 | D13: ="CAF" & C13 & "-" & B13 & "-" & "26" -> CAF012-130-26 | E13: =VLOOKUP(Table2456[[#This Row],[Location (drop-down)]],Table1[#All],3,FALSE) -> USWC | F13: 46062 | I13: PBF - D445 and D4052 discrepancy between ST and VTC results | J13: Lab & Ops | K13: C036-130-26
A14: San Francisco (Concord), CA | B14: =VLOOKUP(Table2456[[#This Row],[Location (drop-down)]],'List source'!D$2:E$71,2,FALSE) -> 131 | C14: 013 | D14: ="CAF" & C14 & "-" & B14 & "-" & "26" -> CAF013-131-26 | E14: =VLOOKUP(Table2456[[#This Row],[Location (drop-down)]],Table1[#All],3,FALSE) -> USWC | F14: 46063 | I14: Chevron - Quantity deviation from nomination not communicated to client until report was issued | J14: Ops | K14: C037-131-26
B15: =VLOOKUP(Table2456[[#This Row],[Location (drop-down)]],'List source'!D$2:E$71,2,FALSE) -> #N/A | C15: 014 | D15: ="CAF" & C15 & "-" & B15 & "-" & "26" -> #N/A | E15: =VLOOKUP(Table2456[[#This Row],[Location (drop-down)]],Table1[#All],3,FALSE) -> #N/A
B16: =VLOOKUP(Table2456[[#This Row],[Location (drop-down)]],'List source'!D$2:E$71,2,FALSE) -> #N/A | C16: 015 | D16: ="CAF" & C16 & "-" & B16 & "-" & "26" -> #N/A | E16: =VLOOKUP(Table2456[[#This Row],[Location (drop-down)]],Table1[#All],3,FALSE) -> #N/A
B17: =VLOOKUP(Table2456[[#This Row],[Location (drop-down)]],'List source'!D$2:E$71,2,FALSE) -> #N/A | C17: 016 | D17: ="CAF" & C17 & "-" & B17 & "-" & "26" -> #N/A | E17: =VLOOKUP(Table2456[[#This Row],[Location (drop-down)]],Table1[#All],3,FALSE) -> #N/A
B18: =VLOOKUP(Table2456[[#This Row],[Location (drop-down)]],'List source'!D$2:E$71,2,FALSE) -> #N/A | C18: 017 | D18: ="CAF" & C18 & "-" & B18 & "-" & "26" -> #N/A | E18: =VLOOKUP(Table2456[[#This Row],[Location (drop-down)]],Table1[#All],3,FALSE) -> #N/A
B19: =VLOOKUP(Table2456[[#This Row],[Location (drop-down)]],'List source'!D$2:E$71,2,FALSE) -> #N/A | C19: 018 | D19: ="CAF" & C19 & "-" & B19 & "-" & "26" -> #N/A | E19: =VLOOKUP(Table2456[[#This Row],[Location (drop-down)]],Table1[#All],3,FALSE) -> #N/A
B20: =VLOOKUP(Table2456[[#This Row],[Location (drop-down)]],'List source'!D$2:E$71,2,FALSE) -> #N/A | C20: 019 | D20: ="CAF" & C20 & "-" & B20 & "-" & "26" -> #N/A | E20: =VLOOKUP(Table2456[[#This Row],[Location (drop-down)]],Table1[#All],3,FALSE) -> #N/A
B21: =VLOOKUP(Table2456[[#This Row],[Location (drop-down)]],'List source'!D$2:E$71,2,FALSE) -> #N/A | C21: 020 | D21: ="CAF" & C21 & "-" & B21 & "-" & "26" -> #N/A | E21: =VLOOKUP(Table2456[[#This Row],[Location (drop-down)]],Table1[#All],3,FALSE) -> #N/A
B22: =VLOOKUP(Table2456[[#This Row],[Location (drop-down)]],'List source'!D$2:E$71,2,FALSE) -> #N/A | C22: 021 | D22: ="CAF" & C22 & "-" & B22 & "-" & "26" -> #N/A | E22: =VLOOKUP(Table2456[[#This Row],[Location (drop-down)]],Table1[#All],3,FALSE) -> #N/A
B23: =VLOOKUP(Table2456[[#This Row],[Location (drop-down)]],'List source'!D$2:E$71,2,FALSE) -> #N/A | C23: 022 | D23: ="CAF" & C23 & "-" & B23 & "-" & "26" -> #N/A | E23: =VLOOKUP(Table2456[[#This Row],[Location (drop-down)]],Table1[#All],3,FALSE) -> #N/A
B24: =VLOOKUP(Table2456[[#This Row],[Location (drop-down)]],'List source'!D$2:E$71,2,FALSE) -> #N/A | C24: 023 | D24: ="CAF" & C24 & "-" & B24 & "-" & "26" -> #N/A | E24: =VLOOKUP(Table2456[[#This Row],[Location (drop-down)]],Table1[#All],3,FALSE) -> #N/A
B25: =VLOOKUP(Table2456[[#This Row],[Location (drop-down)]],'List source'!D$2:E$71,2,FALSE) -> #N/A | C25: 024 | D25: ="CAF" & C25 & "-" & B25 & "-" & "26" -> #N/A | E25: =VLOOKUP(Table2456[[#This Row],[Location (drop-down)]],Table1[#All],3,FALSE) -> #N/A
B26: =VLOOKUP(Table2456[[#This Row],[Location (drop-down)]],'List source'!D$2:E$71,2,FALSE) -> #N/A | C26: 025 | D26: ="CAF" & C26 & "-" & B26 & "-" & "26" -> #N/A | E26: =VLOOKUP(Table2456[[#This Row],[Location (drop-down)]],Table1[#All],3,FALSE) -> #N/A
... B151: =VLOOKUP(Table2456[[#This Row],[Location (drop-down)]],'List source'!D$2:E$71,2,FALSE) -> #N/A | C151: 150 | D151: ="CAF" & C151 & "-" & B151 & "-" & "26" -> #N/A | E151: =VLOOKUP(Table2456[[#This Row],[Location (drop-down)]],Table1[#All],3,FALSE) -> #N/A

Sheet PTO '26
A1: Location (drop-down) | B1: Location ID | C1: # | D1: PTO # | E1: BRIEF DESCRIPTION OF NC if VOID: "VOID, Location, details (initials, date)" | F1: PT Program | G1: Parameter (s) | H1: Z-score (s) | I1: PTO initialized date | J1: QA team member initials | K1: Effectiveness Review & date deemed effective | L1: Notes | M1: Days to Close (Cells in red are not closed)
A2: San Francisco (Concord), CA | B2: =VLOOKUP(Table27[[#This Row],[Location (drop-down)]],'List source'!D$2:E$71,2,FALSE) -> 131 | C2: 0004 | D2: ="PTO" & C2 & "-" & B2 & "-" & "26" -> PTO0004-131-26 | E2: PT: RFG2511; D86 - Distillation, Auto, % Evap | F2: {=MID(LEFT(Table27[[#This Row],[BRIEF DESCRIPTION OF NC if VOID: "VOID, Location, details (initials, date)"]], INDEX(_xlfn._xlws.FILTER(ROW(INDIRECT("1:" & LEN(Table27[[#This Row],[BRIEF DESCRIPTION OF NC if VOID: "VOID, Location, details (initials, date)"]]))), (48 <= CODE(MID(Table27[[#This Row],[BRIEF DESCRIPTION OF NC if VOID: "VOID, Location, details (initials, date)"]], ROW(INDIRECT("1:" & LEN(Table27[[#This Row],[BRIEF DESCRIPTION OF NC if VOID: "VOID, Location, details (initials, date)"]]))), 1))) * (CODE(MID(Table27[[#This Row],[BRIEF DESCRIPTION OF NC if VOID: "VOID, Location, details (initials, date)"]], ROW(INDIRECT("1:" & LEN(Table27[[#This Row],[BRIEF DESCRIPTION OF NC if VOID: "VOID, Location, details (initials, date)"]]))), 1)) <= 57)), 1) - 1), FIND(":", Table27[[#This Row],[BRIEF DESCRIPTION OF NC if VOID: "VOID, Location, details (initials, date)"]]) + 2, LEN(Table27[[#This Row],[BRIEF DESCRIPTION OF NC if VOID: "VOID, Location, details (initials, date)"]]))} -> RFG | G2: =MID(LEFT(Table27[[#This Row],[BRIEF DESCRIPTION OF NC if VOID: "VOID, Location, details (initials, date)"]], FIND(",", Table27[[#This Row],[BRIEF DESCRIPTION OF NC if VOID: "VOID, Location, details (initials, date)"]]) - 1), FIND("{token}", SUBSTITUTE(Table27[[#This Row],[BRIEF DESCRIPTION OF NC if VOID: "VOID, Location, details (initials, date)"]], " ", "{token}", 2)) + 1, LEN(Table27[[#This Row],[BRIEF DESCRIPTION OF NC if VOID: "VOID, Location, details (initials, date)"]])) -> D86 - Distillation | H2: -2.05 | I2: 46029 | J2: JN | K2: 46029 | L2: Meets 4.3.1.1.1 Criteria. | M2: =IF(ISBLANK(K2), TODAY()-(I2), Table27[[#This Row],[Effectiveness Review & date deemed effective]]-Table27[[#This Row],[PTO initialized date]]) -> 0 | N2: Meets both the precision performance and reproducibility criteria.
A3: Los Angeles (Signal Hill), CA | B3: =VLOOKUP(Table27[[#This Row],[Location (drop-down)]],'List source'!D$2:E$71,2,FALSE) -> 130 | C3: 0003 | D3: ="PTO" & C3 & "-" & B3 & "-" & "26" -> PTO0003-130-26 | E3: PT: RFG2511; D5191 - Vapor Pressure, RVP, IL (EPA), Z-Score = -2.13 | F3: {=MID(LEFT(Table27[[#This Row],[BRIEF DESCRIPTION OF NC if VOID: "VOID, Location, details (initials, date)"]], INDEX(_xlfn._xlws.FILTER(ROW(INDIRECT("1:" & LEN(Table27[[#This Row],[BRIEF DESCRIPTION OF NC if VOID: "VOID, Location, details (initials, date)"]]))), (48 <= CODE(MID(Table27[[#This Row],[BRIEF DESCRIPTION OF NC if VOID: "VOID, Location, details (initials, date)"]], ROW(INDIRECT("1:" & LEN(Table27[[#This Row],[BRIEF DESCRIPTION OF NC if VOID: "VOID, Location, details (initials, date)"]]))), 1))) * (CODE(MID(Table27[[#This Row],[BRIEF DESCRIPTION OF NC if VOID: "VOID, Location, details (initials, date)"]], ROW(INDIRECT("1:" & LEN(Table27[[#This Row],[BRIEF DESCRIPTION OF NC if VOID: "VOID, Location, details (initials, date)"]]))), 1)) <= 57)), 1) - 1), FIND(":", Table27[[#This Row],[BRIEF DESCRIPTION OF NC if VOID: "VOID, Location, details (initials, date)"]]) + 2, LEN(Table27[[#This Row],[BRIEF DESCRIPTION OF NC if VOID: "VOID, Location, details (initials, date)"]]))} -> RFG | G3: =MID(LEFT(Table27[[#This Row],[BRIEF DESCRIPTION OF NC if VOID: "VOID, Location, details (initials, date)"]], FIND(",", Table27[[#This Row],[BRIEF DESCRIPTION OF NC if VOID: "VOID, Location, details (initials, date)"]]) - 1), FIND("{token}", SUBSTITUTE(Table27[[#This Row],[BRIEF DESCRIPTION OF NC if VOID: "VOID, Location, details (initials, date)"]], " ", "{token}", 2)) + 1, LEN(Table27[[#This Row],[BRIEF DESCRIPTION OF NC if VOID: "VOID, Location, details (initials, date)"]])) -> D5191 - Vapor Pressure | H3: -2.13 | I3: 46029 | J3: JN | K3: 46030 | L3: Meets 4.3.1.2 Criteria. | M3: =IF(ISBLANK(K3), TODAY()-(I3), Table27[[#This Row],[Effectiveness Review & date deemed effective]]-Table27[[#This Row],[PTO initialized date]]) -> 1 | N3: Confirmed Transcription Error.
A4: Mickleton (Philly), NJ | B4: =VLOOKUP(Table27[[#This Row],[Location (drop-down)]],'List source'!D$2:E$71,2,FALSE) -> 180 | C4: 0021 | D4: ="PTO" & C4 & "-" & B4 & "-" & "26" -> PTO0021-180-26 | E4: PT: RFG2511; D4052 - Density, Digital, 15 °C, & Manual Injection, Z-Scores = 2.96 & 3.53 | F4: {=MID(LEFT(Table27[[#This Row],[BRIEF DESCRIPTION OF NC if VOID: "VOID, Location, details (initials, date)"]], INDEX(_xlfn._xlws.FILTER(ROW(INDIRECT("1:" & LEN(Table27[[#This Row],[BRIEF DESCRIPTION OF NC if VOID: "VOID, Location, details (initials, date)"]]))), (48 <= CODE(MID(Table27[[#This Row],[BRIEF DESCRIPTION OF NC if VOID: "VOID, Location, details (initials, date)"]], ROW(INDIRECT("1:" & LEN(Table27[[#This Row],[BRIEF DESCRIPTION OF NC if VOID: "VOID, Location, details (initials, date)"]]))), 1))) * (CODE(MID(Table27[[#This Row],[BRIEF DESCRIPTION OF NC if VOID: "VOID, Location, details (initials, date)"]], ROW(INDIRECT("1:" & LEN(Table27[[#This Row],[BRIEF DESCRIPTION OF NC if VOID: "VOID, Location, details (initials, date)"]]))), 1)) <= 57)), 1) - 1), FIND(":", Table27[[#This Row],[BRIEF DESCRIPTION OF NC if VOID: "VOID, Location, details (initials, date)"]]) + 2, LEN(Table27[[#This Row],[BRIEF DESCRIPTION OF NC if VOID: "VOID, Location, details (initials, date)"]]))} -> RFG | G4: =MID(LEFT(Table27[[#This Row],[BRIEF DESCRIPTION OF NC if VOID: "VOID, Location, details (initials, date)"]], FIND(",", Table27[[#This Row],[BRIEF DESCRIPTION OF NC if VOID: "VOID, Location, details (initials, date)"]]) - 1), FIND("{token}", SUBSTITUTE(Table27[[#This Row],[BRIEF DESCRIPTION OF NC if VOID: "VOID, Location, details (initials, date)"]], " ", "{token}", 2)) + 1, LEN(Table27[[#This Row],[BRIEF DESCRIPTION OF NC if VOID: "VOID, Location, details (initials, date)"]])) -> D4052 - Density | H4: 2.96 & 3.53 | I4: 46029 | J4: JN | K4: 46030 | L4: Confirmed Transcription Errors. | M4: =IF(ISBLANK(K4), TODAY()-(I4), Table27[[#This Row],[Effectiveness Review & date deemed effective]]-Table27[[#This Row],[PTO initialized date]]) -> 1 | N4: Confirmed Calculation Error.
A5: Mickleton (Philly), NJ | B5: =VLOOKUP(Table27[[#This Row],[Location (drop-down)]],'List source'!D$2:E$71,2,FALSE) -> 180 | C5: 0022 | D5: ="PTO" & C5 & "-" & B5 & "-" & "26" -> PTO0022-180-26 | E5: PT: RFG2511; D5599 - Oxygenates, Total Oxygen & tert-Pentanol, by GC, Z-Scores =-43.25 & 0.00(Rejected) | F5: {=MID(LEFT(Table27[[#This Row],[BRIEF DESCRIPTION OF NC if VOID: "VOID, Location, details (initials, date)"]], INDEX(_xlfn._xlws.FILTER(ROW(INDIRECT("1:" & LEN(Table27[[#This Row],[BRIEF DESCRIPTION OF NC if VOID: "VOID, Location, details (initials, date)"]]))), (48 <= CODE(MID(Table27[[#This Row],[BRIEF DESCRIPTION OF NC if VOID: "VOID, Location, details (initials, date)"]], ROW(INDIRECT("1:" & LEN(Table27[[#This Row],[BRIEF DESCRIPTION OF NC if VOID: "VOID, Location, details (initials, date)"]]))), 1))) * (CODE(MID(Table27[[#This Row],[BRIEF DESCRIPTION OF NC if VOID: "VOID, Location, details (initials, date)"]], ROW(INDIRECT("1:" & LEN(Table27[[#This Row],[BRIEF DESCRIPTION OF NC if VOID: "VOID, Location, details (initials, date)"]]))), 1)) <= 57)), 1) - 1), FIND(":", Table27[[#This Row],[BRIEF DESCRIPTION OF NC if VOID: "VOID, Location, details (initials, date)"]]) + 2, LEN(Table27[[#This Row],[BRIEF DESCRIPTION OF NC if VOID: "VOID, Location, details (initials, date)"]]))} -> RFG | G5: =MID(LEFT(Table27[[#This Row],[BRIEF DESCRIPTION OF NC if VOID: "VOID, Location, details (initials, date)"]], FIND(",", Table27[[#This Row],[BRIEF DESCRIPTION OF NC if VOID: "VOID, Location, details (initials, date)"]]) - 1), FIND("{token}", SUBSTITUTE(Table27[[#This Row],[BRIEF DESCRIPTION OF NC if VOID: "VOID, Location, details (initials, date)"]], " ", "{token}", 2)) + 1, LEN(Table27[[#This Row],[BRIEF DESCRIPTION OF NC if VOID: "VOID, Location, details (initials, date)"]])) -> D5599 - Oxygenates | H5: -43.25 | I5: 46029 | J5: JN | K5: 46030 | L5: Confirmed Transcription Errors. | M5: =IF(ISBLANK(K5), TODAY()-(I5), Table27[[#This Row],[Effectiveness Review & date deemed effective]]-Table27[[#This Row],[PTO initialized date]]) -> 1 | N5: Meets 4.3.1.1.1 Criteria.
A6: Yorktown (Norfolk), VA | B6: =VLOOKUP(Table27[[#This Row],[Location (drop-down)]],'List source'!D$2:E$71,2,FALSE) -> 185 | C6: 0023 | D6: ="PTO" & C6 & "-" & B6 & "-" & "26" -> PTO0023-185-26 | E6: PT: RFG2511; D86 - Distillation, Auto, FBP, °F (EPA), Z-Score = -2.29 | F6: {=MID(LEFT(Table27[[#This Row],[BRIEF DESCRIPTION OF NC if VOID: "VOID, Location, details (initials, date)"]], INDEX(_xlfn._xlws.FILTER(ROW(INDIRECT("1:" & LEN(Table27[[#This Row],[BRIEF DESCRIPTION OF NC if VOID: "VOID, Location, details (initials, date)"]]))), (48 <= CODE(MID(Table27[[#This Row],[BRIEF DESCRIPTION OF NC if VOID: "VOID, Location, details (initials, date)"]], ROW(INDIRECT("1:" & LEN(Table27[[#This Row],[BRIEF DESCRIPTION OF NC if VOID: "VOID, Location, details (initials, date)"]]))), 1))) * (CODE(MID(Table27[[#This Row],[BRIEF DESCRIPTION OF NC if VOID: "VOID, Location, details (initials, date)"]], ROW(INDIRECT("1:" & LEN(Table27[[#This Row],[BRIEF DESCRIPTION OF NC if VOID: "VOID, Location, details (initials, date)"]]))), 1)) <= 57)), 1) - 1), FIND(":", Table27[[#This Row],[BRIEF DESCRIPTION OF NC if VOID: "VOID, Location, details (initials, date)"]]) + 2, LEN(Table27[[#This Row],[BRIEF DESCRIPTION OF NC if VOID: "VOID, Location, details (initials, date)"]]))} -> RFG | G6: =MID(LEFT(Table27[[#This Row],[BRIEF DESCRIPTION OF NC if VOID: "VOID, Location, details (initials, date)"]], FIND(",", Table27[[#This Row],[BRIEF DESCRIPTION OF NC if VOID: "VOID, Location, details (initials, date)"]]) - 1), FIND("{token}", SUBSTITUTE(Table27[[#This Row],[BRIEF DESCRIPTION OF NC if VOID: "VOID, Location, details (initials, date)"]], " ", "{token}", 2)) + 1, LEN(Table27[[#This Row],[BRIEF DESCRIPTION OF NC if VOID: "VOID, Location, details (initials, date)"]])) -> D86 - Distillation | H6: -2.29 | I6: 46029 | J6: JN | K6: 46030 | L6: Meets 4.3.1.2 Criteria. | M6: =IF(ISBLANK(K6), TODAY()-(I6), Table27[[#This Row],[Effectiveness Review & date deemed effective]]-Table27[[#This Row],[PTO initialized date]]) -> 1 | N6: Meets 4.3.1.2 Criteria.
A7: Savannah, GA / Charleston, SC | B7: =VLOOKUP(Table27[[#This Row],[Location (drop-down)]],'List source'!D$2:E$71,2,FALSE) -> 144 | C7: 0013 | D7: ="PTO" & C7 & "-" & B7 & "-" & "26" -> PTO0013-144-26 | E7: PT: RFG2511; D5191 - Vapor Pressure, DVPE, 1L, Z-Score = 2.31 | F7: {=MID(LEFT(Table27[[#This Row],[BRIEF DESCRIPTION OF NC if VOID: "VOID, Location, details (initials, date)"]], INDEX(_xlfn._xlws.FILTER(ROW(INDIRECT("1:" & LEN(Table27[[#This Row],[BRIEF DESCRIPTION OF NC if VOID: "VOID, Location, details (initials, date)"]]))), (48 <= CODE(MID(Table27[[#This Row],[BRIEF DESCRIPTION OF NC if VOID: "VOID, Location, details (initials, date)"]], ROW(INDIRECT("1:" & LEN(Table27[[#This Row],[BRIEF DESCRIPTION OF NC if VOID: "VOID, Location, details (initials, date)"]]))), 1))) * (CODE(MID(Table27[[#This Row],[BRIEF DESCRIPTION OF NC if VOID: "VOID, Location, details (initials, date)"]], ROW(INDIRECT("1:" & LEN(Table27[[#This Row],[BRIEF DESCRIPTION OF NC if VOID: "VOID, Location, details (initials, date)"]]))), 1)) <= 57)), 1) - 1), FIND(":", Table27[[#This Row],[BRIEF DESCRIPTION OF NC if VOID: "VOID, Location, details (initials, date)"]]) + 2, LEN(Table27[[#This Row],[BRIEF DESCRIPTION OF NC if VOID: "VOID, Location, details (initials, date)"]]))} -> RFG | G7: =MID(LEFT(Table27[[#This Row],[BRIEF DESCRIPTION OF NC if VOID: "VOID, Location, details (initials, date)"]], FIND(",", Table27[[#This Row],[BRIEF DESCRIPTION OF NC if VOID: "VOID, Location, details (initials, date)"]]) - 1), FIND("{token}", SUBSTITUTE(Table27[[#This Row],[BRIEF DESCRIPTION OF NC if VOID: "VOID, Location, details (initials, date)"]], " ", "{token}", 2)) + 1, LEN(Table27[[#This Row],[BRIEF DESCRIPTION OF NC if VOID: "VOID, Location, details (initials, date)"]])) -> D5191 - Vapor Pressure | H7: 2.31 | I7: 46029 | J7: JN | K7: 46031 | L7: Confirmed Transcription Error. | M7: =IF(ISBLANK(K7), TODAY()-(I7), Table27[[#This Row],[Effectiveness Review & date deemed effective]]-Table27[[#This Row],[PTO initialized date]]) -> 2 | N7: PBMS Parameter - 14 Day Closure
A8: Lake Charles (Sulfur), LA | B8: =VLOOKUP(Table27[[#This Row],[Location (drop-down)]],'List source'!D$2:E$71,2,FALSE) -> 165 | C8: 0017 | D8: ="PTO" & C8 & "-" & B8 & "-" & "26" -> PTO0017-165-26 | E8: PT: RFG2511; D5599 - Oxygenates, Total Oxygen, by GC OFID, Z-Score = 2.01 | F8: {=MID(LEFT(Table27[[#This Row],[BRIEF DESCRIPTION OF NC if VOID: "VOID, Location, details (initials, date)"]], INDEX(_xlfn._xlws.FILTER(ROW(INDIRECT("1:" & LEN(Table27[[#This Row],[BRIEF DESCRIPTION OF NC if VOID: "VOID, Location, details (initials, date)"]]))), (48 <= CODE(MID(Table27[[#This Row],[BRIEF DESCRIPTION OF NC if VOID: "VOID, Location, details (initials, date)"]], ROW(INDIRECT("1:" & LEN(Table27[[#This Row],[BRIEF DESCRIPTION OF NC if VOID: "VOID, Location, details (initials, date)"]]))), 1))) * (CODE(MID(Table27[[#This Row],[BRIEF DESCRIPTION OF NC if VOID: "VOID, Location, details (initials, date)"]], ROW(INDIRECT("1:" & LEN(Table27[[#This Row],[BRIEF DESCRIPTION OF NC if VOID: "VOID, Location, details (initials, date)"]]))), 1)) <= 57)), 1) - 1), FIND(":", Table27[[#This Row],[BRIEF DESCRIPTION OF NC if VOID: "VOID, Location, details (initials, date)"]]) + 2, LEN(Table27[[#This Row],[BRIEF DESCRIPTION OF NC if VOID: "VOID, Location, details (initials, date)"]]))} -> RFG | G8: =MID(LEFT(Table27[[#This Row],[BRIEF DESCRIPTION OF NC if VOID: "VOID, Location, details (initials, date)"]], FIND(",", Table27[[#This Row],[BRIEF DESCRIPTION OF NC if VOID: "VOID, Location, details (initials, date)"]]) - 1), FIND("{token}", SUBSTITUTE(Table27[[#This Row],[BRIEF DESCRIPTION OF NC if VOID: "VOID, Location, details (initials, date)"]], " ", "{token}", 2)) + 1, LEN(Table27[[#This Row],[BRIEF DESCRIPTION OF NC if VOID: "VOID, Location, details (initials, date)"]])) -> D5599 - Oxygenates | H8: 2.01 | I8: 46029 | J8: JN | K8: 46035 | L8: PBMS Outlier | M8: =IF(ISBLANK(K8), TODAY()-(I8), Table27[[#This Row],[Effectiveness Review & date deemed effective]]-Table27[[#This Row],[PTO initialized date]]) -> 6
